Workbook

Sheet راهنما
A1: اشتغال پایدار ساکنان محلات تهران — برآورد محله به محله
A3: وزن‌های شاخص ترکیبی اشتغال پایدار (قابل تغییر)
A4: نرخ اشتغال پایدار (غیرآسیب‌پذیر) از نیروی کار | B4: 0.4 | C4: شاغلان مزد و حقوق‌بگیر و کارفرما ÷ نیروی کار
A5: سهم مشاغل تخصصی (مدیران، متخصصان، تکنسین‌ها) | B5: 0.3 | C5: کیفیت و ثبات شغل
A6: نسبت اشتغال به جمعیت ۱۰ ساله و بیشتر | B6: 0.2 | C6: گستره اشتغال
A7: عدم بیکاری (۱۰۰ − نرخ بیکاری) | B7: 0.1
A8: مجموع وزن‌ها (باید ۱ باشد) | B8: =SUM(B4:B7) -> 1
A10: خلاصه نتایج
A11: تعداد محلات | B11: =COUNTA(محلات!C2:C350) -> 349
A12: جمعیت کل | B12: =SUM(محلات!D2:D350) -> 8627281
A13: شاغلان برآوردی | B13: =SUM(محلات!P2:P350) -> 2546746
A14: شاغلان پایدار برآوردی | B14: =SUM(محلات!R2:R350) -> 1982521
A15: نرخ بیکاری شهر ٪ (۱۳۹۵) | B15: =مناطق!M24 -> 11.499543
A16: سهم شاغلان پایدار از کل شاغلان ٪ | B16: =B14/B13*100 -> 77.845258
A17: محلات «بسیار بالا» | B17: =COUNTIF(محلات!G2:G350,"بسیار بالا") -> 70
A18: محلات «بالا» | B18: =COUNTIF(محلات!G2:G350,"بالا") -> 70
A19: محلات «متوسط» | B19: =COUNTIF(محلات!G2:G350,"متوسط") -> 69
A20: محلات «پایین» | B20: =COUNTIF(محلات!G2:G350,"پایین") -> 71
A21: محلات «بسیار پایین» | B21: =COUNTIF(محلات!G2:G350,"بسیار پایین") -> 69
A22: بیشترین نرخ اشتغال پایدار محله ٪ | B22: =MAX(محلات!H2:H350) -> 75.887063
A23: کمترین نرخ اشتغال پایدار محله ٪ | B23: =MIN(محلات!H2:H350) -> 59.577994
A24: محلات دارای تفکیک درون‌منطقه‌ای (کیفیت A تا C) | B24: =COUNTIF(محلات!AA2:AA350,"<>D") -> 280
A26: شیت «محلات»: برای هر ۳۴۹ محله، شاخص ترکیبی، نرخ اشتغال پایدار، بیکاری، نسبت اشتغال، مشارکت، سهم اشتغال آسیب‌پذیر، بخش عمومی، مشاغل تخصصی و تعداد برآوردی شاغلان، بیکاران و شاغلان پایدار.
A27: شیت «مناطق»: داده رسمی سرشماری ۱۳۹۵ و ۱۳۸۵ برای ۲۲ منطقه و ستون‌های کنترل (جمع برآورد محلات = آمار منطقه).
A28: شیت «مدل و اعتبارسنجی»: کدام شاخص‌ها درون منطقه تفکیک شده‌اند و دقت مدل.
A29: هشدار: ارقام محله‌ای برآوردی‌اند، نه شمارش مستقیم سرشماری.

Sheet محلات
A1: ردیف | B1: منطقه | C1: محله | D1: جمعیت (حدود ۱۳۹۵) | E1: جمعیت ۱۰ ساله و بیشتر (برآورد) | F1: شاخص ترکیبی اشتغال پایدار (۰ تا ۱۰۰) | G1: سطح اشتغال پایدار | H1: نرخ اشتغال پایدار ٪ از نیروی کار | I1: نرخ بیکاری ٪ | J1: نسبت اشتغال به جمعیت ۱۰+ ٪ | K1: نرخ مشارکت اقتصادی ٪ | L1: سهم اشتغال آسیب‌پذیر ٪ (کارکن مستقل + فامیلی بدون مزد) | M1: سهم مزد و حقوق‌بگیر بخش عمومی ٪ | N1: سهم مشاغل تخصصی ٪ | O1: سهم کارگران ساده ٪ | P1: تعداد برآوردی شاغلان | Q1: تعداد برآوردی بیکاران | R1: تعداد برآوردی شاغلان پایدار | S1: تعداد برآوردی شاغلان بخش عمومی | T1: حد پایین نرخ اشتغال پایدار ٪ | U1: حد بالای نرخ اشتغال پایدار ٪ | V1: رتبه در شهر (شاخص ترکیبی) | W1: قیمت میانه هر متر مسکن (میلیون تومان) | X1: تعداد آگهی معتبر | Y1: نوع تطبیق با داده قیمت | Z1: محله(های) دیوار | AA1: درجه کیفیت داده | AB1: سهم دانش‌آموختگان دانشگاهی ٪ (فایل تحصیلات)
A2: 1 | B2: 1 | C2: ولنجک | D2: 26587 | E2: =ROUND(D2*INDEX(مناطق!$AF$2:$AF$23,B2),0) -> 24657 | F2: =ROUND(100*(راهنما!$B$4*(H2-MIN($H$2:$H$350))/(MAX($H$2:$H$350)-MIN($H$2:$H$350))+راهنما!$B$5*(N2-MIN($N$2:$N$350))/(MAX($N$2:$N$350)-MIN($N$2:$N$350))+راهنما!$B$6*(J2-MIN($J$2:$J$350))/(MAX($J$2:$J$350)-MIN($J$2:$J$350))+راهنما!$B$7*(MAX($I$2:$I$350)-I2)/(MAX($I$2:$I$350)-MIN($I$2:$I$350)))/راهنما!$B$8,1) -> 69.7 | G2: =IF(V2<=ROUND(349*0.2,0),"بسیار بالا",IF(V2<=ROUND(349*0.4,0),"بالا",IF(V2<=ROUND(349*0.6,0),"متوسط",IF(V2<=ROUND(349*0.8,0),"پایین","بسیار پایین")))) -> بسیار بالا | H2: =(100-I2)*(100-L2)/100 -> 73.592643 | I2: 11.77 | J2: 31.73 | K2: =J2/(1-I2/100) -> 35.962824 | L2: 16.59 | M2: 34.7 | N2: 70.13 | O2: 5.41 | P2: =ROUND(E2*J2/100,0) -> 7824 | Q2: =ROUND(P2*I2/(100-I2),0) -> 1044 | R2: =ROUND(P2*(100-L2)/100,0) -> 6526 | S2: =ROUND(P2*M2/100,0) -> 2715 | T2: 72.54 | U2: 74.61 | V2: =RANK(F2,$F$2:$F$350,0) -> 14 | W2: 844.4 | X2: 88 | Y2: دقیق | Z2: ولنجک | AA2: A | AB2: 45.85
A3: 2 | B3: 1 | C3: زعفرانیه | D3: 30377 | E3: =ROUND(D3*INDEX(مناطق!$AF$2:$AF$23,B3),0) -> 28172 | F3: =ROUND(100*(راهنما!$B$4*(H3-MIN($H$2:$H$350))/(MAX($H$2:$H$350)-MIN($H$2:$H$350))+راهنما!$B$5*(N3-MIN($N$2:$N$350))/(MAX($N$2:$N$350)-MIN($N$2:$N$350))+راهنما!$B$6*(J3-MIN($J$2:$J$350))/(MAX($J$2:$J$350)-MIN($J$2:$J$350))+راهنما!$B$7*(MAX($I$2:$I$350)-I3)/(MAX($I$2:$I$350)-MIN($I$2:$I$350)))/راهنما!$B$8,1) -> 69.5 | G3: =IF(V3<=ROUND(349*0.2,0),"بسیار بالا",IF(V3<=ROUND(349*0.4,0),"بالا",IF(V3<=ROUND(349*0.6,0),"متوسط",IF(V3<=ROUND(349*0.8,0),"پایین","بسیار پایین")))) -> بسیار بالا | H3: =(100-I3)*(100-L3)/100 -> 73.548528 | I3: 11.77 | J3: 31.74 | K3: =J3/(1-I3/100) -> 35.974158 | L3: 16.64 | M3: 34.7 | N3: 69.87 | O3: 5.43 | P3: =ROUND(E3*J3/100,0) -> 8942 | Q3: =ROUND(P3*I3/(100-I3),0) -> 1193 | R3: =ROUND(P3*(100-L3)/100,0) -> 7454 | S3: =ROUND(P3*M3/100,0) -> 3103 | T3: 72.52 | U3: 74.56 | V3: =RANK(F3,$F$2:$F$350,0) -> 15 | W3: 831.2 | X3: 87 | Y3: دقیق | Z3: زعفرانیه | AA3: A | AB3: 45.56
A4: 3 | B4: 1 | C4: محمودیه | D4: 8763 | E4: =ROUND(D4*INDEX(مناطق!$AF$2:$AF$23,B4),0) -> 8127 | F4: =ROUND(100*(راهنما!$B$4*(H4-MIN($H$2:$H$350))/(MAX($H$2:$H$350)-MIN($H$2:$H$350))+راهنما!$B$5*(N4-MIN($N$2:$N$350))/(MAX($N$2:$N$350)-MIN($N$2:$N$350))+راهنما!$B$6*(J4-MIN($J$2:$J$350))/(MAX($J$2:$J$350)-MIN($J$2:$J$350))+راهنما!$B$7*(MAX($I$2:$I$350)-I4)/(MAX($I$2:$I$350)-MIN($I$2:$I$350)))/راهنما!$B$8,1) -> 65.8 | G4: =IF(V4<=ROUND(349*0.2,0),"بسیار بالا",IF(V4<=ROUND(349*0.4,0),"بالا",IF(V4<=ROUND(349*0.6,0),"متوسط",IF(V4<=ROUND(349*0.8,0),"پایین","بسیار پایین")))) -> بسیار بالا | H4: =(100-I4)*(100-L4)/100 -> 72.657405 | I4: 11.77 | J4: 31.95 | K4: =J4/(1-I4/100) -> 36.212173 | L4: 17.65 | M4: 34.7 | N4: 64.31 | O4: 5.91 | P4: =ROUND(E4*J4/100,0) -> 2597 | Q4: =ROUND(P4*I4/(100-I4),0) -> 346 | R4: =ROUND(P4*(100-L4)/100,0) -> 2139 | S4: =ROUND(P4*M4/100,0) -> 901 | T4: 71.97 | U4: 73.34 | V4: =RANK(F4,$F$2:$F$350,0) -> 29 | W4: 704.4 | X4: 88 | Y4: دقیق | Z4: محمودیه | AA4: A | AB4: 39.73
A5: 4 | B5: 1 | C5: باغ فردوس | D5: 17579 | E5: =ROUND(D5*INDEX(مناطق!$AF$2:$AF$23,B5),0) -> 16303 | F5: =ROUND(100*(راهنما!$B$4*(H5-MIN($H$2:$H$350))/(MAX($H$2:$H$350)-MIN($H$2:$H$350))+راهنما!$B$5*(N5-MIN($N$2:$N$350))/(MAX($N$2:$N$350)-MIN($N$2:$N$350))+راهنما!$B$6*(J5-MIN($J$2:$J$350))/(MAX($J$2:$J$350)-MIN($J$2:$J$350))+راهنما!$B$7*(MAX($I$2:$I$350)-I5)/(MAX($I$2:$I$350)-MIN($I$2:$I$350)))/راهنما!$B$8,1) -> 65.5 | G5: =IF(V5<=ROUND(349*0.2,0),"بسیار بالا",IF(V5<=ROUND(349*0.4,0),"بالا",IF(V5<=ROUND(349*0.6,0),"متوسط",IF(V5<=ROUND(349*0.8,0),"پایین","بسیار پایین")))) -> بسیار بالا | H5: =(100-I5)*(100-L5)/100 -> 72.577998 | I5: 11.77 | J5: 31.96 | K5: =J5/(1-I5/100) -> 36.223507 | L5: 17.74 | M5: 34.7 | N5: 63.83 | O5: 5.95 | P5: =ROUND(E5*J5/100,0) -> 5210 | Q5: =ROUND(P5*I5/(100-I5),0) -> 695 | R5: =ROUND(P5*(100-L5)/100,0) -> 4286 | S5: =ROUND(P5*M5/100,0) -> 1808 | T5: 71.93 | U5: 73.24 | V5: =RANK(F5,$F$2:$F$350,0) -> 31 | W5: 650 | X5: 13 | Y5: دقیق | Z5: باغ فردوس | AA5: B | AB5: 39.26
A6: 5 | B6: 1 | C6: فرمانیه | D6: 22574 | E6: =ROUND(D6*INDEX(مناطق!$AF$2:$AF$23,B6),0) -> 20936 | F6: =ROUND(100*(راهنما!$B$4*(H6-MIN($H$2:$H$350))/(MAX($H$2:$H$350)-MIN($H$2:$H$350))+راهنما!$B$5*(N6-MIN($N$2:$N$350))/(MAX($N$2:$N$350)-MIN($N$2:$N$350))+راهنما!$B$6*(J6-MIN($J$2:$J$350))/(MAX($J$2:$J$350)-MIN($J$2:$J$350))+راهنما!$B$7*(MAX($I$2:$I$350)-I6)/(MAX($I$2:$I$350)-MIN($I$2:$I$350)))/راهنما!$B$8,1) -> 65.4 | G6: =IF(V6<=ROUND(349*0.2,0),"بسیار بالا",IF(V6<=ROUND(349*0.4,0),"بالا",IF(V6<=ROUND(349*0.6,0),"متوسط",IF(V6<=ROUND(349*0.8,0),"پایین","بسیار پایین")))) -> بسیار بالا | H6: =(100-I6)*(100-L6)/100 -> 72.569175 | I6: 11.77 | J6: 31.97 | K6: =J6/(1-I6/100) -> 36.234841 | L6: 17.75 | M6: 34.7 | N6: 63.75 | O6: 5.96 | P6: =ROUND(E6*J6/100,0) -> 6693 | Q6: =ROUND(P6*I6/(100-I6),0) -> 893 | R6: =ROUND(P6*(100-L6)/100,0) -> 5505 | S6: =ROUND(P6*M6/100,0) -> 2322 | T6: 71.92 | U6: 73.22 | V6: =RANK(F6,$F$2:$F$350,0) -> 34 | W6: 682.1 | X6: 88 | Y6: دقیق | Z6: فرمانیه | AA6: A | AB6: 39.18
A7: 6 | B7: 1 | C7: حصار بوعلی | D7: 13368 | E7: =ROUND(D7*INDEX(مناطق!$AF$2:$AF$23,B7),0) -> 12398 | F7: =ROUND(100*(راهنما!$B$4*(H7-MIN($H$2:$H$350))/(MAX($H$2:$H$350)-MIN($H$2:$H$350))+راهنما!$B$5*(N7-MIN($N$2:$N$350))/(MAX($N$2:$N$350)-MIN($N$2:$N$350))+راهنما!$B$6*(J7-MIN($J$2:$J$350))/(MAX($J$2:$J$350)-MIN($J$2:$J$350))+راهنما!$B$7*(MAX($I$2:$I$350)-I7)/(MAX($I$2:$I$350)-MIN($I$2:$I$350)))/راهنما!$B$8,1) -> 64.5 | G7: =IF(V7<=ROUND(349*0.2,0),"بسیار بالا",IF(V7<=ROUND(349*0.4,0),"بالا",IF(V7<=ROUND(349*0.6,0),"متوسط",IF(V7<=ROUND(349*0.8,0),"پایین","بسیار پایین")))) -> بسیار بالا | H7: =(100-I7)*(100-L7)/100 -> 72.357423 | I7: 11.77 | J7: 32.01 | K7: =J7/(1-I7/100) -> 36.280177 | L7: 17.99 | M7: 34.7 | N7: 62.41 | O7: 6.08 | P7: =ROUND(E7*J7/100,0) -> 3969 | Q7: =ROUND(P7*I7/(100-I7),0) -> 529 | R7: =ROUND(P7*(100-L7)/100,0) -> 3255 | S7: =ROUND(P7*M7/100,0) -> 1377 | T7: 71.79 | U7: 72.93 | V7: =RANK(F7,$F$2:$F$350,0) -> 41 | W7: 653.3 | X7: 87 | Y7: دقیق | Z7: حصار بوعلی | AA7: A | AB7: 37.89
A8: 7 | B8: 1 | C8: نیاوران | D8: 9791 | E8: =ROUND(D8*INDEX(مناطق!$AF$2:$AF$23,B8),0) -> 9080 | F8: =ROUND(100*(راهنما!$B$4*(H8-MIN($H$2:$H$350))/(MAX($H$2:$H$350)-MIN($H$2:$H$350))+راهنما!$B$5*(N8-MIN($N$2:$N$350))/(MAX($N$2:$N$350)-MIN($N$2:$N$350))+راهنما!$B$6*(J8-MIN($J$2:$J$350))/(MAX($J$2:$J$350)-MIN($J$2:$J$350))+راهنما!$B$7*(MAX($I$2:$I$350)-I8)/(MAX($I$2:$I$350)-MIN($I$2:$I$350)))/راهنما!$B$8,1) -> 64.2 | G8: =IF(V8<=ROUND(349*0.2,0),"بسیار بالا",IF(V8<=ROUND(349*0.4,0),"بالا",IF(V8<=ROUND(349*0.6,0),"متوسط",IF(V8<=ROUND(349*0.8,0),"پایین","بسیار پایین")))) -> بسیار بالا | H8: =(100-I8)*(100-L8)/100 -> 72.278016 | I8: 11.77 | J8: 32.03 | K8: =J8/(1-I8/100) -> 36.302845 | L8: 18.08 | M8: 34.7 | N8: 61.91 | O8: 6.12 | P8: =ROUND(E8*J8/100,0) -> 2908 | Q8: =ROUND(P8*I8/(100-I8),0) -> 388 | R8: =ROUND(P8*(100-L8)/100,0) -> 2382 | S8: =ROUND(P8*M8/100,0) -> 1009 | T8: 71.75 | U8: 72.82 | V8: =RANK(F8,$F$2:$F$350,0) -> 45 | W8: 671.2 | X8: 90 | Y8: دستی (نام مرکب/معادل) | Z8: نیاوران | AA8: A | AB8: 37.42
A9: 8 | B9: 1 | C9: جماران | D9: 8373 | E9: =ROUND(D9*INDEX(مناطق!$AF$2:$AF$23,B9),0) -> 7765 | F9: =ROUND(100*(راهنما!$B$4*(H9-MIN($H$2:$H$350))/(MAX($H$2:$H$350)-MIN($H$2:$H$350))+راهنما!$B$5*(N9-MIN($N$2:$N$350))/(MAX($N$2:$N$350)-MIN($N$2:$N$350))+راهنما!$B$6*(J9-MIN($J$2:$J$350))/(MAX($J$2:$J$350)-MIN($J$2:$J$350))+راهنما!$B$7*(MAX($I$2:$I$350)-I9)/(MAX($I$2:$I$350)-MIN($I$2:$I$350)))/راهنما!$B$8,1) -> 64.1 | G9: =IF(V9<=ROUND(349*0.2,0),"بسیار بالا",IF(V9<=ROUND(349*0.4,0),"بالا",IF(V9<=ROUND(349*0.6,0),"متوسط",IF(V9<=ROUND(349*0.8,0),"پایین","بسیار پایین")))) -> بسیار بالا | H9: =(100-I9)*(100-L9)/100 -> 72.26037 | I9: 11.77 | J9: 32.03 | K9: =J9/(1-I9/100) -> 36.302845 | L9: 18.1 | M9: 34.7 | N9: 61.79 | O9: 6.13 | P9: =ROUND(E9*J9/100,0) -> 2487 | Q9: =ROUND(P9*I9/(100-I9),0) -> 332 | R9: =ROUND(P9*(100-L9)/100,0) -> 2037 | S9: =ROUND(P9*M9/100,0) -> 863 | T9: 71.73 | U9: 72.8 | V9: =RANK(F9,$F$2:$F$350,0) -> 46 | W9: 646.9 | X9: 91 | Y9: دقیق | Z9: جماران (نیاوران) | AA9: A | AB9: 37.31
A10: 9 | B10: 1 | C10: امامزاده قاسم | D10: 23845 | E10: =ROUND(D10*INDEX(مناطق!$AF$2:$AF$23,B10),0) -> 22114 | F10: =ROUND(100*(راهنما!$B$4*(H10-MIN($H$2:$H$350))/(MAX($H$2:$H$350)-MIN($H$2:$H$350))+راهنما!$B$5*(N10-MIN($N$2:$N$350))/(MAX($N$2:$N$350)-MIN($N$2:$N$350))+راهنما!$B$6*(J10-MIN($J$2:$J$350))/(MAX($J$2:$J$350)-MIN($J$2:$J$350))+راهنما!$B$7*(MAX($I$2:$I$350)-I10)/(MAX($I$2:$I$350)-MIN($I$2:$I$350)))/راهنما!$B$8,1) -> 63.9 | G10: =IF(V10<=ROUND(349*0.2,0),"بسیار بالا",IF(V10<=ROUND(349*0.4,0),"بالا",IF(V10<=ROUND(349*0.6,0),"متوسط",IF(V10<=ROUND(349*0.8,0),"پایین","بسیار پایین")))) -> بسیار بالا | H10: =(100-I10)*(100-L10)/100 -> 72.216255 | I10: 11.77 | J10: 32.04 | K10: =J10/(1-I10/100) -> 36.314179 | L10: 18.15 | M10: 34.7 | N10: 61.52 | O10: 6.15 | P10: =ROUND(E10*J10/100,0) -> 7085 | Q10: =ROUND(P10*I10/(100-I10),0) -> 945 | R10: =ROUND(P10*(100-L10)/100,0) -> 5799 | S10: =ROUND(P10*M10/100,0) -> 2458 | T10: 71.71 | U10: 72.74 | V10: =RANK(F10,$F$2:$F$350,0) -> 48 | W10: 636.8 | X10: 86 | Y10: دقیق | Z10: امام زاده قاسم (نیاوران) | AA10: A | AB10: 37.06
A11: 10 | B11: 1 | C11: دزاشیب | D11: 15178 | E11: =ROUND(D11*INDEX(مناطق!$AF$2:$AF$23,B11),0) -> 14076 | F11: =ROUND(100*(راهنما!$B$4*(H11-MIN($H$2:$H$350))/(MAX($H$2:$H$350)-MIN($H$2:$H$350))+راهنما!$B$5*(N11-MIN($N$2:$N$350))/(MAX($N$2:$N$350)-MIN($N$2:$N$350))+راهنما!$B$6*(J11-MIN($J$2:$J$350))/(MAX($J$2:$J$350)-MIN($J$2:$J$350))+راهنما!$B$7*(MAX($I$2:$I$350)-I11)/(MAX($I$2:$I$350)-MIN($I$2:$I$350)))/راهنما!$B$8,1) -> 63.1 | G11: =IF(V11<=ROUND(349*0.2,0),"بسیار بالا",IF(V11<=ROUND(349*0.4,0),"بالا",IF(V11<=ROUND(349*0.6,0),"متوسط",IF(V11<=ROUND(349*0.8,0),"پایین","بسیار پایین")))) -> بسیار بالا | H11: =(100-I11)*(100-L11)/100 -> 72.022149 | I11: 11.77 | J11: 32.09 | K11: =J11/(1-I11/100) -> 36.370849 | L11: 18.37 | M11: 34.7 | N11: 60.26 | O11: 6.26 | P11: =ROUND(E11*J11/100,0) -> 4517 | Q11: =ROUND(P11*I11/(100-I11),0) -> 603 | R11: =ROUND(P11*(100-L11)/100,0) -> 3687 | S11: =ROUND(P11*M11/100,0) -> 1567 | T11: 71.59 | U11: 72.47 | V11: =RANK(F11,$F$2:$F$350,0) -> 56 | W11: 608.8 | X11: 88 | Y11: دقیق | Z11: دزاشیب | AA11: A | AB11: 35.9
A12: 11 | B12: 1 | C12: کاشانک | D12: 30216 | E12: =ROUND(D12*INDEX(مناطق!$AF$2:$AF$23,B12),0) -> 28023 | F12: =ROUND(100*(راهنما!$B$4*(H12-MIN($H$2:$H$350))/(MAX($H$2:$H$350)-MIN($H$2:$H$350))+راهنما!$B$5*(N12-MIN($N$2:$N$350))/(MAX($N$2:$N$350)-MIN($N$2:$N$350))+راهنما!$B$6*(J12-MIN($J$2:$J$350))/(MAX($J$2:$J$350)-MIN($J$2:$J$350))+راهنما!$B$7*(MAX($I$2:$I$350)-I12)/(MAX($I$2:$I$350)-MIN($I$2:$I$350)))/راهنما!$B$8,1) -> 61 | G12: =IF(V12<=ROUND(349*0.2,0),"بسیار بالا",IF(V12<=ROUND(349*0.4,0),"بالا",IF(V12<=ROUND(349*0.6,0),"متوسط",IF(V12<=ROUND(349*0.8,0),"پایین","بسیار پایین")))) -> بالا | H12: =(100-I12)*(100-L12)/100 -> 71.536884 | I12: 11.77 | J12: 32.19 | K12: =J12/(1-I12/100) -> 36.484189 | L12: 18.92 | M12: 34.7 | N12: 57.17 | O12: 6.53 | P12: =ROUND(E12*J12/100,0) -> 9021 | Q12: =ROUND(P12*I12/(100-I12),0) -> 1203 | R12: =ROUND(P12*(100-L12)/100,0) -> 7314 | S12: =ROUND(P12*M12/100,0) -> 3130 | T12: 71.31 | U12: 71.8 | V12: =RANK(F12,$F$2:$F$350,0) -> 72 | W12: 595.9 | X12: 90 | Y12: دقیق | Z12: کاشانک | AA12: A | AB12: 33.18
A13: 12 | B13: 1 | C13: قیطریه | D13: 24680 | E13: =ROUND(D13*INDEX(مناطق!$AF$2:$AF$23,B13),0) -> 22889 | F13: =ROUND(100*(راهنما!$B$4*(H13-MIN($H$2:$H$350))/(MAX($H$2:$H$350)-MIN($H$2:$H$350))+راهنما!$B$5*(N13-MIN($N$2:$N$350))/(MAX($N$2:$N$350)-MIN($N$2:$N$350))+راهنما!$B$6*(J13-MIN($J$2:$J$350))/(MAX($J$2:$J$350)-MIN($J$2:$J$350))+راهنما!$B$7*(MAX($I$2:$I$350)-I13)/(MAX($I$2:$I$350)-MIN($I$2:$I$350)))/راهنما!$B$8,1) -> 60.2 | G13: =IF(V13<=ROUND(349*0.2,0),"بسیار بالا",IF(V13<=ROUND(349*0.4,0),"بالا",IF(V13<=ROUND(349*0.6,0),"متوسط",IF(V13<=ROUND(349*0.8,0),"پایین","بسیار پایین")))) -> بالا | H13: =(100-I13)*(100-L13)/100 -> 71.333955 | I13: 11.77 | J13: 32.24 | K13: =J13/(1-I13/100) -> 36.540859 | L13: 19.15 | M13: 34.7 | N13: 55.88 | O13: 6.65 | P13: =ROUND(E13*J13/100,0) -> 7379 | Q13: =ROUND(P13*I13/(100-I13),0) -> 984 | R13: =ROUND(P13*(100-L13)/100,0) -> 5966 | S13: =ROUND(P13*M13/100,0) -> 2561 | T13: 71.19 | U13: 71.51 | V13: =RANK(F13,$F$2:$F$350,0) -> 81 | W13: 562.5 | X13: 89 | Y13: دقیق | Z13: قیطریه | AA13: A | AB13: 32.08
A14: 13 | B14: 1 | C14: تجریش | D14: 14564 | E14: =ROUND(D14*INDEX(مناطق!$AF$2:$AF$23,B14),0) -> 13507 | F14: =ROUND(100*(راهنما!$B$4*(H14-MIN($H$2:$H$350))/(MAX($H$2:$H$350)-MIN($H$2:$H$350))+راهنما!$B$5*(N14-MIN($N$2:$N$350))/(MAX($N$2:$N$350)-MIN($N$2:$N$350))+راهنما!$B$6*(J14-MIN($J$2:$J$350))/(MAX($J$2:$J$350)-MIN($J$2:$J$350))+راهنما!$B$7*(MAX($I$2:$I$350)-I14)/(MAX($I$2:$I$350)-MIN($I$2:$I$350)))/راهنما!$B$8,1) -> 59.2 | G14: =IF(V14<=ROUND(349*0.2,0),"بسیار بالا",IF(V14<=ROUND(349*0.4,0),"بالا",IF(V14<=ROUND(349*0.6,0),"متوسط",IF(V14<=ROUND(349*0.8,0),"پایین","بسیار پایین")))) -> بالا | H14: =(100-I14)*(100-L14)/100 -> 71.11338 | I14: 11.77 | J14: 32.29 | K14: =J14/(1-I14/100) -> 36.597529 | L14: 19.4 | M14: 34.7 | N14: 54.48 | O14: 6.77 | P14: =ROUND(E14*J14/100,0) -> 4361 | Q14: =ROUND(P14*I14/(100-I14),0) -> 582 | R14: =ROUND(P14*(100-L14)/100,0) -> 3515 | S14: =ROUND(P14*M14/100,0) -> 1513 | T14: 71.06 | U14: 71.2 | V14: =RANK(F14,$F$2:$F$350,0) -> 91 | W14: 546.9 | X14: 82 | Y14: دقیق | Z14: تجریش | AA14: A | AB14: 30.93
A15: 14 | B15: 1 | C15: اراج | D15: 16408 | E15: =ROUND(D15*INDEX(مناطق!$AF$2:$AF$23,B15),0) -> 15217 | F15: =ROUND(100*(راهنما!$B$4*(H15-MIN($H$2:$H$350))/(MAX($H$2:$H$350)-MIN($H$2:$H$350))+راهنما!$B$5*(N15-MIN($N$2:$N$350))/(MAX($N$2:$N$350)-MIN($N$2:$N$350))+راهنما!$B$6*(J15-MIN($J$2:$J$350))/(MAX($J$2:$J$350)-MIN($J$2:$J$350))+راهنما!$B$7*(MAX($I$2:$I$350)-I15)/(MAX($I$2:$I$350)-MIN($I$2:$I$350)))/راهنما!$B$8,1) -> 59 | G15: =IF(V15<=ROUND(349*0.2,0),"بسیار بالا",IF(V15<=ROUND(349*0.4,0),"بالا",IF(V15<=ROUND(349*0.6,0),"متوسط",IF(V15<=ROUND(349*0.8,0),"پایین","بسیار پایین")))) -> بالا | H15: =(100-I15)*(100-L15)/100 -> 71.069265 | I15: 11.77 | J15: 32.3 | K15: =J15/(1-I15/100) -> 36.608863 | L15: 19.45 | M15: 34.7 | N15: 54.16 | O15: 6.8 | P15: =ROUND(E15*J15/100,0) -> 4915 | Q15: =ROUND(P15*I15/(100-I15),0) -> 656 | R15: =ROUND(P15*(100-L15)/100,0) -> 3959 | S15: =ROUND(P15*M15/100,0) -> 1706 | T15: 71.03 | U15: 71.13 | V15: =RANK(F15,$F$2:$F$350,0) -> 95 | X15: 0 | Y15: بدون داده قیمت | Z15: — | AA15: D | AB15: 30.67
A16: 15 | B16: 1 | C16: کوهسار | D16: 1088 | E16: =ROUND(D16*INDEX(مناطق!$AF$2:$AF$23,B16),0) -> 1009 | F16: =ROUND(100*(راهنما!$B$4*(H16-MIN($H$2:$H$350))/(MAX($H$2:$H$350)-MIN($H$2:$H$350))+راهنما!$B$5*(N16-MIN($N$2:$N$350))/(MAX($N$2:$N$350)-MIN($N$2:$N$350))+راهنما!$B$6*(J16-MIN($J$2:$J$350))/(MAX($J$2:$J$350)-MIN($J$2:$J$350))+راهنما!$B$7*(MAX($I$2:$I$350)-I16)/(MAX($I$2:$I$350)-MIN($I$2:$I$350)))/راهنما!$B$8,1) -> 59 | G16: =IF(V16<=ROUND(349*0.2,0),"بسیار بالا",IF(V16<=ROUND(349*0.4,0),"بالا",IF(V16<=ROUND(349*0.6,0),"متوسط",IF(V16<=ROUND(349*0.8,0),"پایین","بسیار پایین")))) -> بالا | H16: =(100-I16)*(100-L16)/100 -> 71.069265 | I16: 11.77 | J16: 32.3 | K16: =J16/(1-I16/100) -> 36.608863 | L16: 19.45 | M16: 34.7 | N16: 54.16 | O16: 6.8 | P16: =ROUND(E16*J16/100,0) -> 326 | Q16: =ROUND(P16*I16/(100-I16),0) -> 43 | R16: =ROUND(P16*(100-L16)/100,0) -> 263 | S16: =ROUND(P16*M16/100,0) -> 113 | T16: 71.03 | U16: 71.13 | V16: =RANK(F16,$F$2:$F$350,0) -> 95 | X16: 0 | Y16: بدون داده قیمت | Z16: — | AA16: D | AB16: 30.67
A17: 16 | B17: 1 | C17: حکمت | D17: 40434 | E17: =ROUND(D17*INDEX(مناطق!$AF$2:$AF$23,B17),0) -> 37499 | F17: =ROUND(100*(راهنما!$B$4*(H17-MIN($H$2:$H$350))/(MAX($H$2:$H$350)-MIN($H$2:$H$350))+راهنما!$B$5*(N17-MIN($N$2:$N$350))/(MAX($N$2:$N$350)-MIN($N$2:$N$350))+راهنما!$B$6*(J17-MIN($J$2:$J$350))/(MAX($J$2:$J$350)-MIN($J$2:$J$350))+راهنما!$B$7*(MAX($I$2:$I$350)-I17)/(MAX($I$2:$I$350)-MIN($I$2:$I$350)))/راهنما!$B$8,1) -> 58 | G17: =IF(V17<=ROUND(349*0.2,0),"بسیار بالا",IF(V17<=ROUND(349*0.4,0),"بالا",IF(V17<=ROUND(349*0.6,0),"متوسط",IF(V17<=ROUND(349*0.8,0),"پایین","بسیار پایین")))) -> بالا | H17: =(100-I17)*(100-L17)/100 -> 70.831044 | I17: 11.77 | J17: 32.35 | K17: =J17/(1-I17/100) -> 36.665533 | L17: 19.72 | M17: 34.7 | N17: 52.65 | O17: 6.94 | P17: =ROUND(E17*J17/100,0) -> 12131 | Q17: =ROUND(P17*I17/(100-I17),0) -> 1618 | R17: =ROUND(P17*(100-L17)/100,0) -> 9739 | S17: =ROUND(P17*M17/100,0) -> 4209 | T17: 70.79 | U17: 70.89 | V17: =RANK(F17,$F$2:$F$350,0) -> 104 | W17: 520 | X17: 91 | Y17: دقیق | Z17: حکمت | AA17: A | AB17: 29.46
A18: 17 | B18: 1 | C18: چیذر | D18: 18995 | E18: =ROUND(D18*INDEX(مناطق!$AF$2:$AF$23,B18),0) -> 17616 | F18: =ROUND(100*(راهنما!$B$4*(H18-MIN($H$2:$H$350))/(MAX($H$2:$H$350)-MIN($H$2:$H$350))+راهنما!$B$5*(N18-MIN($N$2:$N$350))/(MAX($N$2:$N$350)-MIN($N$2:$N$350))+راهنما!$B$6*(J18-MIN($J$2:$J$350))/(MAX($J$2:$J$350)-MIN($J$2:$J$350))+راهنما!$B$7*(MAX($I$2:$I$350)-I18)/(MAX($I$2:$I$350)-MIN($I$2:$I$350)))/راهنما!$B$8,1) -> 55.6 | G18: =IF(V18<=ROUND(349*0.2,0),"بسیار بالا",IF(V18<=ROUND(349*0.4,0),"بالا",IF(V18<=ROUND(349*0.6,0),"متوسط",IF(V18<=ROUND(349*0.8,0),"پایین","بسیار پایین")))) -> بالا | H18: =(100-I18)*(100-L18)/100 -> 70.275195 | I18: 11.77 | J18: 32.46 | K18: =J18/(1-I18/100) -> 36.790207 | L18: 20.35 | M18: 34.7 | N18: 49.23 | O18: 7.26 | P18: =ROUND(E18*J18/100,0) -> 5718 | Q18: =ROUND(P18*I18/(100-I18),0) -> 763 | R18: =ROUND(P18*(100-L18)/100,0) -> 4554 | S18: =ROUND(P18*M18/100,0) -> 1984 | T18: 70.01 | U18: 70.57 | V18: =RANK(F18,$F$2:$F$350,0) -> 125 | W18: 470.1 | X18: 78 | Y18: دقیق | Z18: چیذر | AA18: A | AB18: 26.84
A19: 18 | B19: 1 | C19: ازگل | D19: 25362 | E19: =ROUND(D19*INDEX(مناطق!$AF$2:$AF$23,B19),0) -> 23521 | F19: =ROUND(100*(راهنما!$B$4*(H19-MIN($H$2:$H$350))/(MAX($H$2:$H$350)-MIN($H$2:$H$350))+راهنما!$B$5*(N19-MIN($N$2:$N$350))/(MAX($N$2:$N$350)-MIN($N$2:$N$350))+راهنما!$B$6*(J19-MIN($J$2:$J$350))/(MAX($J$2:$J$350)-MIN($J$2:$J$350))+راهنما!$B$7*(MAX($I$2:$I$350)-I19)/(MAX($I$2:$I$350)-MIN($I$2:$I$350)))/راهنما!$B$8,1) -> 53.9 | G19: =IF(V19<=ROUND(349*0.2,0),"بسیار بالا",IF(V19<=ROUND(349*0.4,0),"بالا",IF(V19<=ROUND(349*0.6,0),"متوسط",IF(V19<=ROUND(349*0.8,0),"پایین","بسیار پایین")))) -> بالا | H19: =(100-I19)*(100-L19)/100 -> 69.869337 | I19: 11.77 | J19: 32.54 | K19: =J19/(1-I19/100) -> 36.88088 | L19: 20.81 | M19: 34.7 | N19: 46.71 | O19: 7.51 | P19: =ROUND(E19*J19/100,0) -> 7654 | Q19: =ROUND(P19*I19/(100-I19),0) -> 1021 | R19: =ROUND(P19*(100-L19)/100,0) -> 6061 | S19: =ROUND(P19*M19/100,0) -> 2656 | T19: 69.42 | U19: 70.34 | V19: =RANK(F19,$F$2:$F$350,0) -> 138 | W19: 397.4 | X19: 86 | Y19: دقیق | Z19: ازگل | AA19: A | AB19: 25.01
A20: 19 | B20: 1 | C20: اوین | D20: 8226 | E20: =ROUND(D20*INDEX(مناطق!$AF$2:$AF$23,B20),0) -> 7629 | F20: =ROUND(100*(راهنما!$B$4*(H20-MIN($H$2:$H$350))/(MAX($H$2:$H$350)-MIN($H$2:$H$350))+راهنما!$B$5*(N20-MIN($N$2:$N$350))/(MAX($N$2:$N$350)-MIN($N$2:$N$350))+راهنما!$B$6*(J20-MIN($J$2:$J$350))/(MAX($J$2:$J$350)-MIN($J$2:$J$350))+راهنما!$B$7*(MAX($I$2:$I$350)-I20)/(MAX($I$2:$I$350)-MIN($I$2:$I$350)))/راهنما!$B$8,1) -> 53.6 | G20: =IF(V20<=ROUND(349*0.2,0),"بسیار بالا",IF(V20<=ROUND(349*0.4,0),"بالا",IF(V20<=ROUND(349*0.6,0),"متوسط",IF(V20<=ROUND(349*0.8,0),"پایین","بسیار پایین")))) -> متوسط | H20: =(100-I20)*(100-L20)/100 -> 69.781107 | I20: 11.77 | J20: 32.56 | K20: =J20/(1-I20/100) -> 36.903548 | L20: 20.91 | M20: 34.7 | N20: 46.21 | O20: 7.56 | P20: =ROUND(E20*J20/100,0) -> 2484 | Q20: =ROUND(P20*I20/(100-I20),0) -> 331 | R20: =ROUND(P20*(100-L20)/100,0) -> 1965 | S20: =ROUND(P20*M20/100,0) -> 862 | T20: 69.3 | U20: 70.29 | V20: =RANK(F20,$F$2:$F$350,0) -> 141 | W20: 412.5 | X20: 50 | Y20: دقیق | Z20: اوین | AA20: A | AB20: 24.66
A21: 20 | B21: 1 | C21: دربند | D21: 11282 | E21: =ROUND(D21*INDEX(مناطق!$AF$2:$AF$23,B21),0) -> 10463 | F21: =ROUND(100*(راهنما!$B$4*(H21-MIN($H$2:$H$350))/(MAX($H$2:$H$350)-MIN($H$2:$H$350))+راهنما!$B$5*(N21-MIN($N$2:$N$350))/(MAX($N$2:$N$350)-MIN($N$2:$N$350))+راهنما!$B$6*(J21-MIN($J$2:$J$350))/(MAX($J$2:$J$350)-MIN($J$2:$J$350))+راهنما!$B$7*(MAX($I$2:$I$350)-I21)/(MAX($I$2:$I$350)-MIN($I$2:$I$350)))/راهنما!$B$8,1) -> 53.2 | G21: =IF(V21<=ROUND(349*0.2,0),"بسیار بالا",IF(V21<=ROUND(349*0.4,0),"بالا",IF(V21<=ROUND(349*0.6,0),"متوسط",IF(V21<=ROUND(349*0.8,0),"پایین","بسیار پایین")))) -> متوسط | H21: =(100-I21)*(100-L21)/100 -> 69.7017 | I21: 11.77 | J21: 32.58 | K21: =J21/(1-I21/100) -> 36.926216 | L21: 21 | M21: 34.7 | N21: 45.69 | O21: 7.61 | P21: =ROUND(E21*J21/100,0) -> 3409 | Q21: =ROUND(P21*I21/(100-I21),0) -> 455 | R21: =ROUND(P21*(100-L21)/100,0) -> 2693 | S21: =ROUND(P21*M21/100,0) -> 1183 | T21: 69.17 | U21: 70.24 | V21: =RANK(F21,$F$2:$F$350,0) -> 144 | W21: 423.5 | X21: 46 | Y21: دقیق | Z21: دربند | AA21: A | AB21: 24.29
A22: 21 | B22: 1 | C22: دانشگاه - گلها | D22: 3048 | E22: =ROUND(D22*INDEX(مناطق!$AF$2:$AF$23,B22),0) -> 2827 | F22: =ROUND(100*(راهنما!$B$4*(H22-MIN($H$2:$H$350))/(MAX($H$2:$H$350)-MIN($H$2:$H$350))+راهنما!$B$5*(N22-MIN($N$2:$N$350))/(MAX($N$2:$N$350)-MIN($N$2:$N$350))+راهنما!$B$6*(J22-MIN($J$2:$J$350))/(MAX($J$2:$J$350)-MIN($J$2:$J$350))+راهنما!$B$7*(MAX($I$2:$I$350)-I22)/(MAX($I$2:$I$350)-MIN($I$2:$I$350)))/راهنما!$B$8,1) -> 53.1 | G22: =IF(V22<=ROUND(349*0.2,0),"بسیار بالا",IF(V22<=ROUND(349*0.4,0),"بالا",IF(V22<=ROUND(349*0.6,0),"متوسط",IF(V22<=ROUND(349*0.8,0),"پایین","بسیار پایین")))) -> متوسط | H22: =(100-I22)*(100-L22)/100 -> 69.657585 | I22: 11.77 | J22: 32.59 | K22: =J22/(1-I22/100) -> 36.93755 | L22: 21.05 | M22: 34.7 | N22: 45.47 | O22: 7.63 | P22: =ROUND(E22*J22/100,0) -> 921 | Q22: =ROUND(P22*I22/(100-I22),0) -> 123 | R22: =ROUND(P22*(100-L22)/100,0) -> 727 | S22: =ROUND(P22*M22/100,0) -> 320 | T22: 69.12 | U22: 70.22 | V22: =RANK(F22,$F$2:$F$350,0) -> 145 | W22: 428.2 | X22: 29 | Y22: دستی (نام مرکب/معادل) | Z22: شهرک گلها | AA22: B | AB22: 24.14
A23: 22 | B23: 1 | C23: درکه | D23: 6719 | E23: =ROUND(D23*INDEX(مناطق!$AF$2:$AF$23,B23),0) -> 6231 | F23: =ROUND(100*(راهنما!$B$4*(H23-MIN($H$2:$H$350))/(MAX($H$2:$H$350)-MIN($H$2:$H$350))+راهنما!$B$5*(N23-MIN($N$2:$N$350))/(MAX($N$2:$N$350)-MIN($N$2:$N$350))+راهنما!$B$6*(J23-MIN($J$2:$J$350))/(MAX($J$2:$J$350)-MIN($J$2:$J$350))+راهنما!$B$7*(MAX($I$2:$I$350)-I23)/(MAX($I$2:$I$350)-MIN($I$2:$I$350)))/راهنما!$B$8,1) -> 52.5 | G23: =IF(V23<=ROUND(349*0.2,0),"بسیار بالا",IF(V23<=ROUND(349*0.4,0),"بالا",IF(V23<=ROUND(349*0.6,0),"متوسط",IF(V23<=ROUND(349*0.8,0),"پایین","بسیار پایین")))) -> متوسط | H23: =(100-I23)*(100-L23)/100 -> 69.516417 | I23: 11.77 | J23: 32.62 | K23: =J23/(1-I23/100) -> 36.971552 | L23: 21.21 | M23: 34.7 | N23: 44.59 | O23: 7.72 | P23: =ROUND(E23*J23/100,0) -> 2033 | Q23: =ROUND(P23*I23/(100-I23),0) -> 271 | R23: =ROUND(P23*(100-L23)/100,0) -> 1602 | S23: =ROUND(P23*M23/100,0) -> 705 | T23: 68.9 | U23: 70.14 | V23: =RANK(F23,$F$2:$F$350,0) -> 151 | W23: 394.8 | X23: 50 | Y23: دقیق | Z23: درکه | AA23: A | AB23: 23.53
A24: 23 | B24: 1 | C24: شهرک نفت | D24: 24137 | E24: =ROUND(D24*INDEX(مناطق!$AF$2:$AF$23,B24),0) -> 22385 | F24: =ROUND(100*(راهنما!$B$4*(H24-MIN($H$2:$H$350))/(MAX($H$2:$H$350)-MIN($H$2:$H$350))+راهنما!$B$5*(N24-MIN($N$2:$N$350))/(MAX($N$2:$N$350)-MIN($N$2:$N$350))+راهنما!$B$6*(J24-MIN($J$2:$J$350))/(MAX($J$2:$J$350)-MIN($J$2:$J$350))+راهنما!$B$7*(MAX($I$2:$I$350)-I24)/(MAX($I$2:$I$350)-MIN($I$2:$I$350)))/راهنما!$B$8,1) -> 51.5 | G24: =IF(V24<=ROUND(349*0.2,0),"بسیار بالا",IF(V24<=ROUND(349*0.4,0),"بالا",IF(V24<=ROUND(349*0.6,0),"متوسط",IF(V24<=ROUND(349*0.8,0),"پایین","بسیار پایین")))) -> متوسط | H24: =(100-I24)*(100-L24)/100 -> 69.278196 | I24: 11.77 | J24: 32.66 | K24: =J24/(1-I24/100) -> 37.016888 | L24: 21.48 | M24: 34.7 | N24: 43.23 | O24: 7.86 | P24: =ROUND(E24*J24/100,0) -> 7311 | Q24: =ROUND(P24*I24/(100-I24),0) -> 975 | R24: =ROUND(P24*(100-L24)/100,0) -> 5741 | S24: =ROUND(P24*M24/100,0) -> 2537 | T24: 68.57 | U24: 70.01 | V24: =RANK(F24,$F$2:$F$350,0) -> 155 | W24: 423.1 | X24: 80 | Y24: دستی (نام مرکب/معادل) | Z24: مینی‌سیتی (شهرک نفت) | AA24: A | AB24: 22.6
A25: 24 | B25: 1 | C25: دارآباد | D25: 15236 | E25: =ROUND(D25*INDEX(مناطق!$AF$2:$AF$23,B25),0) -> 14130 | F25: =ROUND(100*(راهنما!$B$4*(H25-MIN($H$2:$H$350))/(MAX($H$2:$H$350)-MIN($H$2:$H$350))+راهنما!$B$5*(N25-MIN($N$2:$N$350))/(MAX($N$2:$N$350)-MIN($N$2:$N$350))+راهنما!$B$6*(J25-MIN($J$2:$J$350))/(MAX($J$2:$J$350)-MIN($J$2:$J$350))+راهنما!$B$7*(MAX($I$2:$I$350)-I25)/(MAX($I$2:$I$350)-MIN($I$2:$I$350)))/راهنما!$B$8,1) -> 51.5 | G25: =IF(V25<=ROUND(349*0.2,0),"بسیار بالا",IF(V25<=ROUND(349*0.4,0),"بالا",IF(V25<=ROUND(349*0.6,0),"متوسط",IF(V25<=ROUND(349*0.8,0),"پایین","بسیار پایین")))) -> متوسط | H25: =(100-I25)*(100-L25)/100 -> 69.278196 | I25: 11.77 | J25: 32.66 | K25: =J25/(1-I25/100) -> 37.016888 | L25: 21.48 | M25: 34.7 | N25: 43.22 | O25: 7.86 | P25: =ROUND(E25*J25/100,0) -> 4615 | Q25: =ROUND(P25*I25/(100-I25),0) -> 616 | R25: =ROUND(P25*(100-L25)/100,0) -> 3624 | S25: =ROUND(P25*M25/100,0) -> 1601 | T25: 68.57 | U25: 70 | V25: =RANK(F25,$F$2:$F$350,0) -> 155 | W25: 376.5 | X25: 81 | Y25: دقیق | Z25: دارآباد | AA25: A | AB25: 22.6
A26: 25 | B26: 1 | C26: سوهانک | D26: 22829 | E26: =ROUND(D26*INDEX(مناطق!$AF$2:$AF$23,B26),0) -> 21172 | F26: =ROUND(100*(راهنما!$B$4*(H26-MIN($H$2:$H$350))/(MAX($H$2:$H$350)-MIN($H$2:$H$350))+راهنما!$B$5*(N26-MIN($N$2:$N$350))/(MAX($N$2:$N$350)-MIN($N$2:$N$350))+راهنما!$B$6*(J26-MIN($J$2:$J$350))/(MAX($J$2:$J$350)-MIN($J$2:$J$350))+راهنما!$B$7*(MAX($I$2:$I$350)-I26)/(MAX($I$2:$I$350)-MIN($I$2:$I$350)))/راهنما!$B$8,1) -> 51 | G26: =IF(V26<=ROUND(349*0.2,0),"بسیار بالا",IF(V26<=ROUND(349*0.4,0),"بالا",IF(V26<=ROUND(349*0.6,0),"متوسط",IF(V26<=ROUND(349*0.8,0),"پایین","بسیار پایین")))) -> متوسط | H26: =(100-I26)*(100-L26)/100 -> 69.181143 | I26: 11.77 | J26: 32.68 | K26: =J26/(1-I26/100) -> 37.039556 | L26: 21.59 | M26: 34.7 | N26: 42.62 | O26: 7.93 | P26: =ROUND(E26*J26/100,0) -> 6919 | Q26: =ROUND(P26*I26/(100-I26),0) -> 923 | R26: =ROUND(P26*(100-L26)/100,0) -> 5425 | S26: =ROUND(P26*M26/100,0) -> 2401 | T26: 68.42 | U26: 69.95 | V26: =RANK(F26,$F$2:$F$350,0) -> 159 | W26: 375.2 | X26: 89 | Y26: دقیق | Z26: سوهانک | AA26: A | AB26: 22.19
A27: 26 | B27: 1 | C27: شهرک محلاتی | D27: 32186 | E27: =ROUND(D27*INDEX(مناطق!$AF$2:$AF$23,B27),0) -> 29850 | F27: =ROUND(100*(راهنما!$B$4*(H27-MIN($H$2:$H$350))/(MAX($H$2:$H$350)-MIN($H$2:$H$350))+راهنما!$B$5*(N27-MIN($N$2:$N$350))/(MAX($N$2:$N$350)-MIN($N$2:$N$350))+راهنما!$B$6*(J27-MIN($J$2:$J$350))/(MAX($J$2:$J$350)-MIN($J$2:$J$350))+راهنما!$B$7*(MAX($I$2:$I$350)-I27)/(MAX($I$2:$I$350)-MIN($I$2:$I$350)))/راهنما!$B$8,1) -> 48.5 | G27: =IF(V27<=ROUND(349*0.2,0),"بسیار بالا",IF(V27<=ROUND(349*0.4,0),"بالا",IF(V27<=ROUND(349*0.6,0),"متوسط",IF(V27<=ROUND(349*0.8,0),"پایین","بسیار پایین")))) -> متوسط | H27: =(100-I27)*(100-L27)/100 -> 68.55471 | I27: 11.77 | J27: 32.81 | K27: =J27/(1-I27/100) -> 37.186898 | L27: 22.3 | M27: 34.7 | N27: 39.11 | O27: 8.31 | P27: =ROUND(E27*J27/100,0) -> 9794 | Q27: =ROUND(P27*I27/(100-I27),0) -> 1307 | R27: =ROUND(P27*(100-L27)/100,0) -> 7610 | S27: =ROUND(P27*M27/100,0) -> 3399 | T27: 67.5 | U27: 69.6 | V27: =RANK(F27,$F$2:$F$350,0) -> 187 | W27: 343.9 | X27: 56 | Y27: دقیق | Z27: شهرک محلاتی | AA27: A | AB27: 19.91
A28: 27 | B28: 1 | C28: گلابدره | D28: 14224 | E28: =ROUND(D28*INDEX(مناطق!$AF$2:$AF$23,B28),0) -> 13192 | F28: =ROUND(100*(راهنما!$B$4*(H28-MIN($H$2:$H$350))/(MAX($H$2:$H$350)-MIN($H$2:$H$350))+راهنما!$B$5*(N28-MIN($N$2:$N$350))/(MAX($N$2:$N$350)-MIN($N$2:$N$350))+راهنما!$B$6*(J28-MIN($J$2:$J$350))/(MAX($J$2:$J$350)-MIN($J$2:$J$350))+راهنما!$B$7*(MAX($I$2:$I$350)-I28)/(MAX($I$2:$I$350)-MIN($I$2:$I$350)))/راهنما!$B$8,1) -> 42.2 | G28: =IF(V28<=ROUND(349*0.2,0),"بسیار بالا",IF(V28<=ROUND(349*0.4,0),"بالا",IF(V28<=ROUND(349*0.6,0),"متوسط",IF(V28<=ROUND(349*0.8,0),"پایین","بسیار پایین")))) -> پایین | H28: =(100-I28)*(100-L28)/100 -> 66.895986 | I28: 11.77 | J28: 33.12 | K28: =J28/(1-I28/100) -> 37.538252 | L28: 24.18 | M28: 34.7 | N28: 30.69 | O28: 9.37 | P28: =ROUND(E28*J28/100,0) -> 4369 | Q28: =ROUND(P28*I28/(100-I28),0) -> 583 | R28: =ROUND(P28*(100-L28)/100,0) -> 3313 | S28: =ROUND(P28*M28/100,0) -> 1516 | T28: 65.04 | U28: 68.68 | V28: =RANK(F28,$F$2:$F$350,0) -> 241 | W28: 260 | X28: 17 | Y28: دقیق | Z28: گلاب دره | AA28: B | AB28: 14.88
... A37: 36 | B37: 2 | C37: مرزداران شرقی | D37: 42043 | E37: =ROUND(D37*INDEX(مناطق!$AF$2:$AF$23,B37),0) -> 38640 | F37: =ROUND(100*(راهنما!$B$4*(H37-MIN($H$2:$H$350))/(MAX($H$2:$H$350)-MIN($H$2:$H$350))+راهنما!$B$5*(N37-MIN($N$2:$N$350))/(MAX($N$2:$N$350)-MIN($N$2:$N$350))+راهنما!$B$6*(J37-MIN($J$2:$J$350))/(MAX($J$2:$J$350)-MIN($J$2:$J$350))+راهنما!$B$7*(MAX($I$2:$I$350)-I37)/(MAX($I$2:$I$350)-MIN($I$2:$I$350)))/راهنما!$B$8,1) -> 54.6 | G37: =IF(V37<=ROUND(349*0.2,0),"بسیار بالا",IF(V37<=ROUND(349*0.4,0),"بالا",IF(V37<=ROUND(349*0.6,0),"متوسط",IF(V37<=ROUND(349*0.8,0),"پایین","بسیار پایین")))) -> بالا | H37: =(100-I37)*(100-L37)/100 -> 71.046417 | I37: 13.81 | J37: 31.84 | K37: =J37/(1-I37/100) -> 36.941641 | L37: 17.57 | M37: 33.66 | N37: 57.25 | O37: 3.43 | P37: =ROUND(E37*J37/100,0) -> 12303 | Q37: =ROUND(P37*I37/(100-I37),0) -> 1971 | R37: =ROUND(P37*(100-L37)/100,0) -> 10141 | S37: =ROUND(P37*M37/100,0) -> 4141 | T37: 70.98 | U37: 71.12 | V37: =RANK(F37,$F$2:$F$350,0) -> 132 | W37: 405.9 | X37: 89 | Y37: دستی (نام مرکب/معادل) | Z37: مرزداران | AA37: A | AB37: 31.45
A38: 37 | B38: 2 | C38: سپهر | D38: 33619 | E38: =ROUND(D38*INDEX(مناطق!$AF$2:$AF$23,B38),0) -> 30898 | F38: =ROUND(100*(راهنما!$B$4*(H38-MIN($H$2:$H$350))/(MAX($H$2:$H$350)-MIN($H$2:$H$350))+راهنما!$B$5*(N38-MIN($N$2:$N$350))/(MAX($N$2:$N$350)-MIN($N$2:$N$350))+راهنما!$B$6*(J38-MIN($J$2:$J$350))/(MAX($J$2:$J$350)-MIN($J$2:$J$350))+راهنما!$B$7*(MAX($I$2:$I$350)-I38)/(MAX($I$2:$I$350)-MIN($I$2:$I$350)))/راهنما!$B$8,1) -> 54.3 | G38: =IF(V38<=ROUND(349*0.2,0),"بسیار بالا",IF(V38<=ROUND(349*0.4,0),"بالا",IF(V38<=ROUND(349*0.6,0),"متوسط",IF(V38<=ROUND(349*0.8,0),"پایین","بسیار پایین")))) -> بالا | H38: =(100-I38)*(100-L38)/100 -> 70.986084 | I38: 13.81 | J38: 31.85 | K38: =J38/(1-I38/100) -> 36.953243 | L38: 17.64 | M38: 33.66 | N38: 56.87 | O38: 3.45 | P38: =ROUND(E38*J38/100,0) -> 9841 | Q38: =ROUND(P38*I38/(100-I38),0) -> 1577 | R38: =ROUND(P38*(100-L38)/100,0) -> 8105 | S38: =ROUND(P38*M38/100,0) -> 3312 | T38: 70.95 | U38: 71.04 | V38: =RANK(F38,$F$2:$F$350,0) -> 135 | X38: 0 | Y38: بدون داده قیمت | Z38: — | AA38: D | AB38: 31.13
A39: 38 | B39: 2 | C39: شهرک قدس | D39: 29776 | E39: =ROUND(D39*INDEX(مناطق!$AF$2:$AF$23,B39),0) -> 27366 | F39: =ROUND(100*(راهنما!$B$4*(H39-MIN($H$2:$H$350))/(MAX($H$2:$H$350)-MIN($H$2:$H$350))+راهنما!$B$5*(N39-MIN($N$2:$N$350))/(MAX($N$2:$N$350)-MIN($N$2:$N$350))+راهنما!$B$6*(J39-MIN($J$2:$J$350))/(MAX($J$2:$J$350)-MIN($J$2:$J$350))+راهنما!$B$7*(MAX($I$2:$I$350)-I39)/(MAX($I$2:$I$350)-MIN($I$2:$I$350)))/راهنما!$B$8,1) -> 54.3 | G39: =IF(V39<=ROUND(349*0.2,0),"بسیار بالا",IF(V39<=ROUND(349*0.4,0),"بالا",IF(V39<=ROUND(349*0.6,0),"متوسط",IF(V39<=ROUND(349*0.8,0),"پایین","بسیار پایین")))) -> بالا | H39: =(100-I39)*(100-L39)/100 -> 70.986084 | I39: 13.81 | J39: 31.85 | K39: =J39/(1-I39/100) -> 36.953243 | L39: 17.64 | M39: 33.66 | N39: 56.87 | O39: 3.45 | P39: =ROUND(E39*J39/100,0) -> 8716 | Q39: =ROUND(P39*I39/(100-I39),0) -> 1397 | R39: =ROUND(P39*(100-L39)/100,0) -> 7178 | S39: =ROUND(P39*M39/100,0) -> 2934 | T39: 70.95 | U39: 71.04 | V39: =RANK(F39,$F$2:$F$350,0) -> 135 | X39: 0 | Y39: بدون داده قیمت | Z39: — | AA39: D | AB39: 31.13
A40: 39 | B40: 2 | C40: تیموری | D40: 17555 | E40: =ROUND(D40*INDEX(مناطق!$AF$2:$AF$23,B40),0) -> 16134 | F40: =ROUND(100*(راهنما!$B$4*(H40-MIN($H$2:$H$350))/(MAX($H$2:$H$350)-MIN($H$2:$H$350))+راهنما!$B$5*(N40-MIN($N$2:$N$350))/(MAX($N$2:$N$350)-MIN($N$2:$N$350))+راهنما!$B$6*(J40-MIN($J$2:$J$350))/(MAX($J$2:$J$350)-MIN($J$2:$J$350))+راهنما!$B$7*(MAX($I$2:$I$350)-I40)/(MAX($I$2:$I$350)-MIN($I$2:$I$350)))/راهنما!$B$8,1) -> 54.3 | G40: =IF(V40<=ROUND(349*0.2,0),"بسیار بالا",IF(V40<=ROUND(349*0.4,0),"بالا",IF(V40<=ROUND(349*0.6,0),"متوسط",IF(V40<=ROUND(349*0.8,0),"پایین","بسیار پایین")))) -> بالا | H40: =(100-I40)*(100-L40)/100 -> 70.986084 | I40: 13.81 | J40: 31.85 | K40: =J40/(1-I40/100) -> 36.953243 | L40: 17.64 | M40: 33.66 | N40: 56.87 | O40: 3.45 | P40: =ROUND(E40*J40/100,0) -> 5139 | Q40: =ROUND(P40*I40/(100-I40),0) -> 823 | R40: =ROUND(P40*(100-L40)/100,0) -> 4232 | S40: =ROUND(P40*M40/100,0) -> 1730 | T40: 70.95 | U40: 71.04 | V40: =RANK(F40,$F$2:$F$350,0) -> 135 | X40: 0 | Y40: بدون داده قیمت | Z40: — | AA40: D | AB40: 31.13
A41: 40 | B41: 2 | C41: پونک | D41: 25981 | E41: =ROUND(D41*INDEX(مناطق!$AF$2:$AF$23,B41),0) -> 23878 | F41: =ROUND(100*(راهنما!$B$4*(H41-MIN($H$2:$H$350))/(MAX($H$2:$H$350)-MIN($H$2:$H$350))+راهنما!$B$5*(N41-MIN($N$2:$N$350))/(MAX($N$2:$N$350)-MIN($N$2:$N$350))+راهنما!$B$6*(J41-MIN($J$2:$J$350))/(MAX($J$2:$J$350)-MIN($J$2:$J$350))+راهنما!$B$7*(MAX($I$2:$I$350)-I41)/(MAX($I$2:$I$350)-MIN($I$2:$I$350)))/راهنما!$B$8,1) -> 52.8 | G41: =IF(V41<=ROUND(349*0.2,0),"بسیار بالا",IF(V41<=ROUND(349*0.4,0),"بالا",IF(V41<=ROUND(349*0.6,0),"متوسط",IF(V41<=ROUND(349*0.8,0),"پایین","بسیار پایین")))) -> متوسط | H41: =(100-I41)*(100-L41)/100 -> 70.649943 | I41: 13.81 | J41: 31.93 | K41: =J41/(1-I41/100) -> 37.046061 | L41: 18.03 | M41: 33.66 | N41: 54.51 | O41: 3.56 | P41: =ROUND(E41*J41/100,0) -> 7624 | Q41: =ROUND(P41*I41/(100-I41),0) -> 1222 | R41: =ROUND(P41*(100-L41)/100,0) -> 6249 | S41: =ROUND(P41*M41/100,0) -> 2566 | T41: 70.55 | U41: 70.75 | V41: =RANK(F41,$F$2:$F$350,0) -> 147 | W41: 379.7 | X41: 90 | Y41: دقیق | Z41: پونک | AA41: A | AB41: 29.23
A42: 41 | B42: 2 | C42: پرواز | D42: 13348 | E42: =ROUND(D42*INDEX(مناطق!$AF$2:$AF$23,B42),0) -> 12268 | F42: =ROUND(100*(راهنما!$B$4*(H42-MIN($H$2:$H$350))/(MAX($H$2:$H$350)-MIN($H$2:$H$350))+راهنما!$B$5*(N42-MIN($N$2:$N$350))/(MAX($N$2:$N$350)-MIN($N$2:$N$350))+راهنما!$B$6*(J42-MIN($J$2:$J$350))/(MAX($J$2:$J$350)-MIN($J$2:$J$350))+راهنما!$B$7*(MAX($I$2:$I$350)-I42)/(MAX($I$2:$I$350)-MIN($I$2:$I$350)))/راهنما!$B$8,1) -> 50.5 | G42: =IF(V42<=ROUND(349*0.2,0),"بسیار بالا",IF(V42<=ROUND(349*0.4,0),"بالا",IF(V42<=ROUND(349*0.6,0),"متوسط",IF(V42<=ROUND(349*0.8,0),"پایین","بسیار پایین")))) -> متوسط | H42: =(100-I42)*(100-L42)/100 -> 70.132803 | I42: 13.81 | J42: 32.04 | K42: =J42/(1-I42/100) -> 37.173686 | L42: 18.63 | M42: 33.66 | N42: 51 | O42: 3.74 | P42: =ROUND(E42*J42/100,0) -> 3931 | Q42: =ROUND(P42*I42/(100-I42),0) -> 630 | R42: =ROUND(P42*(100-L42)/100,0) -> 3199 | S42: =ROUND(P42*M42/100,0) -> 1323 | T42: 69.82 | U42: 70.46 | V42: =RANK(F42,$F$2:$F$350,0) -> 173 | W42: 339.3 | X42: 25 | Y42: دستی (نام مرکب/معادل) | Z42: پرواز | AA42: B | AB42: 26.55
A43: 42 | B43: 2 | C43: شهر آرا | D43: 36305 | E43: =ROUND(D43*INDEX(مناطق!$AF$2:$AF$23,B43),0) -> 33367 | F43: =ROUND(100*(راهنما!$B$4*(H43-MIN($H$2:$H$350))/(MAX($H$2:$H$350)-MIN($H$2:$H$350))+راهنما!$B$5*(N43-MIN($N$2:$N$350))/(MAX($N$2:$N$350)-MIN($N$2:$N$350))+راهنما!$B$6*(J43-MIN($J$2:$J$350))/(MAX($J$2:$J$350)-MIN($J$2:$J$350))+راهنما!$B$7*(MAX($I$2:$I$350)-I43)/(MAX($I$2:$I$350)-MIN($I$2:$I$350)))/راهنما!$B$8,1) -> 50.2 | G43: =IF(V43<=ROUND(349*0.2,0),"بسیار بالا",IF(V43<=ROUND(349*0.4,0),"بالا",IF(V43<=ROUND(349*0.6,0),"متوسط",IF(V43<=ROUND(349*0.8,0),"پایین","بسیار پایین")))) -> متوسط | H43: =(100-I43)*(100-L43)/100 -> 70.055232 | I43: 13.81 | J43: 32.06 | K43: =J43/(1-I43/100) -> 37.196891 | L43: 18.72 | M43: 33.66 | N43: 50.5 | O43: 3.76 | P43: =ROUND(E43*J43/100,0) -> 10697 | Q43: =ROUND(P43*I43/(100-I43),0) -> 1714 | R43: =ROUND(P43*(100-L43)/100,0) -> 8695 | S43: =ROUND(P43*M43/100,0) -> 3601 | T43: 69.71 | U43: 70.41 | V43: =RANK(F43,$F$2:$F$350,0) -> 175 | W43: 360.5 | X43: 93 | Y43: دقیق | Z43: شهرآرا | AA43: A | AB43: 26.18
A44: 43 | B44: 2 | C44: تهران ویلا | D44: 17173 | E44: =ROUND(D44*INDEX(مناطق!$AF$2:$AF$23,B44),0) -> 15783 | F44: =ROUND(100*(راهنما!$B$4*(H44-MIN($H$2:$H$350))/(MAX($H$2:$H$350)-MIN($H$2:$H$350))+راهنما!$B$5*(N44-MIN($N$2:$N$350))/(MAX($N$2:$N$350)-MIN($N$2:$N$350))+راهنما!$B$6*(J44-MIN($J$2:$J$350))/(MAX($J$2:$J$350)-MIN($J$2:$J$350))+راهنما!$B$7*(MAX($I$2:$I$350)-I44)/(MAX($I$2:$I$350)-MIN($I$2:$I$350)))/راهنما!$B$8,1) -> 48.6 | G44: =IF(V44<=ROUND(349*0.2,0),"بسیار بالا",IF(V44<=ROUND(349*0.4,0),"بالا",IF(V44<=ROUND(349*0.6,0),"متوسط",IF(V44<=ROUND(349*0.8,0),"پایین","بسیار پایین")))) -> متوسط | H44: =(100-I44)*(100-L44)/100 -> 69.701853 | I44: 13.81 | J44: 32.14 | K44: =J44/(1-I44/100) -> 37.289709 | L44: 19.13 | M44: 33.66 | N44: 48.11 | O44: 3.89 | P44: =ROUND(E44*J44/100,0) -> 5073 | Q44: =ROUND(P44*I44/(100-I44),0) -> 813 | R44: =ROUND(P44*(100-L44)/100,0) -> 4103 | S44: =ROUND(P44*M44/100,0) -> 1708 | T44: 69.19 | U44: 70.21 | V44: =RANK(F44,$F$2:$F$350,0) -> 184 | W44: 343.6 | X44: 93 | Y44: دقیق | Z44: تهران‌ویلا | AA44: A | AB44: 24.47
A45: 44 | B45: 2 | C45: برق آلستوم(ستارخان) | D45: 26267 | E45: =ROUND(D45*INDEX(مناطق!$AF$2:$AF$23,B45),0) -> 24141 | F45: =ROUND(100*(راهنما!$B$4*(H45-MIN($H$2:$H$350))/(MAX($H$2:$H$350)-MIN($H$2:$H$350))+راهنما!$B$5*(N45-MIN($N$2:$N$350))/(MAX($N$2:$N$350)-MIN($N$2:$N$350))+راهنما!$B$6*(J45-MIN($J$2:$J$350))/(MAX($J$2:$J$350)-MIN($J$2:$J$350))+راهنما!$B$7*(MAX($I$2:$I$350)-I45)/(MAX($I$2:$I$350)-MIN($I$2:$I$350)))/راهنما!$B$8,1) -> 47.1 | G45: =IF(V45<=ROUND(349*0.2,0),"بسیار بالا",IF(V45<=ROUND(349*0.4,0),"بالا",IF(V45<=ROUND(349*0.6,0),"متوسط",IF(V45<=ROUND(349*0.8,0),"پایین","بسیار پایین")))) -> متوسط | H45: =(100-I45)*(100-L45)/100 -> 69.348474 | I45: 13.81 | J45: 32.22 | K45: =J45/(1-I45/100) -> 37.382527 | L45: 19.54 | M45: 33.66 | N45: 45.81 | O45: 4.01 | P45: =ROUND(E45*J45/100,0) -> 7778 | Q45: =ROUND(P45*I45/(100-I45),0) -> 1246 | R45: =ROUND(P45*(100-L45)/100,0) -> 6258 | S45: =ROUND(P45*M45/100,0) -> 2618 | T45: 68.68 | U45: 70.01 | V45: =RANK(F45,$F$2:$F$350,0) -> 199 | W45: 307.4 | X45: 95 | Y45: جایگزین (محله مجاور) | Z45: ستارخان | AA45: B | AB45: 22.89
A46: 45 | B46: 2 | C46: صادقیه | D46: 42945 | E46: =ROUND(D46*INDEX(مناطق!$AF$2:$AF$23,B46),0) -> 39469 | F46: =ROUND(100*(راهنما!$B$4*(H46-MIN($H$2:$H$350))/(MAX($H$2:$H$350)-MIN($H$2:$H$350))+راهنما!$B$5*(N46-MIN($N$2:$N$350))/(MAX($N$2:$N$350)-MIN($N$2:$N$350))+راهنما!$B$6*(J46-MIN($J$2:$J$350))/(MAX($J$2:$J$350)-MIN($J$2:$J$350))+راهنما!$B$7*(MAX($I$2:$I$350)-I46)/(MAX($I$2:$I$350)-MIN($I$2:$I$350)))/راهنما!$B$8,1) -> 45.7 | G46: =IF(V46<=ROUND(349*0.2,0),"بسیار بالا",IF(V46<=ROUND(349*0.4,0),"بالا",IF(V46<=ROUND(349*0.6,0),"متوسط",IF(V46<=ROUND(349*0.8,0),"پایین","بسیار پایین")))) -> متوسط | H46: =(100-I46)*(100-L46)/100 -> 69.020952 | I46: 13.81 | J46: 32.29 | K46: =J46/(1-I46/100) -> 37.463743 | L46: 19.92 | M46: 33.66 | N46: 43.68 | O46: 4.13 | P46: =ROUND(E46*J46/100,0) -> 12745 | Q46: =ROUND(P46*I46/(100-I46),0) -> 2042 | R46: =ROUND(P46*(100-L46)/100,0) -> 10206 | S46: =ROUND(P46*M46/100,0) -> 4290 | T46: 68.19 | U46: 69.82 | V46: =RANK(F46,$F$2:$F$350,0) -> 208 | W46: 279.5 | X46: 92 | Y46: دستی (نام مرکب/معادل) | Z46: صادقیه | AA46: A | AB46: 21.49
A47: 46 | B47: 2 | C47: توحید | D47: 34358 | E47: =ROUND(D47*INDEX(مناطق!$AF$2:$AF$23,B47),0) -> 31577 | F47: =ROUND(100*(راهنما!$B$4*(H47-MIN($H$2:$H$350))/(MAX($H$2:$H$350)-MIN($H$2:$H$350))+راهنما!$B$5*(N47-MIN($N$2:$N$350))/(MAX($N$2:$N$350)-MIN($N$2:$N$350))+راهنما!$B$6*(J47-MIN($J$2:$J$350))/(MAX($J$2:$J$350)-MIN($J$2:$J$350))+راهنما!$B$7*(MAX($I$2:$I$350)-I47)/(MAX($I$2:$I$350)-MIN($I$2:$I$350)))/راهنما!$B$8,1) -> 43.4 | G47: =IF(V47<=ROUND(349*0.2,0),"بسیار بالا",IF(V47<=ROUND(349*0.4,0),"بالا",IF(V47<=ROUND(349*0.6,0),"متوسط",IF(V47<=ROUND(349*0.8,0),"پایین","بسیار پایین")))) -> پایین | H47: =(100-I47)*(100-L47)/100 -> 68.495193 | I47: 13.81 | J47: 32.4 | K47: =J47/(1-I47/100) -> 37.591368 | L47: 20.53 | M47: 33.66 | N47: 40.44 | O47: 4.33 | P47: =ROUND(E47*J47/100,0) -> 10231 | Q47: =ROUND(P47*I47/(100-I47),0) -> 1639 | R47: =ROUND(P47*(100-L47)/100,0) -> 8131 | S47: =ROUND(P47*M47/100,0) -> 3444 | T47: 67.42 | U47: 69.53 | V47: =RANK(F47,$F$2:$F$350,0) -> 231 | W47: 291.7 | X47: 88 | Y47: دقیق | Z47: توحید | AA47: A | AB47: 19.44
A48: 47 | B48: 2 | C48: طرشت | D48: 25110 | E48: =ROUND(D48*INDEX(مناطق!$AF$2:$AF$23,B48),0) -> 23078 | F48: =ROUND(100*(راهنما!$B$4*(H48-MIN($H$2:$H$350))/(MAX($H$2:$H$350)-MIN($H$2:$H$350))+راهنما!$B$5*(N48-MIN($N$2:$N$350))/(MAX($N$2:$N$350)-MIN($N$2:$N$350))+راهنما!$B$6*(J48-MIN($J$2:$J$350))/(MAX($J$2:$J$350)-MIN($J$2:$J$350))+راهنما!$B$7*(MAX($I$2:$I$350)-I48)/(MAX($I$2:$I$350)-MIN($I$2:$I$350)))/راهنما!$B$8,1) -> 42.3 | G48: =IF(V48<=ROUND(349*0.2,0),"بسیار بالا",IF(V48<=ROUND(349*0.4,0),"بالا",IF(V48<=ROUND(349*0.6,0),"متوسط",IF(V48<=ROUND(349*0.8,0),"پایین","بسیار پایین")))) -> پایین | H48: =(100-I48)*(100-L48)/100 -> 68.210766 | I48: 13.81 | J48: 32.46 | K48: =J48/(1-I48/100) -> 37.660982 | L48: 20.86 | M48: 33.66 | N48: 38.75 | O48: 4.43 | P48: =ROUND(E48*J48/100,0) -> 7491 | Q48: =ROUND(P48*I48/(100-I48),0) -> 1200 | R48: =ROUND(P48*(100-L48)/100,0) -> 5928 | S48: =ROUND(P48*M48/100,0) -> 2521 | T48: 67 | U48: 69.37 | V48: =RANK(F48,$F$2:$F$350,0) -> 240 | W48: 252.9 | X48: 87 | Y48: دقیق | Z48: طرشت | AA48: A | AB48: 18.42
...

Sheet مناطق
A1: منطقه | B1: جمعیت محلات (حدود ۱۳۹۵) | C1: جمعیت ۱۰ ساله و بیشتر ۱۳۹۵ | D1: شاغلان ۱۳۹۵ | E1: شاغلان مرد | F1: شاغلان زن | G1: بیکاران ۱۳۹۵ | H1: بیکاران مرد | I1: بیکاران زن | J1: خانه‌دار | K1: محصل | L1: دارای درآمد بدون کار | M1: نرخ بیکاری ٪ | N1: نرخ بیکاری مردان ٪ | O1: نرخ بیکاری زنان ٪ | P1: نرخ مشارکت ٪ | Q1: نسبت اشتغال ٪ | R1: سهم زنان از نیروی کار ٪ | S1: شاغلان ۱۳۸۵ | T1: سهم مزد و حقوق‌بگیر عمومی ٪ (۱۳۸۵) | U1: سهم مزد و حقوق‌بگیر خصوصی ٪ | V1: سهم کارفرمایان ٪ | W1: سهم کارکنان مستقل ٪ | X1: سهم کارکن فامیلی بدون مزد ٪ | Y1: سهم اشتغال آسیب‌پذیر ٪ | Z1: سهم مشاغل تخصصی ٪ | AA1: سهم کارگران ساده ٪ | AB1: نرخ اشتغال پایدار ٪ از نیروی کار | AC1: میانگین وزنی نرخ اشتغال پایدار محلات (کنترل) | AD1: مجموع شاغلان برآوردی محلات (کنترل) | AE1: اختلاف با شاغلان سرشماری ٪ | AF1: نسبت جمعیت ۱۰+ به جمعیت کل
A2: 1 | B2: =SUMIF(محلات!$B$2:$B$350,A2,محلات!$D$2:$D$350) -> 486069 | C2: 450792 | D2: 145591 | E2: 110088 | F2: 35503 | G2: 19414 | H2: 10353 | I2: 9061 | J2: 115548 | K2: 85409 | L2: 55288 | M2: =G2/(D2+G2)*100 -> 11.765704 | N2: =H2/(E2+H2)*100 -> 8.59591 | O2: =I2/(F2+I2)*100 -> 20.332555 | P2: =(D2+G2)/C2*100 -> 36.603356 | Q2: =D2/C2*100 -> 32.296713 | R2: =(F2+I2)/(D2+G2)*100 -> 27.007666 | S2: 122374 | T2: 34.701 | U2: 28.789 | V2: 16.988 | W2: 18.904 | X2: 0.618 | Y2: =W2+X2 -> 19.522 | Z2: 54.008 | AA2: 6.865 | AB2: =(100-M2)*(100-Y2)/100 -> 71.009197 | AC2: =SUMPRODUCT((محلات!$B$2:$B$350=A2)*محلات!$D$2:$D$350*محلات!$H$2:$H$350)/B2 -> 71.005524 | AD2: =SUMIF(محلات!$B$2:$B$350,A2,محلات!$P$2:$P$350) -> 145592 | AE2: =(AD2/D2-1)*100 -> 0.00068685564 | AF2: =C2/B2 -> 0.92742388
A3: 2 | B3: =SUMIF(محلات!$B$2:$B$350,A3,محلات!$D$2:$D$350) -> 691795 | C3: 635807 | D3: 202499 | E3: 144048 | F3: 58451 | G3: 32459 | H3: 17104 | I3: 15355 | J3: 146583 | K3: 121578 | L3: 91512 | M3: =G3/(D3+G3)*100 -> 13.814809 | N3: =H3/(E3+H3)*100 -> 10.613582 | O3: =I3/(F3+I3)*100 -> 20.804542 | P3: =(D3+G3)/C3*100 -> 36.954296 | Q3: =D3/C3*100 -> 31.84913 | R3: =(F3+I3)/(D3+G3)*100 -> 31.412423 | S3: 209644 | T3: 33.664 | U3: 35.466 | V3: 13.173 | W3: 17.08 | X3: 0.618 | Y3: =W3+X3 -> 17.698 | Z3: 56.631 | AA3: 3.48 | AB3: =(100-M3)*(100-Y3)/100 -> 70.932136 | AC3: =SUMPRODUCT((محلات!$B$2:$B$350=A3)*محلات!$D$2:$D$350*محلات!$H$2:$H$350)/B3 -> 70.936061 | AD3: =SUMIF(محلات!$B$2:$B$350,A3,محلات!$P$2:$P$350) -> 202505 | AE3: =(AD3/D3-1)*100 -> 0.0029629776 | AF3: =C3/B3 -> 0.91906851
A4: 3 | B4: =SUMIF(محلات!$B$2:$B$350,A4,محلات!$D$2:$D$350) -> 330004 | C4: 304260 | D4: 99413 | E4: 72411 | F4: 27002 | G4: 13293 | H4: 6817 | I4: 6476 | J4: 74353 | K4: 55816 | L4: 41295 | M4: =G4/(D4+G4)*100 -> 11.794403 | N4: =H4/(E4+H4)*100 -> 8.6042813 | O4: =I4/(F4+I4)*100 -> 19.344047 | P4: =(D4+G4)/C4*100 -> 37.042661 | Q4: =D4/C4*100 -> 32.6737 | R4: =(F4+I4)/(D4+G4)*100 -> 29.703831 | S4: 100463 | T4: 27.108 | U4: 36.216 | V4: 20.659 | W4: 15.093 | X4: 0.923 | Y4: =W4+X4 -> 16.016 | Z4: 58.82 | AA4: 5.18 | AB4: =(100-M4)*(100-Y4)/100 -> 74.078588 | AC4: =SUMPRODUCT((محلات!$B$2:$B$350=A4)*محلات!$D$2:$D$350*محلات!$H$2:$H$350)/B4 -> 74.081751 | AD4: =SUMIF(محلات!$B$2:$B$350,A4,محلات!$P$2:$P$350) -> 99407 | AE4: =(AD4/D4-1)*100 -> -0.006035428 | AF4: =C4/B4 -> 0.92198882
A5: 4 | B5: =SUMIF(محلات!$B$2:$B$350,A5,محلات!$D$2:$D$350) -> 906598 | C5: 802121 | D5: 265455 | E5: 213878 | F5: 51577 | G5: 36217 | H5: 21478 | I5: 14739 | J5: 230597 | K5: 148746 | L5: 70789 | M5: =G5/(D5+G5)*100 -> 12.005423 | N5: =H5/(E5+H5)*100 -> 9.1257499 | O5: =I5/(F5+I5)*100 -> 22.225406 | P5: =(D5+G5)/C5*100 -> 37.609288 | Q5: =D5/C5*100 -> 33.094134 | R5: =(F5+I5)/(D5+G5)*100 -> 21.982816 | S5: 277017 | T5: 31.592 | U5: 34.417 | V5: 11.513 | W5: 22.177 | X5: 0.301 | Y5: =W5+X5 -> 22.478 | Z5: 33.571 | AA5: 4.337 | AB5: =(100-M5)*(100-Y5)/100 -> 68.215156 | AC5: =SUMPRODUCT((محلات!$B$2:$B$350=A5)*محلات!$D$2:$D$350*محلات!$H$2:$H$350)/B5 -> 68.211566 | AD5: =SUMIF(محلات!$B$2:$B$350,A5,محلات!$P$2:$P$350) -> 265458 | AE5: =(AD5/D5-1)*100 -> 0.0011301351 | AF5: =C5/B5 -> 0.88475929
A6: 5 | B6: =SUMIF(محلات!$B$2:$B$350,A6,محلات!$D$2:$D$350) -> 853212 | C6: 767169 | D6: 255117 | E6: 188296 | F6: 66821 | G6: 38563 | H6: 20619 | I6: 17944 | J6: 188812 | K6: 149546 | L6: 87086 | M6: =G6/(D6+G6)*100 -> 13.130959 | N6: =H6/(E6+H6)*100 -> 9.8695642 | O6: =I6/(F6+I6)*100 -> 21.169115 | P6: =(D6+G6)/C6*100 -> 38.281005 | Q6: =D6/C6*100 -> 33.254342 | R6: =(F6+I6)/(D6+G6)*100 -> 28.863048 | S6: 240504 | T6: 36.643 | U6: 32.847 | V6: 12.925 | W6: 17.047 | X6: 0.538 | Y6: =W6+X6 -> 17.585 | Z6: 50.064 | AA6: 3.208 | AB6: =(100-M6)*(100-Y6)/100 -> 71.59312 | AC6: =SUMPRODUCT((محلات!$B$2:$B$350=A6)*محلات!$D$2:$D$350*محلات!$H$2:$H$350)/B6 -> 71.593197 | AD6: =SUMIF(محلات!$B$2:$B$350,A6,محلات!$P$2:$P$350) -> 255115 | AE6: =(AD6/D6-1)*100 -> -0.00078395403 | AF6: =C6/B6 -> 0.89915402
A7: 6 | B7: =SUMIF(محلات!$B$2:$B$350,A7,محلات!$D$2:$D$350) -> 250753 | C7: 233346 | D7: 75454 | E7: 52416 | F7: 23038 | G7: 10873 | H7: 5705 | I7: 5168 | J7: 50454 | K7: 52094 | L7: 28891 | M7: =G7/(D7+G7)*100 -> 12.595132 | N7: =H7/(E7+H7)*100 -> 9.8157293 | O7: =I7/(F7+I7)*100 -> 18.322343 | P7: =(D7+G7)/C7*100 -> 36.995277 | Q7: =D7/C7*100 -> 32.335673 | R7: =(F7+I7)/(D7+G7)*100 -> 32.673439 | S7: 80451 | T7: 37.27 | U7: 32.993 | V7: 12.958 | W7: 15.968 | X7: 0.813 | Y7: =W7+X7 -> 16.781 | Z7: 57.177 | AA7: 4.562 | AB7: =(100-M7)*(100-Y7)/100 -> 72.737457 | AC7: =SUMPRODUCT((محلات!$B$2:$B$350=A7)*محلات!$D$2:$D$350*محلات!$H$2:$H$350)/B7 -> 72.73418 | AD7: =SUMIF(محلات!$B$2:$B$350,A7,محلات!$P$2:$P$350) -> 75449 | AE7: =(AD7/D7-1)*100 -> -0.0066265539 | AF7: =C7/B7 -> 0.93058109
A8: 7 | B8: =SUMIF(محلات!$B$2:$B$350,A8,محلات!$D$2:$D$350) -> 312002 | C8: 282523 | D8: 97793 | E8: 73072 | F8: 24721 | G8: 12204 | H8: 7112 | I8: 5092 | J8: 73600 | K8: 47958 | L8: 31795 | M8: =G8/(D8+G8)*100 -> 11.094848 | N8: =H8/(E8+H8)*100 -> 8.8695999 | O8: =I8/(F8+I8)*100 -> 17.079797 | P8: =(D8+G8)/C8*100 -> 38.933821 | Q8: =D8/C8*100 -> 34.614173 | R8: =(F8+I8)/(D8+G8)*100 -> 27.103466 | S8: 110064 | T8: 34.783 | U8: 35.76 | V8: 9.888 | W8: 19.243 | X8: 0.326 | Y8: =W8+X8 -> 19.569 | Z8: 43.375 | AA8: 4.159 | AB8: =(100-M8)*(100-Y8)/100 -> 71.507303 | AC8: =SUMPRODUCT((محلات!$B$2:$B$350=A8)*محلات!$D$2:$D$350*محلات!$H$2:$H$350)/B8 -> 71.510604 | AD8: =SUMIF(محلات!$B$2:$B$350,A8,محلات!$P$2:$P$350) -> 97791 | AE8: =(AD8/D8-1)*100 -> -0.0020451362 | AF8: =C8/B8 -> 0.90551663
A9: 8 | B9: =SUMIF(محلات!$B$2:$B$350,A9,محلات!$D$2:$D$350) -> 425044 | C9: 379995 | D9: 127225 | E9: 98160 | F9: 29065 | G9: 18004 | H9: 10162 | I9: 7842 | J9: 105142 | K9: 65476 | L9: 40373 | M9: =G9/(D9+G9)*100 -> 12.396973 | N9: =H9/(E9+H9)*100 -> 9.3812891 | O9: =I9/(F9+I9)*100 -> 21.248002 | P9: =(D9+G9)/C9*100 -> 38.218661 | Q9: =D9/C9*100 -> 33.480704 | R9: =(F9+I9)/(D9+G9)*100 -> 25.412968 | S9: 130949 | T9: 34.2 | U9: 34.768 | V9: 11.032 | W9: 19.585 | X9: 0.416 | Y9: =W9+X9 -> 20.001 | Z9: 37.11 | AA9: 3.847 | AB9: =(100-M9)*(100-Y9)/100 -> 70.081546 | AC9: =SUMPRODUCT((محلات!$B$2:$B$350=A9)*محلات!$D$2:$D$350*محلات!$H$2:$H$350)/B9 -> 70.078506 | AD9: =SUMIF(محلات!$B$2:$B$350,A9,محلات!$P$2:$P$350) -> 127224 | AE9: =(AD9/D9-1)*100 -> -0.00078600904 | AF9: =C9/B9 -> 0.89401333
A10: 9 | B10: =SUMIF(محلات!$B$2:$B$350,A10,محلات!$D$2:$D$350) -> 174115 | C10: 151018 | D10: 50322 | E10: 41459 | F10: 8863 | G10: 7209 | H10: 4394 | I10: 2815 | J10: 44119 | K10: 27301 | L10: 13143 | M10: =G10/(D10+G10)*100 -> 12.530636 | N10: =H10/(E10+H10)*100 -> 9.5827972 | O10: =I10/(F10+I10)*100 -> 24.105155 | P10: =(D10+G10)/C10*100 -> 38.095459 | Q10: =D10/C10*100 -> 33.321856 | R10: =(F10+I10)/(D10+G10)*100 -> 20.298622 | S10: 55678 | T10: 46.319 | U10: 28.106 | V10: 7.761 | W10: 17.668 | X10: 0.146 | Y10: =W10+X10 -> 17.814 | Z10: 27.402 | AA10: 7.027 | AB10: =(100-M10)*(100-Y10)/100 -> 71.887572 | AC10: =SUMPRODUCT((محلات!$B$2:$B$350=A10)*محلات!$D$2:$D$350*محلات!$H$2:$H$350)/B10 -> 71.887107 | AD10: =SUMIF(محلات!$B$2:$B$350,A10,محلات!$P$2:$P$350) -> 50320 | AE10: =(AD10/D10-1)*100 -> -0.0039744048 | AF10: =C10/B10 -> 0.86734629
A11: 10 | B11: =SUMIF(محلات!$B$2:$B$350,A11,محلات!$D$2:$D$350) -> 326885 | C11: 287663 | D11: 100338 | E11: 79524 | F11: 20814 | G11: 14052 | H11: 8476 | I11: 5576 | J11: 81735 | K11: 46736 | L11: 26789 | M11: =G11/(D11+G11)*100 -> 12.284291 | N11: =H11/(E11+H11)*100 -> 9.6318182 | O11: =I11/(F11+I11)*100 -> 21.129216 | P11: =(D11+G11)/C11*100 -> 39.765281 | Q11: =D11/C11*100 -> 34.880398 | R11: =(F11+I11)/(D11+G11)*100 -> 23.070198 | S11: 108470 | T11: 37.523 | U11: 32.925 | V11: 8.561 | W11: 20.349 | X11: 0.641 | Y11: =W11+X11 -> 20.99 | Z11: 32.602 | AA11: 5.055 | AB11: =(100-M11)*(100-Y11)/100 -> 69.304182 | AC11: =SUMPRODUCT((محلات!$B$2:$B$350=A11)*محلات!$D$2:$D$350*محلات!$H$2:$H$350)/B11 -> 69.306853 | AD11: =SUMIF(محلات!$B$2:$B$350,A11,محلات!$P$2:$P$350) -> 100334 | AE11: =(AD11/D11-1)*100 -> -0.0039865255 | AF11: =C11/B11 -> 0.88001285
A12: 11 | B12: =SUMIF(محلات!$B$2:$B$350,A12,محلات!$D$2:$D$350) -> 307469 | C12: 271859 | D12: 95523 | E12: 75913 | F12: 19610 | G12: 10543 | H12: 6487 | I12: 4056 | J12: 76171 | K12: 49917 | L12: 21609 | M12: =G12/(D12+G12)*100 -> 9.9400373 | N12: =H12/(E12+H12)*100 -> 7.8725728 | O12: =I12/(F12+I12)*100 -> 17.138511 | P12: =(D12+G12)/C12*100 -> 39.015078 | Q12: =D12/C12*100 -> 35.136964 | R12: =(F12+I12)/(D12+G12)*100 -> 22.312522 | S12: 98208 | T12: 37.033 | U12: 31.387 | V12: 8.452 | W12: 22.623 | X12: 0.506 | Y12: =W12+X12 -> 23.129 | Z12: 34.089 | AA12: 5.404 | AB12: =(100-M12)*(100-Y12)/100 -> 69.229994 | AC12: =SUMPRODUCT((محلات!$B$2:$B$350=A12)*محلات!$D$2:$D$350*محلات!$H$2:$H$350)/B12 -> 69.228232 | AD12: =SUMIF(محلات!$B$2:$B$350,A12,محلات!$P$2:$P$350) -> 95525 | AE12: =(AD12/D12-1)*100 -> 0.0020937366 | AF12: =C12/B12 -> 0.88418345
A13: 12 | B13: =SUMIF(محلات!$B$2:$B$350,A13,محلات!$D$2:$D$350) -> 240909 | C13: 208406 | D13: 72351 | E13: 62542 | F13: 9809 | G13: 6710 | H13: 4657 | I13: 2053 | J13: 65250 | K13: 38281 | L13: 12679 | M13: =G13/(D13+G13)*100 -> 8.4871175 | N13: =H13/(E13+H13)*100 -> 6.9301627 | O13: =I13/(F13+I13)*100 -> 17.307368 | P13: =(D13+G13)/C13*100 -> 37.936048 | Q13: =D13/C13*100 -> 34.716371 | R13: =(F13+I13)/(D13+G13)*100 -> 15.003605 | S13: 85773 | T13: 22.867 | U13: 37.074 | V13: 10.586 | W13: 28.662 | X13: 0.811 | Y13: =W13+X13 -> 29.473 | Z13: 23.285 | AA13: 11.235 | AB13: =(100-M13)*(100-Y13)/100 -> 64.541291 | AC13: =SUMPRODUCT((محلات!$B$2:$B$350=A13)*محلات!$D$2:$D$350*محلات!$H$2:$H$350)/B13 -> 64.538928 | AD13: =SUMIF(محلات!$B$2:$B$350,A13,محلات!$P$2:$P$350) -> 72352 | AE13: =(AD13/D13-1)*100 -> 0.0013821509 | AF13: =C13/B13 -> 0.86508184
... A23: 22 | B23: =SUMIF(محلات!$B$2:$B$350,A23,محلات!$D$2:$D$350) -> 174227 | C23: 153510 | D23: 48879 | E23: 39647 | F23: 9232 | G23: 7729 | H23: 4405 | I23: 3324 | J23: 41380 | K23: 31688 | L23: 14783 | M23: =G23/(D23+G23)*100 -> 13.653547 | N23: =H23/(E23+H23)*100 -> 9.999546 | O23: =I23/(F23+I23)*100 -> 26.473399 | P23: =(D23+G23)/C23*100 -> 36.875774 | Q23: =D23/C23*100 -> 31.840922 | R23: =(F23+I23)/(D23+G23)*100 -> 22.180611 | S23: 35913 | T23: 41.164 | U23: 26.569 | V23: 10.743 | W23: 20.956 | X23: 0.565 | Y23: =W23+X23 -> 21.521 | Z23: 32.416 | AA23: 6.651 | AB23: =(100-M23)*(100-Y23)/100 -> 67.763833 | AC23: =SUMPRODUCT((محلات!$B$2:$B$350=A23)*محلات!$D$2:$D$350*محلات!$H$2:$H$350)/B23 -> 67.765409 | AD23: =SUMIF(محلات!$B$2:$B$350,A23,محلات!$P$2:$P$350) -> 48878 | AE23: =(AD23/D23-1)*100 -> -0.0020458684 | AF23: =C23/B23 -> 0.88109191
A24: کل شهر | B24: =SUM(B2:B23) -> 8627281 | C24: =SUM(C2:C23) -> 7644828 | D24: =SUM(D2:D23) -> 2546775 | E24: =SUM(E2:E23) -> 2040876 | F24: =SUM(F2:F23) -> 505899 | G24: =SUM(G2:G23) -> 330922 | H24: =SUM(H2:H23) -> 198511 | I24: =SUM(I2:I23) -> 132411 | ... L24: =SUM(L2:L23) -> 729447 | M24: =G24/(D24+G24)*100 -> 11.499543 | P24: =(D24+G24)/C24*100 -> 37.642403 | Q24: =D24/C24*100 -> 33.313699 | S24: =SUM(S2:S23) -> 2629106 | AD24: =SUM(AD2:AD23) -> 2546746

Sheet مدل و اعتبارسنجی
A1: مدل کوچک‌ناحیه‌ای: logit(شاخص منطقه) = a + b × ln(قیمت هر متر مسکن) ؛ ۲۲ منطقه
A3: شاخص | B3: شیب b | C3: خطای معیار b | D3: R² | E3: همبستگی با قیمت | F3: میانگین خطای مطلق حذف‌یک‌منطقه (واحد درصد) | G3: استفاده برای تفکیک درون‌منطقه‌ای؟
A4: نرخ بیکاری | B4: 0.191 | C4: 0.075 | D4: 0.247 | E4: 0.488 | F4: 1.28 | G4: خیر (مقدار منطقه برای همه محلات)
A5: نرخ مشارکت | B5: -0.028 | C5: 0.019 | D5: 0.094 | E5: -0.307 | F5: 0.68 | G5: خیر (مقدار منطقه برای همه محلات)
A6: نسبت اشتغال | B6: -0.057 | C6: 0.022 | D6: 0.257 | E6: -0.507 | F6: 0.78 | G6: بله
A7: سهم بخش عمومی | B7: 0.075 | C7: 0.136 | D7: 0.015 | E7: 0.107 | F7: 4.77 | G7: خیر (مقدار منطقه برای همه محلات)
A8: سهم اشتغال آسیب‌پذیر | B8: -0.427 | C8: 0.091 | D8: 0.524 | E8: -0.717 | F8: 2.63 | G8: بله
A9: سهم مشاغل تخصصی | B9: 1.508 | C9: 0.175 | D9: 0.788 | E9: 0.902 | F9: 5.54 | G9: بله
A10: سهم کارگران ساده | B10: -0.536 | C10: 0.172 | D10: 0.325 | E10: -0.57 | F10: 1.77 | G10: بله
A11: نرخ اشتغال پایدار | B11: 0.239 | C11: 0.049 | D11: 0.539 | E11: 0.732 | F11: 1.98 | G11: بله
A12: نرخ بیکاری زنان | B12: -0.079 | C12: 0.075 | D12: 0.053 | E12: -0.231 | F12: 1.87 | G12: خیر (مقدار منطقه برای همه محلات)
A13: نرخ بیکاری مردان | B13: 0.108 | C13: 0.065 | D13: 0.122 | E13: 0.341 | F13: 0.9 | G13: خیر (مقدار منطقه برای همه محلات)
A16: معیار استفاده: R² ≥ ۰٫۲۵ و معناداری شیب در سطح ۹۵٪. شاخص‌هایی که رابطه معنادار با قیمت ندارند (بیکاری، بخش عمومی، مشارکت) در همه محلات یک منطقه برابر رقم سرشماری منطقه‌اند.
A17: برای شاخص‌های پذیرفته‌شده: logit(محله) = logit(منطقه) + c + b × (ln قیمت محله − میانگین منطقه)؛ c طوری تعیین شد که میانگین وزنی جمعیتی محلات = رقم سرشماری منطقه.
A18: قیمت محله با روش بیزی تجربی به سمت میانگین منطقه منقبض شده (محلات کم‌آگهی) — همان داده و روش فایل تحصیلات نسخه ۲.
A19: بازه پایین/بالا: با شیب b ± ۱٫۹۶ خطای معیار.
A20: نکته مهم: رابطه بیکاری با قیمت در ۱۳۹۵ مثبت است (مناطق مرفه بیکاری کمی بالاتر دارند، عمدتاً به سبب ورود زنان تحصیل‌کرده به بازار کار)، بنابراین بیکاری به‌تنهایی معیار مناسب «پایداری» نیست.

Sheet داده خام ۱۳۸۵
A1: منطقه | B1: شاغلان کل | C1: بخش خصوصی جمع | D1: کارفرمایان | E1: کارکنان مستقل | F1: مزد و حقوق‌بگیر خصوصی | G1: کارکن فامیلی بدون مزد | H1: مزد و حقوق‌بگیر عمومی | I1: اظهارنشده | J1: مدیران | K1: متخصصان | L1: تکنسین‌ها | M1: کارمندان اداری | N1: خدماتی و فروشندگان | O1: کشاورزی ماهر | P1: صنعتگران | Q1: متصدیان و رانندگان | R1: کارگران ساده | S1: سایر/اظهارنشده
A2: 1 | B2: 122374 | C2: 77967 | D2: 20284 | E2: 22571 | F2: 34374 | G2: 738 | H2: 41433 | I2: 2974 | J2: 17009 | K2: 30987 | L2: 11515 | M2: 7647 | N2: 20844 | O2: 452 | P2: 9206 | Q2: 4966 | R2: 7564 | S2: 12184
A3: 2 | B3: 209644 | C3: 135938 | D3: 26994 | E3: 35001 | F3: 72677 | G3: 1266 | H3: 68984 | I3: 4722 | J3: 27788 | K3: 60206 | L3: 26295 | M3: 16268 | N3: 33737 | O3: 1086 | P3: 18611 | Q3: 10798 | R3: 7024 | S3: 7829
A4: 3 | B4: 100463 | C4: 71463 | D4: 20254 | E4: 14797 | F4: 35506 | G4: 905 | H4: 26576 | I4: 2424 | J4: 16230 | K4: 30639 | L4: 9081 | M4: 5561 | N4: 17579 | O4: 510 | P4: 6934 | Q4: 3659 | R4: 4927 | S4: 5343
A5: 4 | B5: 277017 | C5: 185289 | D5: 31185 | E5: 60067 | F5: 93221 | G5: 815 | H5: 85569 | I5: 6160 | J5: 15519 | K5: 43554 | L5: 26277 | M5: 21477 | N5: 42566 | O5: 980 | P5: 64551 | Q5: 28286 | R5: 11027 | S5: 22779
A6: 5 | B6: 240504 | C6: 149414 | D6: 30481 | E6: 40202 | F6: 77463 | G6: 1268 | H6: 86415 | I6: 4675 | J6: 23474 | K6: 58068 | L6: 33218 | M6: 21159 | N6: 38147 | O6: 1235 | P6: 28539 | Q6: 18034 | R6: 7354 | S6: 11277
A7: 6 | B7: 80451 | C7: 49298 | D7: 10183 | E7: 12549 | F7: 25928 | G7: 639 | H7: 29289 | I7: 1864 | J7: 8571 | K7: 25009 | L7: 8845 | M7: 6911 | N7: 13387 | O7: 304 | P7: 5278 | Q7: 2509 | R7: 3385 | S7: 6251
A8: 7 | B8: 110064 | C8: 70562 | D8: 10698 | E8: 20820 | F8: 38691 | G8: 353 | H8: 37634 | I8: 1868 | J8: 6842 | K8: 24517 | L8: 13260 | M8: 11584 | N8: 17860 | O8: 152 | P8: 16281 | Q8: 8093 | R8: 4278 | S8: 7197
A9: 8 | B9: 130949 | C9: 84796 | D9: 14216 | E9: 25239 | F9: 44804 | G9: 536 | H9: 44072 | I9: 2082 | J9: 7376 | K9: 23230 | L9: 15753 | M9: 14165 | N9: 20342 | O9: 322 | P9: 25040 | Q9: 13891 | R9: 4806 | S9: 6025
