Workbook

Sheet راهنما
A1: سطح تحصیلات ساکنان محلات تهران — نسخه ۲ (برآورد کوچک‌ناحیه‌ای)
A3: تعداد محلات | B3: =COUNTA(محلات!C2:C350) -> 349
A4: جمعیت کل | B4: =SUM(محلات!D2:D350) -> 8627281
A5: تعداد برآوردی دانش‌آموختگان دانشگاهی | B5: =SUM(محلات!J2:J350) -> 1540308
A6: سهم وزنی دانش‌آموختگان در شهر ٪ | B6: =B5/B4*100 -> 17.853922
A7: محلات با سطح «بسیار بالا» | B7: =COUNTIF(محلات!Q2:Q350,"بسیار بالا") -> 50
A8: محلات با سطح «بالا» | B8: =COUNTIF(محلات!Q2:Q350,"بالا") -> 68
A9: محلات با سطح «متوسط» | B9: =COUNTIF(محلات!Q2:Q350,"متوسط") -> 92
A10: محلات با سطح «پایین» | B10: =COUNTIF(محلات!Q2:Q350,"پایین") -> 68
A11: محلات با سطح «بسیار پایین» | B11: =COUNTIF(محلات!Q2:Q350,"بسیار پایین") -> 71
A12: محلات دارای داده قیمت (کیفیت A تا C) | B12: =COUNTIF(محلات!X2:X350,"<>D") -> 280
A13: محلات با کیفیت A | B13: =COUNTIF(محلات!X2:X350,"A") -> 254
A14: بیشترین سهم برآوردی محله ٪ | B14: =MAX(محلات!E2:E350) -> 46.93
A15: کمترین سهم برآوردی محله ٪ | B15: =MIN(محلات!E2:E350) -> 2.58
A16: تعداد آگهی معتبر قیمت | B16: 23102
A18: چه چیزی تغییر کرد نسبت به نسخه ۱؟ در نسخه ۱ همه محلات یک منطقه مقدار یکسان داشتند. در این نسخه، با استفاده از قیمت هر متر مسکن در ۳۱۱ محله (۲۳ هزار آگهی)، تفاوت درون هر منطقه برآورد و سپس با رقم رسمی سرشماری همان منطقه کالیبره شده است.
A19: شیت «محلات»: برآورد هر محله، بازه عدم قطعیت، مقایسه با روش قبلی، و درجه کیفیت داده (A بهترین تا D فقط مقدار منطقه).
A20: شیت «مناطق»: کنترل کالیبراسیون (ستون E باید برابر D باشد) و دقت مدل در سطح منطقه.
A21: شیت «مدل و اعتبارسنجی»: ضرایب، R² و خطای اعتبارسنجی حذف‌یک‌منطقه.
A22: شیت‌های «داده قیمت دیوار» و «جدول تطبیق»: داده خام کمکی و نحوه تطبیق نام محلات.
A23: هشدار: ارقام محله‌ای برآوردی‌اند، نه شمارش مستقیم سرشماری.

Sheet محلات
A1: ردیف | B1: منطقه | C1: محله | D1: جمعیت (حدود ۱۳۹۵) | E1: سهم دانش‌آموختگان دانشگاهی از کل جمعیت ٪ (برآورد تعدیل‌شده) | F1: حد پایین بازه ٪ | G1: حد بالای بازه ٪ | H1: مقدار میانگین منطقه ٪ (روش نسخه ۱) | I1: اختلاف با میانگین منطقه (واحد درصد) | J1: تعداد برآوردی دانش‌آموختگان دانشگاهی | K1: مردان دارای تحصیلات دانشگاهی ٪ | L1: زنان دارای تحصیلات دانشگاهی ٪ | M1: باسوادی ۳۰ تا ۵۹ سال ٪ | N1: باسوادی ۶۰ سال و بالاتر ٪ | O1: استفاده از اینترنت ٪ | P1: رتبه در شهر (سهم دانش‌آموختگان) | Q1: سطح تحصیلات | R1: قیمت میانه هر متر (میلیون تومان، دیوار) | S1: انحراف لگاریتم قیمت از میانگین منطقه | T1: تعداد آگهی معتبر | U1: نوع تطبیق | V1: محله(های) دیوار استفاده‌شده | W1: وزن اعتماد به داده محله (۰ تا ۱) | X1: درجه کیفیت داده
A2: 1 | B2: 1 | C2: ولنجک | D2: 26587 | E2: 45.85 | F2: 42.72 | G2: 48.96 | H2: 31.3 | I2: =E2-H2 -> 14.55 | J2: =ROUND(D2*E2/100,0) -> 12190 | K2: 65.38 | L2: 56.8 | M2: 98.56 | N2: 96.64 | O2: 62.76 | P2: =RANK(E2,$E$2:$E$350,0) -> 3 | Q2: =IF(E2>=30,"بسیار بالا",IF(E2>=20,"بالا",IF(E2>=13,"متوسط",IF(E2>=8,"پایین","بسیار پایین")))) -> بسیار بالا | R2: 844.4 | S2: 0.455 | T2: 88 | U2: دقیق (نام یکسان) | V2: ولنجک | W2: 0.99 | X2: A
A3: 2 | B3: 1 | C3: زعفرانیه | D3: 30377 | E3: 45.56 | F3: 42.49 | G3: 48.6 | H3: 31.3 | I3: =E3-H3 -> 14.26 | J3: =ROUND(D3*E3/100,0) -> 13840 | K3: 65.11 | L3: 56.56 | M3: 98.55 | N3: 96.59 | O3: 62.5 | P3: =RANK(E3,$E$2:$E$350,0) -> 4 | Q3: =IF(E3>=30,"بسیار بالا",IF(E3>=20,"بالا",IF(E3>=13,"متوسط",IF(E3>=8,"پایین","بسیار پایین")))) -> بسیار بالا | R3: 831.2 | S3: 0.447 | T3: 87 | U3: دقیق (نام یکسان) | V3: زعفرانیه | W3: 0.98 | X3: A
A4: 3 | B4: 1 | C4: محمودیه | D4: 8763 | E4: 39.73 | F4: 37.98 | G4: 41.45 | H4: 31.3 | I4: =E4-H4 -> 8.43 | J4: =ROUND(D4*E4/100,0) -> 3482 | K4: 59.52 | L4: 51.69 | M4: 98.27 | N4: 95.27 | O4: 57.32 | P4: =RANK(E4,$E$2:$E$350,0) -> 6 | Q4: =IF(E4>=30,"بسیار بالا",IF(E4>=20,"بالا",IF(E4>=13,"متوسط",IF(E4>=8,"پایین","بسیار پایین")))) -> بسیار بالا | R4: 704.4 | S4: 0.28 | T4: 88 | U4: دقیق (نام یکسان) | V4: محمودیه | W4: 0.99 | X4: A
A5: 4 | B5: 1 | C5: باغ فردوس | D5: 17579 | E5: 39.26 | F5: 37.61 | G5: 40.87 | H5: 31.3 | I5: =E5-H5 -> 7.96 | J5: =ROUND(D5*E5/100,0) -> 6902 | K5: 59.05 | L5: 51.29 | M5: 98.25 | N5: 95.14 | O5: 56.88 | P5: =RANK(E5,$E$2:$E$350,0) -> 7 | Q5: =IF(E5>=30,"بسیار بالا",IF(E5>=20,"بالا",IF(E5>=13,"متوسط",IF(E5>=8,"پایین","بسیار پایین")))) -> بسیار بالا | R5: 650 | S5: 0.266 | T5: 13 | U5: دقیق (نام یکسان) | V5: باغ فردوس | W5: 0.87 | X5: B
A6: 5 | B6: 1 | C6: فرمانیه | D6: 22574 | E6: 39.18 | F6: 37.55 | G6: 40.78 | H6: 31.3 | I6: =E6-H6 -> 7.88 | J6: =ROUND(D6*E6/100,0) -> 8844 | K6: 58.97 | L6: 51.22 | M6: 98.25 | N6: 95.12 | O6: 56.81 | P6: =RANK(E6,$E$2:$E$350,0) -> 8 | Q6: =IF(E6>=30,"بسیار بالا",IF(E6>=20,"بالا",IF(E6>=13,"متوسط",IF(E6>=8,"پایین","بسیار پایین")))) -> بسیار بالا | R6: 682.1 | S6: 0.264 | T6: 88 | U6: دقیق (نام یکسان) | V6: فرمانیه | W6: 0.98 | X6: A
A7: 6 | B7: 1 | C7: حصار بوعلی | D7: 13368 | E7: 37.89 | F7: 36.55 | G7: 39.19 | H7: 31.3 | I7: =E7-H7 -> 6.59 | J7: =ROUND(D7*E7/100,0) -> 5065 | K7: 57.64 | L7: 50.1 | M7: 98.17 | N7: 94.74 | O7: 55.59 | P7: =RANK(E7,$E$2:$E$350,0) -> 12 | Q7: =IF(E7>=30,"بسیار بالا",IF(E7>=20,"بالا",IF(E7>=13,"متوسط",IF(E7>=8,"پایین","بسیار پایین")))) -> بسیار بالا | R7: 653.3 | S7: 0.225 | T7: 87 | U7: دقیق (نام یکسان) | V7: حصار بوعلی | W7: 0.99 | X7: A
A8: 7 | B8: 1 | C8: نیاوران | D8: 9791 | E8: 37.42 | F8: 36.19 | G8: 38.61 | H8: 31.3 | I8: =E8-H8 -> 6.12 | J8: =ROUND(D8*E8/100,0) -> 3664 | K8: 57.15 | L8: 49.69 | M8: 98.15 | N8: 94.6 | O8: 55.14 | P8: =RANK(E8,$E$2:$E$350,0) -> 13 | Q8: =IF(E8>=30,"بسیار بالا",IF(E8>=20,"بالا",IF(E8>=13,"متوسط",IF(E8>=8,"پایین","بسیار پایین")))) -> بسیار بالا | R8: 671.2 | S8: 0.211 | T8: 90 | U8: دستی (نام مرکب/معادل) | V8: نیاوران | W8: 0.99 | X8: A
A9: 8 | B9: 1 | C9: جماران | D9: 8373 | E9: 37.31 | F9: 36.1 | G9: 38.48 | H9: 31.3 | I9: =E9-H9 -> 6.01 | J9: =ROUND(D9*E9/100,0) -> 3124 | K9: 57.04 | L9: 49.59 | M9: 98.14 | N9: 94.56 | O9: 55.04 | P9: =RANK(E9,$E$2:$E$350,0) -> 14 | Q9: =IF(E9>=30,"بسیار بالا",IF(E9>=20,"بالا",IF(E9>=13,"متوسط",IF(E9>=8,"پایین","بسیار پایین")))) -> بسیار بالا | R9: 646.9 | S9: 0.208 | T9: 91 | U9: دقیق (نام یکسان) | V9: جماران (نیاوران) | W9: 0.99 | X9: A
A10: 9 | B10: 1 | C10: امامزاده قاسم | D10: 23845 | E10: 37.06 | F10: 35.91 | G10: 38.17 | H10: 31.3 | I10: =E10-H10 -> 5.76 | J10: =ROUND(D10*E10/100,0) -> 8837 | K10: 56.77 | L10: 49.37 | M10: 98.13 | N10: 94.48 | O10: 54.8 | P10: =RANK(E10,$E$2:$E$350,0) -> 17 | Q10: =IF(E10>=30,"بسیار بالا",IF(E10>=20,"بالا",IF(E10>=13,"متوسط",IF(E10>=8,"پایین","بسیار پایین")))) -> بسیار بالا | R10: 636.8 | S10: 0.201 | T10: 86 | U10: دقیق (نام یکسان) | V10: امام زاده قاسم (نیاوران) | W10: 0.98 | X10: A
A11: 10 | B11: 1 | C11: دزاشیب | D11: 15178 | E11: 35.9 | F11: 35 | G11: 36.74 | H11: 31.3 | I11: =E11-H11 -> 4.6 | J11: =ROUND(D11*E11/100,0) -> 5449 | K11: 55.54 | L11: 48.34 | M11: 98.06 | N11: 94.1 | O11: 53.67 | P11: =RANK(E11,$E$2:$E$350,0) -> 19 | Q11: =IF(E11>=30,"بسیار بالا",IF(E11>=20,"بالا",IF(E11>=13,"متوسط",IF(E11>=8,"پایین","بسیار پایین")))) -> بسیار بالا | R11: 608.8 | S11: 0.165 | T11: 88 | U11: دقیق (نام یکسان) | V11: دزاشیب | W11: 0.98 | X11: A
A12: 11 | B12: 1 | C12: کاشانک | D12: 30216 | E12: 33.18 | F12: 32.88 | G12: 33.42 | H12: 31.3 | I12: =E12-H12 -> 1.88 | J12: =ROUND(D12*E12/100,0) -> 10026 | K12: 52.55 | L12: 45.87 | M12: 97.88 | N12: 93.07 | O12: 50.95 | P12: =RANK(E12,$E$2:$E$350,0) -> 32 | Q12: =IF(E12>=30,"بسیار بالا",IF(E12>=20,"بالا",IF(E12>=13,"متوسط",IF(E12>=8,"پایین","بسیار پایین")))) -> بسیار بالا | R12: 595.9 | S12: 0.081 | T12: 90 | U12: دقیق (نام یکسان) | V12: کاشانک | W12: 0.99 | X12: A
A13: 12 | B13: 1 | C13: قیطریه | D13: 24680 | E13: 32.08 | F13: 32.02 | G13: 32.09 | H13: 31.3 | I13: =E13-H13 -> 0.78 | J13: =ROUND(D13*E13/100,0) -> 7917 | K13: 51.31 | L13: 44.86 | M13: 97.8 | N13: 92.59 | O13: 49.82 | P13: =RANK(E13,$E$2:$E$350,0) -> 35 | Q13: =IF(E13>=30,"بسیار بالا",IF(E13>=20,"بالا",IF(E13>=13,"متوسط",IF(E13>=8,"پایین","بسیار پایین")))) -> بسیار بالا | R13: 562.5 | S13: 0.046 | T13: 89 | U13: دقیق (نام یکسان) | V13: قیطریه | W13: 0.99 | X13: A
A14: 13 | B14: 1 | C14: تجریش | D14: 14564 | E14: 30.93 | F14: 30.69 | G14: 31.11 | H14: 31.3 | I14: =E14-H14 -> -0.37 | J14: =ROUND(D14*E14/100,0) -> 4505 | K14: 49.97 | L14: 43.77 | M14: 97.72 | N14: 92.05 | O14: 48.61 | P14: =RANK(E14,$E$2:$E$350,0) -> 45 | Q14: =IF(E14>=30,"بسیار بالا",IF(E14>=20,"بالا",IF(E14>=13,"متوسط",IF(E14>=8,"پایین","بسیار پایین")))) -> بسیار بالا | R14: 546.9 | S14: 0.008 | T14: 82 | U14: دقیق (نام یکسان) | V14: تجریش | W14: 0.98 | X14: A
A15: 14 | B15: 1 | C15: اراج | D15: 16408 | E15: 30.67 | F15: 30.38 | G15: 30.91 | H15: 31.3 | I15: =E15-H15 -> -0.63 | J15: =ROUND(D15*E15/100,0) -> 5032 | K15: 49.67 | L15: 43.53 | M15: 97.7 | N15: 91.92 | O15: 48.34 | P15: =RANK(E15,$E$2:$E$350,0) -> 46 | Q15: =IF(E15>=30,"بسیار بالا",IF(E15>=20,"بالا",IF(E15>=13,"متوسط",IF(E15>=8,"پایین","بسیار پایین")))) -> بسیار بالا | S15: 0 | T15: 0 | U15: بدون تطبیق | V15: — | W15: 0 | X15: D
A16: 15 | B16: 1 | C16: کوهسار | D16: 1088 | E16: 30.67 | F16: 30.38 | G16: 30.91 | H16: 31.3 | I16: =E16-H16 -> -0.63 | J16: =ROUND(D16*E16/100,0) -> 334 | K16: 49.67 | L16: 43.53 | M16: 97.7 | N16: 91.92 | O16: 48.34 | P16: =RANK(E16,$E$2:$E$350,0) -> 46 | Q16: =IF(E16>=30,"بسیار بالا",IF(E16>=20,"بالا",IF(E16>=13,"متوسط",IF(E16>=8,"پایین","بسیار پایین")))) -> بسیار بالا | S16: 0 | T16: 0 | U16: بدون تطبیق | V16: — | W16: 0 | X16: D
A17: 16 | B17: 1 | C17: حکمت | D17: 40434 | E17: 29.46 | F17: 28.92 | G17: 29.95 | H17: 31.3 | I17: =E17-H17 -> -1.84 | J17: =ROUND(D17*E17/100,0) -> 11912 | K17: 48.24 | L17: 42.37 | M17: 97.6 | N17: 91.29 | O17: 47.04 | P17: =RANK(E17,$E$2:$E$350,0) -> 52 | Q17: =IF(E17>=30,"بسیار بالا",IF(E17>=20,"بالا",IF(E17>=13,"متوسط",IF(E17>=8,"پایین","بسیار پایین")))) -> بالا | R17: 520 | S17: -0.04 | T17: 91 | U17: دقیق (نام یکسان) | V17: حکمت | W17: 0.99 | X17: A
A18: 17 | B18: 1 | C18: چیذر | D18: 18995 | E18: 26.84 | F18: 25.81 | G18: 27.86 | H18: 31.3 | I18: =E18-H18 -> -4.46 | J18: =ROUND(D18*E18/100,0) -> 5098 | K18: 45.02 | L18: 39.79 | M18: 97.36 | N18: 89.71 | O18: 44.13 | P18: =RANK(E18,$E$2:$E$350,0) -> 65 | Q18: =IF(E18>=30,"بسیار بالا",IF(E18>=20,"بالا",IF(E18>=13,"متوسط",IF(E18>=8,"پایین","بسیار پایین")))) -> بالا | R18: 470.1 | S18: -0.131 | T18: 78 | U18: دقیق (نام یکسان) | V18: چیذر | W18: 0.99 | X18: A
A19: 18 | B19: 1 | C19: ازگل | D19: 25362 | E19: 25.01 | F19: 23.65 | G19: 26.37 | H19: 31.3 | I19: =E19-H19 -> -6.29 | J19: =ROUND(D19*E19/100,0) -> 6343 | K19: 42.67 | L19: 37.93 | M19: 97.18 | N19: 88.38 | O19: 42.01 | P19: =RANK(E19,$E$2:$E$350,0) -> 75 | Q19: =IF(E19>=30,"بسیار بالا",IF(E19>=20,"بالا",IF(E19>=13,"متوسط",IF(E19>=8,"پایین","بسیار پایین")))) -> بالا | R19: 397.4 | S19: -0.198 | T19: 86 | U19: دقیق (نام یکسان) | V19: ازگل | W19: 0.99 | X19: A
A20: 19 | B20: 1 | C20: اوین | D20: 8226 | E20: 24.66 | F20: 23.24 | G20: 26.08 | H20: 31.3 | I20: =E20-H20 -> -6.64 | J20: =ROUND(D20*E20/100,0) -> 2029 | K20: 42.21 | L20: 37.56 | M20: 97.14 | N20: 88.1 | O20: 41.59 | P20: =RANK(E20,$E$2:$E$350,0) -> 81 | Q20: =IF(E20>=30,"بسیار بالا",IF(E20>=20,"بالا",IF(E20>=13,"متوسط",IF(E20>=8,"پایین","بسیار پایین")))) -> بالا | R20: 412.5 | S20: -0.211 | T20: 50 | U20: دقیق (نام یکسان) | V20: اوین | W20: 0.96 | X20: A
A21: 20 | B21: 1 | C21: دربند | D21: 11282 | E21: 24.29 | F21: 22.81 | G21: 25.78 | H21: 31.3 | I21: =E21-H21 -> -7.01 | J21: =ROUND(D21*E21/100,0) -> 2740 | K21: 41.72 | L21: 37.18 | M21: 97.1 | N21: 87.8 | O21: 41.15 | P21: =RANK(E21,$E$2:$E$350,0) -> 85 | Q21: =IF(E21>=30,"بسیار بالا",IF(E21>=20,"بالا",IF(E21>=13,"متوسط",IF(E21>=8,"پایین","بسیار پایین")))) -> بالا | R21: 423.5 | S21: -0.225 | T21: 46 | U21: دقیق (نام یکسان) | V21: دربند | W21: 0.96 | X21: A
A22: 21 | B22: 1 | C22: دانشگاه - گلها | D22: 3048 | E22: 24.14 | F22: 22.63 | G22: 25.66 | H22: 31.3 | I22: =E22-H22 -> -7.16 | J22: =ROUND(D22*E22/100,0) -> 736 | K22: 41.52 | L22: 37.02 | M22: 97.08 | N22: 87.67 | O22: 40.97 | P22: =RANK(E22,$E$2:$E$350,0) -> 87 | Q22: =IF(E22>=30,"بسیار بالا",IF(E22>=20,"بالا",IF(E22>=13,"متوسط",IF(E22>=8,"پایین","بسیار پایین")))) -> بالا | R22: 428.2 | S22: -0.231 | T22: 29 | U22: دستی (نام مرکب/معادل) | V22: شهرک گلها | W22: 0.95 | X22: B
A23: 22 | B23: 1 | C23: درکه | D23: 6719 | E23: 23.53 | F23: 21.93 | G23: 25.16 | H23: 31.3 | I23: =E23-H23 -> -7.77 | J23: =ROUND(D23*E23/100,0) -> 1581 | K23: 40.71 | L23: 36.38 | M23: 97.01 | N23: 87.14 | O23: 40.24 | P23: =RANK(E23,$E$2:$E$350,0) -> 89 | Q23: =IF(E23>=30,"بسیار بالا",IF(E23>=20,"بالا",IF(E23>=13,"متوسط",IF(E23>=8,"پایین","بسیار پایین")))) -> بالا | R23: 394.8 | S23: -0.255 | T23: 50 | U23: دقیق (نام یکسان) | V23: درکه | W23: 0.97 | X23: A
A24: 23 | B24: 1 | C24: شهرک نفت | D24: 24137 | E24: 22.6 | F24: 20.86 | G24: 24.39 | H24: 31.3 | I24: =E24-H24 -> -8.7 | J24: =ROUND(D24*E24/100,0) -> 5455 | K24: 39.46 | L24: 35.39 | M24: 96.89 | N24: 86.28 | O24: 39.11 | P24: =RANK(E24,$E$2:$E$350,0) -> 95 | Q24: =IF(E24>=30,"بسیار بالا",IF(E24>=20,"بالا",IF(E24>=13,"متوسط",IF(E24>=8,"پایین","بسیار پایین")))) -> بالا | R24: 423.1 | S24: -0.291 | T24: 80 | U24: دستی (نام مرکب/معادل) | V24: مینی‌سیتی (شهرک نفت) | W24: 0.99 | X24: A
A25: 24 | B25: 1 | C25: دارآباد | D25: 15236 | E25: 22.6 | F25: 20.86 | G25: 24.39 | H25: 31.3 | I25: =E25-H25 -> -8.7 | J25: =ROUND(D25*E25/100,0) -> 3443 | K25: 39.45 | L25: 35.39 | M25: 96.89 | N25: 86.28 | O25: 39.1 | P25: =RANK(E25,$E$2:$E$350,0) -> 95 | Q25: =IF(E25>=30,"بسیار بالا",IF(E25>=20,"بالا",IF(E25>=13,"متوسط",IF(E25>=8,"پایین","بسیار پایین")))) -> بالا | R25: 376.5 | S25: -0.291 | T25: 81 | U25: دقیق (نام یکسان) | V25: دارآباد | W25: 0.99 | X25: A
A26: 25 | B26: 1 | C26: سوهانک | D26: 22829 | E26: 22.19 | F26: 20.4 | G26: 24.05 | H26: 31.3 | I26: =E26-H26 -> -9.11 | J26: =ROUND(D26*E26/100,0) -> 5066 | K26: 38.9 | L26: 34.95 | M26: 96.84 | N26: 85.88 | O26: 38.6 | P26: =RANK(E26,$E$2:$E$350,0) -> 97 | Q26: =IF(E26>=30,"بسیار بالا",IF(E26>=20,"بالا",IF(E26>=13,"متوسط",IF(E26>=8,"پایین","بسیار پایین")))) -> بالا | R26: 375.2 | S26: -0.308 | T26: 89 | U26: دقیق (نام یکسان) | V26: سوهانک | W26: 0.99 | X26: A
A27: 26 | B27: 1 | C27: شهرک محلاتی | D27: 32186 | E27: 19.91 | F27: 17.82 | G27: 22.13 | H27: 31.3 | I27: =E27-H27 -> -11.39 | J27: =ROUND(D27*E27/100,0) -> 6408 | K27: 35.68 | L27: 32.42 | M27: 96.51 | N27: 83.33 | O27: 35.69 | P27: =RANK(E27,$E$2:$E$350,0) -> 119 | Q27: =IF(E27>=30,"بسیار بالا",IF(E27>=20,"بالا",IF(E27>=13,"متوسط",IF(E27>=8,"پایین","بسیار پایین")))) -> متوسط | R27: 343.9 | S27: -0.404 | T27: 56 | U27: دقیق (نام یکسان) | V27: شهرک محلاتی | W27: 0.99 | X27: A
A28: 27 | B28: 1 | C28: گلابدره | D28: 14224 | E28: 14.88 | F28: 12.4 | G28: 17.73 | H28: 31.3 | I28: =E28-H28 -> -16.42 | J28: =ROUND(D28*E28/100,0) -> 2117 | K28: 28.08 | L28: 26.43 | M28: 95.52 | N28: 75.16 | O28: 28.75 | P28: =RANK(E28,$E$2:$E$350,0) -> 187 | Q28: =IF(E28>=30,"بسیار بالا",IF(E28>=20,"بالا",IF(E28>=13,"متوسط",IF(E28>=8,"پایین","بسیار پایین")))) -> متوسط | R28: 260 | S28: -0.651 | T28: 17 | U28: دقیق (نام یکسان) | V28: گلاب دره | W28: 0.75 | X28: B
... A37: 36 | B37: 2 | C37: مرزداران شرقی | D37: 42043 | E37: 31.45 | F37: 31.26 | G37: 31.6 | H37: 31.7 | I37: =E37-H37 -> -0.25 | J37: =ROUND(D37*E37/100,0) -> 13223 | K37: 48.91 | L37: 45.79 | M37: 95.99 | N37: 89.98 | O37: 45.49 | P37: =RANK(E37,$E$2:$E$350,0) -> 38 | Q37: =IF(E37>=30,"بسیار بالا",IF(E37>=20,"بالا",IF(E37>=13,"متوسط",IF(E37>=8,"پایین","بسیار پایین")))) -> بسیار بالا | R37: 405.9 | S37: 0.01 | T37: 89 | U37: دستی (نام مرکب/معادل) | V37: مرزداران | W37: 0.99 | X37: A
A38: 37 | B38: 2 | C38: سپهر | D38: 33619 | E38: 31.13 | F38: 30.87 | G38: 31.35 | H38: 31.7 | I38: =E38-H38 -> -0.57 | J38: =ROUND(D38*E38/100,0) -> 10466 | K38: 48.53 | L38: 45.49 | M38: 95.94 | N38: 89.78 | O38: 45.15 | P38: =RANK(E38,$E$2:$E$350,0) -> 41 | Q38: =IF(E38>=30,"بسیار بالا",IF(E38>=20,"بالا",IF(E38>=13,"متوسط",IF(E38>=8,"پایین","بسیار پایین")))) -> بسیار بالا | S38: 0 | T38: 0 | U38: بدون تطبیق | V38: — | W38: 0 | X38: D
A39: 38 | B39: 2 | C39: شهرک قدس | D39: 29776 | E39: 31.13 | F39: 30.87 | G39: 31.35 | H39: 31.7 | I39: =E39-H39 -> -0.57 | J39: =ROUND(D39*E39/100,0) -> 9269 | K39: 48.53 | L39: 45.49 | M39: 95.94 | N39: 89.78 | O39: 45.15 | P39: =RANK(E39,$E$2:$E$350,0) -> 41 | Q39: =IF(E39>=30,"بسیار بالا",IF(E39>=20,"بالا",IF(E39>=13,"متوسط",IF(E39>=8,"پایین","بسیار پایین")))) -> بسیار بالا | S39: 0 | T39: 0 | U39: بدون تطبیق | V39: — | W39: 0 | X39: D
A40: 39 | B40: 2 | C40: تیموری | D40: 17555 | E40: 31.13 | F40: 30.87 | G40: 31.35 | H40: 31.7 | I40: =E40-H40 -> -0.57 | J40: =ROUND(D40*E40/100,0) -> 5465 | K40: 48.53 | L40: 45.49 | M40: 95.94 | N40: 89.78 | O40: 45.15 | P40: =RANK(E40,$E$2:$E$350,0) -> 41 | Q40: =IF(E40>=30,"بسیار بالا",IF(E40>=20,"بالا",IF(E40>=13,"متوسط",IF(E40>=8,"پایین","بسیار پایین")))) -> بسیار بالا | S40: 0 | T40: 0 | U40: بدون تطبیق | V40: — | W40: 0 | X40: D
A41: 40 | B41: 2 | C41: پونک | D41: 25981 | E41: 29.23 | F41: 28.58 | G41: 29.83 | H41: 31.7 | I41: =E41-H41 -> -2.47 | J41: =ROUND(D41*E41/100,0) -> 7594 | K41: 46.28 | L41: 43.65 | M41: 95.68 | N41: 88.54 | O41: 43.13 | P41: =RANK(E41,$E$2:$E$350,0) -> 54 | Q41: =IF(E41>=30,"بسیار بالا",IF(E41>=20,"بالا",IF(E41>=13,"متوسط",IF(E41>=8,"پایین","بسیار پایین")))) -> بالا | R41: 379.7 | S41: -0.063 | T41: 90 | U41: دقیق (نام یکسان) | V41: پونک | W41: 0.99 | X41: A
A42: 41 | B42: 2 | C42: پرواز | D42: 13348 | E42: 26.55 | F42: 25.4 | G42: 27.69 | H42: 31.7 | I42: =E42-H42 -> -5.15 | J42: =ROUND(D42*E42/100,0) -> 3544 | K42: 42.99 | L42: 40.98 | M42: 95.25 | N42: 86.46 | O42: 40.2 | P42: =RANK(E42,$E$2:$E$350,0) -> 66 | Q42: =IF(E42>=30,"بسیار بالا",IF(E42>=20,"بالا",IF(E42>=13,"متوسط",IF(E42>=8,"پایین","بسیار پایین")))) -> بالا | R42: 339.3 | S42: -0.157 | T42: 25 | U42: دستی (نام مرکب/معادل) | V42: پرواز | W42: 0.97 | X42: B
A43: 42 | B43: 2 | C43: شهر آرا | D43: 36305 | E43: 26.18 | F43: 24.97 | G43: 27.39 | H43: 31.7 | I43: =E43-H43 -> -5.52 | J43: =ROUND(D43*E43/100,0) -> 9505 | K43: 42.53 | L43: 40.6 | M43: 95.19 | N43: 86.14 | O43: 39.79 | P43: =RANK(E43,$E$2:$E$350,0) -> 69 | Q43: =IF(E43>=30,"بسیار بالا",IF(E43>=20,"بالا",IF(E43>=13,"متوسط",IF(E43>=8,"پایین","بسیار پایین")))) -> بالا | R43: 360.5 | S43: -0.17 | T43: 93 | U43: دقیق (نام یکسان) | V43: شهرآرا | W43: 0.99 | X43: A
A44: 43 | B44: 2 | C44: تهران ویلا | D44: 17173 | E44: 24.47 | F44: 22.97 | G44: 26 | H44: 31.7 | I44: =E44-H44 -> -7.23 | J44: =ROUND(D44*E44/100,0) -> 4202 | K44: 40.34 | L44: 38.82 | M44: 94.87 | N44: 84.53 | O44: 37.85 | P44: =RANK(E44,$E$2:$E$350,0) -> 83 | Q44: =IF(E44>=30,"بسیار بالا",IF(E44>=20,"بالا",IF(E44>=13,"متوسط",IF(E44>=8,"پایین","بسیار پایین")))) -> بالا | R44: 343.6 | S44: -0.233 | T44: 93 | U44: دقیق (نام یکسان) | V44: تهران‌ویلا | W44: 0.99 | X44: A
A45: 44 | B45: 2 | C45: برق آلستوم(ستارخان) | D45: 26267 | E45: 22.89 | F45: 21.15 | G45: 24.7 | H45: 31.7 | I45: =E45-H45 -> -8.81 | J45: =ROUND(D45*E45/100,0) -> 6013 | K45: 38.26 | L45: 37.13 | M45: 94.55 | N45: 82.82 | O45: 36 | P45: =RANK(E45,$E$2:$E$350,0) -> 94 | Q45: =IF(E45>=30,"بسیار بالا",IF(E45>=20,"بالا",IF(E45>=13,"متوسط",IF(E45>=8,"پایین","بسیار پایین")))) -> بالا | R45: 307.4 | S45: -0.295 | T45: 95 | U45: جایگزین (محله مجاور/مشابه) | V45: ستارخان | W45: 0.99 | X45: B
A46: 45 | B46: 2 | C46: صادقیه | D46: 42945 | E46: 21.49 | F46: 19.55 | G46: 23.53 | H46: 31.7 | I46: =E46-H46 -> -10.21 | J46: =ROUND(D46*E46/100,0) -> 9229 | K46: 36.36 | L46: 35.58 | M46: 94.23 | N46: 81.11 | O46: 34.32 | P46: =RANK(E46,$E$2:$E$350,0) -> 103 | Q46: =IF(E46>=30,"بسیار بالا",IF(E46>=20,"بالا",IF(E46>=13,"متوسط",IF(E46>=8,"پایین","بسیار پایین")))) -> بالا | R46: 279.5 | S46: -0.352 | T46: 92 | U46: دستی (نام مرکب/معادل) | V46: صادقیه | W46: 0.99 | X46: A
A47: 46 | B47: 2 | C47: توحید | D47: 34358 | E47: 19.44 | F47: 17.26 | G47: 21.79 | H47: 31.7 | I47: =E47-H47 -> -12.26 | J47: =ROUND(D47*E47/100,0) -> 6679 | K47: 33.5 | L47: 33.24 | M47: 93.7 | N47: 78.2 | O47: 31.8 | P47: =RANK(E47,$E$2:$E$350,0) -> 124 | Q47: =IF(E47>=30,"بسیار بالا",IF(E47>=20,"بالا",IF(E47>=13,"متوسط",IF(E47>=8,"پایین","بسیار پایین")))) -> متوسط | R47: 291.7 | S47: -0.44 | T47: 88 | U47: دقیق (نام یکسان) | V47: توحید | W47: 0.98 | X47: A
A48: 47 | B48: 2 | C48: طرشت | D48: 25110 | E48: 18.42 | F48: 16.13 | G48: 20.91 | H48: 31.7 | I48: =E48-H48 -> -13.28 | J48: =ROUND(D48*E48/100,0) -> 4625 | K48: 32.03 | L48: 32.04 | M48: 93.4 | N48: 76.53 | O48: 30.5 | P48: =RANK(E48,$E$2:$E$350,0) -> 135 | Q48: =IF(E48>=30,"بسیار بالا",IF(E48>=20,"بالا",IF(E48>=13,"متوسط",IF(E48>=8,"پایین","بسیار پایین")))) -> متوسط | R48: 252.9 | S48: -0.487 | T48: 87 | U48: دقیق (نام یکسان) | V48: طرشت | W48: 0.99 | X48: A
...

Sheet مناطق
A1: منطقه | B1: جمعیت (مجموع محلات) | C1: تعداد محلات | D1: سهم دانش‌آموختگان دانشگاهی ٪ (سرشماری ۱۳۹۰) | E1: میانگین وزنی برآورد محلات ٪ (کنترل) | F1: تعداد برآوردی دانش‌آموختگان | G1: کمترین برآورد محله ٪ | H1: بیشترین برآورد محله ٪ | I1: مردان دانشگاهی ٪ | J1: زنان دانشگاهی ٪ | K1: باسوادی ۳۰–۵۹ ٪ | L1: باسوادی ۶۰+ ٪ | M1: اینترنت ٪ | N1: میانگین لگاریتم قیمت هر متر (تومان) | O1: قیمت متناظر (میلیون تومان/متر) | P1: پوشش جمعیتی محلات دارای داده قیمت ٪ | Q1: پیش‌بینی مدل از قیمت ٪ | R1: خطای مدل (واحد درصد)
A2: 1 | B2: =SUMIF(محلات!$B$2:$B$350,A2,محلات!$D$2:$D$350) -> 486069 | C2: =COUNTIF(محلات!$B$2:$B$350,A2) -> 27 | D2: 31.3 | E2: =SUMPRODUCT((محلات!$B$2:$B$350=A2)*محلات!$D$2:$D$350*محلات!$E$2:$E$350)/B2 -> 31.299578 | F2: =SUMIF(محلات!$B$2:$B$350,A2,محلات!$J$2:$J$350) -> 152139 | G2: =_xlfn.MINIFS(محلات!$E$2:$E$350,محلات!$B$2:$B$350,A2) -> 14.88 | H2: =_xlfn.MAXIFS(محلات!$E$2:$E$350,محلات!$B$2:$B$350,A2) -> 45.85 | I2: 49.7 | J2: 43.7 | K2: 97.6 | L2: 90.9 | M2: 48.4 | N2: 20.0926 | O2: =ROUND(EXP(N2)/1000000,1) -> 532.2 | P2: 96.4 | Q2: 38.88 | R2: =Q2-D2 -> 7.58
A3: 2 | B3: =SUMIF(محلات!$B$2:$B$350,A3,محلات!$D$2:$D$350) -> 691795 | C3: =COUNTIF(محلات!$B$2:$B$350,A3) -> 21 | D3: 31.7 | E3: =SUMPRODUCT((محلات!$B$2:$B$350=A3)*محلات!$D$2:$D$350*محلات!$E$2:$E$350)/B3 -> 31.699118 | F3: =SUMIF(محلات!$B$2:$B$350,A3,محلات!$J$2:$J$350) -> 219294 | G3: =_xlfn.MINIFS(محلات!$E$2:$E$350,محلات!$B$2:$B$350,A3) -> 17.74 | H3: =_xlfn.MAXIFS(محلات!$E$2:$E$350,محلات!$B$2:$B$350,A3) -> 46.93 | I3: 48.6 | J3: 45.6 | K3: 95.8 | L3: 88.7 | M3: 45.3 | N3: 19.8219 | O3: =ROUND(EXP(N3)/1000000,1) -> 406 | P3: 88.3 | Q3: 30.18 | R3: =Q3-D3 -> -1.52
A4: 3 | B4: =SUMIF(محلات!$B$2:$B$350,A4,محلات!$D$2:$D$350) -> 330004 | C4: =COUNTIF(محلات!$B$2:$B$350,A4) -> 12 | D4: 33.9 | E4: =SUMPRODUCT((محلات!$B$2:$B$350=A4)*محلات!$D$2:$D$350*محلات!$E$2:$E$350)/B4 -> 33.899719 | F4: =SUMIF(محلات!$B$2:$B$350,A4,محلات!$J$2:$J$350) -> 111871 | G4: =_xlfn.MINIFS(محلات!$E$2:$E$350,محلات!$B$2:$B$350,A4) -> 26.53 | H4: =_xlfn.MAXIFS(محلات!$E$2:$E$350,محلات!$B$2:$B$350,A4) -> 46.45 | I4: 52.5 | J4: 47.8 | K4: 97.7 | L4: 89.4 | M4: 48.7 | N4: 19.9449 | O4: =ROUND(EXP(N4)/1000000,1) -> 459.2 | P4: 86.3 | Q4: 34 | R4: =Q4-D4 -> 0.1
A5: 4 | B5: =SUMIF(محلات!$B$2:$B$350,A5,محلات!$D$2:$D$350) -> 906598 | C5: =COUNTIF(محلات!$B$2:$B$350,A5) -> 20 | D5: 17.9 | E5: =SUMPRODUCT((محلات!$B$2:$B$350=A5)*محلات!$D$2:$D$350*محلات!$E$2:$E$350)/B5 -> 17.898036 | F5: =SUMIF(محلات!$B$2:$B$350,A5,محلات!$J$2:$J$350) -> 162265 | G5: =_xlfn.MINIFS(محلات!$E$2:$E$350,محلات!$B$2:$B$350,A5) -> 5.23 | H5: =_xlfn.MAXIFS(محلات!$E$2:$E$350,محلات!$B$2:$B$350,A5) -> 38.6 | I5: 30 | J5: 30.2 | K5: 95.1 | L5: 68.2 | M5: 28.2 | N5: 19.3225 | O5: =ROUND(EXP(N5)/1000000,1) -> 246.4 | P5: 83.5 | Q5: 17.5 | R5: =Q5-D5 -> -0.4
A6: 5 | B6: =SUMIF(محلات!$B$2:$B$350,A6,محلات!$D$2:$D$350) -> 853212 | C6: =COUNTIF(محلات!$B$2:$B$350,A6) -> 29 | D6: 26 | E6: =SUMPRODUCT((محلات!$B$2:$B$350=A6)*محلات!$D$2:$D$350*محلات!$E$2:$E$350)/B6 -> 25.999633 | F6: =SUMIF(محلات!$B$2:$B$350,A6,محلات!$J$2:$J$350) -> 221833 | G6: =_xlfn.MINIFS(محلات!$E$2:$E$350,محلات!$B$2:$B$350,A6) -> 14.04 | H6: =_xlfn.MAXIFS(محلات!$E$2:$E$350,محلات!$B$2:$B$350,A6) -> 31.6 | I6: 41.8 | J6: 39.3 | K6: 97.3 | L6: 78.2 | M6: 40 | N6: 19.5563 | O6: =ROUND(EXP(N6)/1000000,1) -> 311.3 | P6: 100 | Q6: 22.84 | R6: =Q6-D6 -> -3.16
A7: 6 | B7: =SUMIF(محلات!$B$2:$B$350,A7,محلات!$D$2:$D$350) -> 250753 | C7: =COUNTIF(محلات!$B$2:$B$350,A7) -> 14 | D7: 29.5 | E7: =SUMPRODUCT((محلات!$B$2:$B$350=A7)*محلات!$D$2:$D$350*محلات!$E$2:$E$350)/B7 -> 29.500537 | F7: =SUMIF(محلات!$B$2:$B$350,A7,محلات!$J$2:$J$350) -> 73971 | G7: =_xlfn.MINIFS(محلات!$E$2:$E$350,محلات!$B$2:$B$350,A7) -> 16.04 | H7: =_xlfn.MAXIFS(محلات!$E$2:$E$350,محلات!$B$2:$B$350,A7) -> 37.28 | I7: 52 | J7: 47.2 | K7: 97.2 | L7: 89.3 | M7: 49.3 | N7: 19.6599 | O7: =ROUND(EXP(N7)/1000000,1) -> 345.3 | P7: 92.1 | Q7: 25.55 | R7: =Q7-D7 -> -3.95
A8: 7 | B8: =SUMIF(محلات!$B$2:$B$350,A8,محلات!$D$2:$D$350) -> 312002 | C8: =COUNTIF(محلات!$B$2:$B$350,A8) -> 14 | D8: 21 | E8: =SUMPRODUCT((محلات!$B$2:$B$350=A8)*محلات!$D$2:$D$350*محلات!$E$2:$E$350)/B8 -> 20.99939 | F8: =SUMIF(محلات!$B$2:$B$350,A8,محلات!$J$2:$J$350) -> 65520 | G8: =_xlfn.MINIFS(محلات!$E$2:$E$350,محلات!$B$2:$B$350,A8) -> 14.25 | H8: =_xlfn.MAXIFS(محلات!$E$2:$E$350,محلات!$B$2:$B$350,A8) -> 35.77 | I8: 33.9 | J8: 34.5 | K8: 95.8 | L8: 78.3 | M8: 33.4 | N8: 19.3049 | O8: =ROUND(EXP(N8)/1000000,1) -> 242.1 | P8: 86.5 | Q8: 17.14 | R8: =Q8-D8 -> -3.86
A9: 8 | B9: =SUMIF(محلات!$B$2:$B$350,A9,محلات!$D$2:$D$350) -> 425044 | C9: =COUNTIF(محلات!$B$2:$B$350,A9) -> 13 | D9: 18.4 | E9: =SUMPRODUCT((محلات!$B$2:$B$350=A9)*محلات!$D$2:$D$350*محلات!$E$2:$E$350)/B9 -> 18.399549 | F9: =SUMIF(محلات!$B$2:$B$350,A9,محلات!$J$2:$J$350) -> 78207 | G9: =_xlfn.MINIFS(محلات!$E$2:$E$350,محلات!$B$2:$B$350,A9) -> 12.9 | H9: =_xlfn.MAXIFS(محلات!$E$2:$E$350,محلات!$B$2:$B$350,A9) -> 24.18 | I9: 29.9 | J9: 30.6 | K9: 96.9 | L9: 68.1 | M9: 29.9 | N9: 19.2705 | O9: =ROUND(EXP(N9)/1000000,1) -> 233.9 | P9: 100 | Q9: 16.45 | R9: =Q9-D9 -> -1.95
A10: 9 | B10: =SUMIF(محلات!$B$2:$B$350,A10,محلات!$D$2:$D$350) -> 174115 | C10: =COUNTIF(محلات!$B$2:$B$350,A10) -> 9 | D10: 12.6 | E10: =SUMPRODUCT((محلات!$B$2:$B$350=A10)*محلات!$D$2:$D$350*محلات!$E$2:$E$350)/B10 -> 12.59941 | F10: =SUMIF(محلات!$B$2:$B$350,A10,محلات!$J$2:$J$350) -> 21937 | G10: =_xlfn.MINIFS(محلات!$E$2:$E$350,محلات!$B$2:$B$350,A10) -> 10.77 | H10: =_xlfn.MAXIFS(محلات!$E$2:$E$350,محلات!$B$2:$B$350,A10) -> 15.12 | I10: 24.9 | J10: 23.6 | K10: 95.6 | L10: 51.6 | M10: 23.7 | N10: 18.917 | O10: =ROUND(EXP(N10)/1000000,1) -> 164.3 | P10: 74.7 | Q10: 10.63 | R10: =Q10-D10 -> -1.97
A11: 10 | B11: =SUMIF(محلات!$B$2:$B$350,A11,محلات!$D$2:$D$350) -> 326885 | C11: =COUNTIF(محلات!$B$2:$B$350,A11) -> 10 | D11: 13.9 | E11: =SUMPRODUCT((محلات!$B$2:$B$350=A11)*محلات!$D$2:$D$350*محلات!$E$2:$E$350)/B11 -> 13.898524 | F11: =SUMIF(محلات!$B$2:$B$350,A11,محلات!$J$2:$J$350) -> 45432 | G11: =_xlfn.MINIFS(محلات!$E$2:$E$350,محلات!$B$2:$B$350,A11) -> 11.89 | H11: =_xlfn.MAXIFS(محلات!$E$2:$E$350,محلات!$B$2:$B$350,A11) -> 15.75 | I11: 24.2 | J11: 25.4 | K11: 94.8 | L11: 57.1 | M11: 23.7 | N11: 18.8489 | O11: =ROUND(EXP(N11)/1000000,1) -> 153.5 | P11: 83.1 | Q11: 9.74 | R11: =Q11-D11 -> -4.16
A12: 11 | B12: =SUMIF(محلات!$B$2:$B$350,A12,محلات!$D$2:$D$350) -> 307469 | C12: =COUNTIF(محلات!$B$2:$B$350,A12) -> 17 | D12: 15.1 | E12: =SUMPRODUCT((محلات!$B$2:$B$350=A12)*محلات!$D$2:$D$350*محلات!$E$2:$E$350)/B12 -> 15.100014 | F12: =SUMIF(محلات!$B$2:$B$350,A12,محلات!$J$2:$J$350) -> 46429 | G12: =_xlfn.MINIFS(محلات!$E$2:$E$350,محلات!$B$2:$B$350,A12) -> 11.67 | H12: =_xlfn.MAXIFS(محلات!$E$2:$E$350,محلات!$B$2:$B$350,A12) -> 18.98 | I12: 25.2 | J12: 27.7 | K12: 96.2 | L12: 64.8 | M12: 26.4 | N12: 19.0155 | O12: =ROUND(EXP(N12)/1000000,1) -> 181.3 | P12: 75.5 | Q12: 12.04 | R12: =Q12-D12 -> -3.06
A13: 12 | B13: =SUMIF(محلات!$B$2:$B$350,A13,محلات!$D$2:$D$350) -> 240909 | C13: =COUNTIF(محلات!$B$2:$B$350,A13) -> 13 | D13: 10.8 | E13: =SUMPRODUCT((محلات!$B$2:$B$350=A13)*محلات!$D$2:$D$350*محلات!$E$2:$E$350)/B13 -> 10.799046 | F13: =SUMIF(محلات!$B$2:$B$350,A13,محلات!$J$2:$J$350) -> 26016 | G13: =_xlfn.MINIFS(محلات!$E$2:$E$350,محلات!$B$2:$B$350,A13) -> 5.9 | H13: =_xlfn.MAXIFS(محلات!$E$2:$E$350,محلات!$B$2:$B$350,A13) -> 17.9 | I13: 20 | J13: 22 | K13: 91.8 | L13: 60.8 | M13: 22.2 | N13: 18.9517 | O13: =ROUND(EXP(N13)/1000000,1) -> 170.1 | P13: 85.1 | Q13: 11.11 | R13: =Q13-D13 -> 0.31
... A23: 22 | B23: =SUMIF(محلات!$B$2:$B$350,A23,محلات!$D$2:$D$350) -> 174227 | C23: =COUNTIF(محلات!$B$2:$B$350,A23) -> 12 | D23: 19.1 | E23: =SUMPRODUCT((محلات!$B$2:$B$350=A23)*محلات!$D$2:$D$350*محلات!$E$2:$E$350)/B23 -> 19.101588 | F23: =SUMIF(محلات!$B$2:$B$350,A23,محلات!$J$2:$J$350) -> 33279 | G23: =_xlfn.MINIFS(محلات!$E$2:$E$350,محلات!$B$2:$B$350,A23) -> 15.17 | H23: =_xlfn.MAXIFS(محلات!$E$2:$E$350,محلات!$B$2:$B$350,A23) -> 21.9 | I23: 33.6 | J23: 31.7 | K23: 96.5 | L23: 73.7 | M23: 33.4 | N23: 19.2148 | O23: =ROUND(EXP(N23)/1000000,1) -> 221.2 | P23: 69.4 | Q23: 15.39 | R23: =Q23-D23 -> -3.71
A24: کل شهر | B24: =SUM(B2:B23) -> 8627281 | C24: =SUM(C2:C23) -> 349 | E24: =F24/B24*100 -> 17.853922 | F24: =SUM(F2:F23) -> 1540308

Sheet مدل و اعتبارسنجی
A1: مدل برآورد کوچک‌ناحیه‌ای: logit(شاخص) = a + b × ln(قیمت هر متر)
A3: شاخص | B3: عرض از مبدأ a | C3: شیب b | D3: خطای معیار b | E3: R² (۲۲ منطقه، مقیاس لوجیت) | F3: همبستگی پیرسون با قیمت | G3: میانگین خطای مطلق اعتبارسنجی حذف‌یک‌منطقه (واحد درصد) | H3: RMSE حذف‌یک‌منطقه
A4: باسوادی ۳۰ تا ۵۹ سال | B4: -17.329 | C4: 1.055 | D4: 0.197 | E4: 0.589 | F4: 0.703 | G4: 1.92 | H4: 2.45
A5: باسوادی ۶۰ سال و بالاتر | B5: -38.435 | C5: 2.036 | D5: 0.211 | E5: 0.823 | F5: 0.873 | G5: 6.34 | H5: 9.27
A6: سهم دانش‌آموختگان دانشگاهی از کل جمعیت | B6: -29.105 | C6: 1.426 | D6: 0.155 | E6: 0.809 | F6: 0.928 | G6: 3 | H6: 4.15
A7: مردان دارای تحصیلات دانشگاهی | B7: -28.339 | C7: 1.425 | D7: 0.155 | E7: 0.808 | F7: 0.914 | G7: 4.26 | H7: 6.06
A8: زنان دارای تحصیلات دانشگاهی | B8: -23.488 | C8: 1.173 | D8: 0.127 | E8: 0.811 | F8: 0.912 | G8: 3.74 | H8: 5.18
A9: استفاده از اینترنت | B9: -25.794 | C9: 1.292 | D9: 0.127 | E9: 0.839 | F9: 0.926 | G9: 3.72 | H9: 5.04
A11: واریانس بین‌محله‌ای لگاریتم قیمت درون مناطق (τ²) = 0.0636 ؛ میانه واریانس درون‌محله‌ای آگهی‌ها = 0.0524
A12: وزن اعتماد محله = τ² / (τ² + s²/n) ؛ لگاریتم قیمت محله به سمت میانگین منطقه منقبض می‌شود (برآورد بیزی تجربی) تا محلات کم‌آگهی نوسان کاذب نداشته باشند.
A13: گام ۱: برای هر شاخص، رابطه لوجیت شاخص با لگاریتم قیمت در سطح ۲۲ منطقه برازش شد (ستون‌های بالا).
A14: گام ۲: برای هر محله: logit(p محله) = logit(p منطقه) + c منطقه + b × (لگاریتم قیمت منقبض‌شده محله − میانگین وزنی منطقه).
A15: گام ۳: ثابت c برای هر منطقه با روش دوبخشی طوری تعیین شد که میانگین وزنی (جمعیتی) برآورد محلات دقیقاً برابر رقم سرشماری همان منطقه شود (ستون E شیت مناطق را با D مقایسه کنید).
A16: گام ۴: محلات بدون داده قیمت، مقدار پایه منطقه (پس از کالیبراسیون) را می‌گیرند. بازه پایین/بالا با شیب b ± ۱٫۹۶ خطای معیار محاسبه شده است.
A17: محدودیت: شیب b از تفاوت میان مناطق برآورد شده و فرض شده درون مناطق نیز برقرار است (خطر خطای اکولوژیک). این برآورد است، نه داده اندازه‌گیری‌شده سرشماری در سطح محله.

Sheet داده قیمت دیوار
A1: کد محله در دیوار | B1: نام محله در دیوار | C1: تعداد آگهی معتبر | D1: قیمت میانه هر متر (میلیون تومان) | E1: چارک اول | F1: چارک سوم | G1: انحراف معیار لگاریتم قیمت
A2: 55 | B2: ولنجک | C2: 88 | D2: 844.4 | E2: 696.4 | F2: 1000 | G2: 0.278
A3: 56 | B3: زعفرانیه | C3: 87 | D3: 831.2 | E3: 640 | F3: 1000 | G3: 0.325
A4: 85 | B4: الهیه | C4: 87 | D4: 831.1 | E4: 692.3 | F4: 1105.3 | G4: 0.292
A5: 62 | B5: کامرانیه | C5: 84 | D5: 753.4 | E5: 613.7 | F5: 997.5 | G5: 0.303
A6: 60 | B6: محمودیه | C6: 88 | D6: 704.4 | E6: 574 | F6: 877.8 | G6: 0.29
A7: 64 | B7: فرمانیه | C7: 88 | D7: 682.1 | E7: 558.1 | F7: 851 | G7: 0.312
A8: 71 | B8: دروس | C8: 92 | D8: 678.9 | E8: 510.8 | F8: 899.9 | G8: 0.345
A9: 42 | B9: نیاوران | C9: 90 | D9: 671.2 | E9: 534.2 | F9: 800.8 | G9: 0.293
A10: 75 | B10: سعادت‌آباد | C10: 88 | D10: 656.2 | E10: 472.9 | F10: 925.4 | G10: 0.43
A11: 942 | B11: حصار بوعلی | C11: 87 | D11: 653.3 | E11: 535.7 | F11: 800 | G11: 0.276
A12: 930 | B12: باغ فردوس | C12: 13 | D12: 650 | E12: 499.9 | F12: 1000 | G12: 0.351
A13: 44 | B13: جماران (نیاوران) | C13: 91 | D13: 646.9 | E13: 527.3 | F13: 771.4 | G13: 0.288
... A49: 49 | B49: مینی‌سیتی (شهرک نفت) | C49: 80 | D49: 423.1 | E49: 311 | F49: 494.9 | G49: 0.24
A50: 93 | B50: بازار | C50: 3 | D50: 423.1 | G50: 0.65
A51: 70 | B51: قلهک | C51: 91 | D51: 422.2 | E51: 376.5 | F51: 492.3 | G51: 0.29
A52: 932 | B52: والفجر | C52: 71 | D52: 420 | E52: 376 | F52: 470.6 | G52: 0.297
A53: 1024 | B53: هروی | C53: 86 | D53: 417 | E53: 369.5 | F53: 488.4 | G53: 0.213
A54: 933 | B54: جهاد | C54: 90 | D54: 415.3 | E54: 349.2 | F54: 448.6 | G54: 0.193
A55: 57 | B55: اوین | C55: 50 | D55: 412.5 | E55: 354 | F55: 534 | G55: 0.36
A56: 1035 | B56: شیراز | C56: 36 | D56: 409.3 | E56: 371.1 | F56: 505.4 | G56: 0.252
A57: 139 | B57: مرزداران | C57: 89 | D57: 405.9 | E57: 360 | F57: 466.7 | G57: 0.227
A58: 84 | B58: زرگنده | C58: 89 | D58: 400 | E58: 335.1 | F58: 455 | G58: 0.233
A59: 53 | B59: ازگل | C59: 86 | D59: 397.4 | E59: 361.4 | F59: 555.6 | G59: 0.26
A60: 58 | B60: درکه | C60: 50 | D60: 394.8 | E60: 349.9 | F60: 475.7 | G60: 0.295
A61: 82 | B61: پونک | C61: 90 | D61: 379.7 | E61: 322.2 | F61: 453.2 | G61: 0.23
A62: 47 | B62: دارآباد | C62: 81 | D62: 376.5 | E62: 348.2 | F62: 450 | G62: 0.245
... A123: 46 | B123: گلاب دره | C123: 17 | D123: 260 | E123: 142.4 | F123: 400.7 | G123: 0.605
A124: 169 | B124: شهرک آپادانا | C124: 2 | D124: 256 | G124: 0.108
A125: 928 | B125: دانشگاه شریف | C125: 92 | D125: 255.8 | E125: 223.1 | F125: 290.9 | G125: 0.189
A126: 121 | B126: حکیمیه | C126: 81 | D126: 255 | E126: 226.5 | F126: 281 | G126: 0.323
A127: 171 | B127: طرشت | C127: 87 | D127: 252.9 | E127: 227 | F127: 277.8 | G127: 0.196
A128: 154 | B128: بهاران | C128: 88 | D128: 251.9 | E128: 240.1 | F128: 276.9 | G128: 0.2
A129: 134 | B129: نیروی هوایی (پیروزی) | C129: 91 | D129: 249.8 | E129: 200 | F129: 315.9 | G129: 0.368
A130: 163 | B130: شهرک صدرا | C130: 62 | D130: 249.1 | E130: 229.9 | F130: 268.9 | G130: 0.249
A131: 165 | B131: گلستان (شهرک راه آهن) | C131: 81 | D131: 247.6 | E131: 205.3 | F131: 313.3 | G131: 0.66
A132: 156 | B132: جوانمردان (اندیشه) | C132: 91 | D132: 247.2 | E132: 214.3 | F132: 272.4 | G132: 0.311
A133: 118 | B133: دردشت | C133: 90 | D133: 245.4 | E133: 209.6 | F133: 309.6 | G133: 0.236
A134: 155 | B134: شهر زیبا | C134: 83 | D134: 244.6 | E134: 177.9 | F134: 275 | G134: 0.491
A135: 126 | B135: مجیدیه | C135: 86 | D135: 242.5 | E135: 193.8 | F135: 261.9 | G135: 0.215
...

Sheet جدول تطبیق
A1: منطقه | B1: محله شهرداری | C1: نوع تطبیق | D1: کد(های) دیوار | E1: نام(های) دیوار | F1: تعداد آگهی
A2: 1 | B2: اراج | C2: بدون تطبیق | D2: — | E2: — | F2: 0
A3: 1 | B3: ازگل | C3: دقیق (نام یکسان) | D3: 53 | E3: ازگل | F3: 86
A4: 1 | B4: امامزاده قاسم | C4: دقیق (نام یکسان) | D4: 45 | E4: امام زاده قاسم (نیاوران) | F4: 86
A5: 1 | B5: اوین | C5: دقیق (نام یکسان) | D5: 57 | E5: اوین | F5: 50
A6: 1 | B6: باغ فردوس | C6: دقیق (نام یکسان) | D6: 930 | E6: باغ فردوس | F6: 13
A7: 1 | B7: تجریش | C7: دقیق (نام یکسان) | D7: 61 | E7: تجریش | F7: 82
A8: 1 | B8: جماران | C8: دقیق (نام یکسان) | D8: 44 | E8: جماران (نیاوران) | F8: 91
A9: 1 | B9: حصار بوعلی | C9: دقیق (نام یکسان) | D9: 942 | E9: حصار بوعلی | F9: 87
A10: 1 | B10: حکمت | C10: دقیق (نام یکسان) | D10: 931 | E10: حکمت | F10: 91
A11: 1 | B11: دارآباد | C11: دقیق (نام یکسان) | D11: 47 | E11: دارآباد | F11: 81
A12: 1 | B12: دانشگاه - گلها | C12: دستی (نام مرکب/معادل) | D12: 50 | E12: شهرک گلها | F12: 29
A13: 1 | B13: دربند | C13: دقیق (نام یکسان) | D13: 54 | E13: دربند | F13: 46
... A350: 22 | B350: گلستان | C350: دقیق (نام یکسان) | D350: 165 | E350: گلستان (شهرک راه آهن) | F350: 81

Sheet منابع و روش
A1: منبع / موضوع | B1: توضیح
A2: شاخص‌های آموزشی مناطق | B2: صادقی و زنجری (۱۳۹۶)، فصلنامه رفاه اجتماعی، ش ۶۶، جدول ۲؛ مبتنی بر داده‌های خام سرشماری ۱۳۹۰ برای ۲۲ منطقه — https://www.sid.ir/fileserver/jf/62113966604
A3: جمعیت محلات | B3: ۳۴۹ محله تهران (حدود ۱۳۹۵)، سامانه داده‌های باز شهرداری تهران (data.tehran.ir) به نقل از https://d-learn.ir/tehran-neighborhood-data
A4: متغیر کمکی قیمت مسکن | B4: آگهی‌های فروش آپارتمان دیوار (api.divar.ir)، ۳۱۱ محله، جمع‌آوری مهر ۱۴۰۵؛ قیمت درخواستی فروشنده، متراژ از عنوان آگهی استخراج شد (دقت ۹۷٫۷٪ در مقایسه با ۱۳۰ آگهی کامل)
A5: کنترل کلی شهر | B5: سرشماری ۱۳۹۵: ۹۵٪ باسوادی جمعیت ۶ ساله و بیشتر شهر تهران؛ کمترین باسوادی مناطق ۱۷ و ۱۹ و بیشترین ۳ و ۶ — https://www.mizanonline.ir/fa/news/681973/
A6: پالایش داده قیمت | B6: حذف آگهی تکراری، آگهی‌های محله دیگر، متراژ خارج از ۲۵ تا ۱۰۰۰ متر، قیمت هر متر خارج از ۲۰ تا ۲۰۰۰ میلیون تومان
A7: درجه کیفیت A | B7: تطبیق دقیق/دستی و حداقل ۳۰ آگهی معتبر
A8: درجه کیفیت B | B8: ۱۰ تا ۲۹ آگهی، یا محله جایگزین با ۳۰+ آگهی
A9: درجه کیفیت C | B9: کمتر از ۱۰ آگهی یا محله جایگزین با آگهی کم
A10: درجه کیفیت D | B10: بدون داده قیمت؛ فقط مقدار منطقه
A11: آستانه‌های سطح | B11: ≥۳۰٪ بسیار بالا؛ ۲۰ تا ۳۰ بالا؛ ۱۳ تا ۲۰ متوسط؛ ۸ تا ۱۳ پایین؛ کمتر از ۸ بسیار پایین (سهم دانش‌آموختگان دانشگاهی از کل جمعیت)
A12: محدودیت‌ها | B12: ۱) داده رسمی تحصیلات به تفکیک محله منتشر/در دسترس نبود (سایت‌های شهرداری و مرکز آمار از محیط کار قابل دسترسی نبودند). ۲) پایه سرشماری ۱۳۹۰ است و سطح تحصیلات از آن زمان افزایش یافته؛ ارقام برای مقایسه نسبی محلات مناسب‌ترند. ۳) قیمت مسکن نماینده وضعیت اقتصادی-اجتماعی است، نه اندازه‌گیری مستقیم تحصیلات. ۴) منطقه ۲۰ (شهرری) پوشش آگهی بسیار کمی دارد.
