Workbook

Sheet راهنما
A1: استطاعت مسکن ساکنان محلات تهران — مهر ۱۴۰۵
A3: تعداد محلات | B3: =COUNTA(محلات!C2:C350) -> 349
A4: خانوارهای برآوردی | B4: =SUM(محلات!E2:E350) -> 2889992
A5: درآمد سالانه مبنا خانوار متوسط تهران (میلیون تومان) | B5: =پارامترها!B5/1000000 -> 973.35
A6: میانگین وزنی قیمت هر متر (میلیون تومان) | B6: =مناطق!H24 -> 252.72867
A7: میانگین وزنی PIR ساکنان (واحد استاندارد) | B7: =مناطق!J24 -> 19.457751
A8: میانگین وزنی سهم اجاره از درآمد ساکنان ٪ | B8: =مناطق!K24 -> 68.70226
A9: کمترین PIR خانوار متوسط تهران (ارزان‌ترین محله) | B9: =MIN(محلات!L2:L350) -> 5.8714748
A10: بیشترین PIR خانوار متوسط تهران (گران‌ترین محله) | B10: =MAX(محلات!L2:L350) -> 64.848205
A11: محلات با سطح خرید «شدید» یا بدتر (ساکنان) | B11: =COUNTIF(محلات!#REF!,"شدید")+COUNTIF(محلات!#REF!,"بسیار شدید (غیرممکن)") -> #REF!
A12: محلات با اجاره «فشار شدید» برای ساکنان | B12: =COUNTIF(محلات!R2:R350,"فشار شدید") -> 347
A13: محلاتی که کمتر از ۲۰٪ خانوارهای تهران توان اجاره واحد استاندارد آن را دارند | B13: =COUNTIF(محلات!S2:S350,"<20") -> 261
A14: قسط ماهانه وام ۲ میلیاردی (میلیون تومان) | B14: =پارامترها!B12/1000000 -> 40.27524
A16: شیت «محلات»: برای هر ۳۴۹ محله قیمت فروش و اجاره، درآمد برآوردی ساکنان، PIR، سال‌های انتظار، سهم اجاره از درآمد، سهم خانوارهای تهران قادر به خرید/اجاره، اثر وام مسکن، شاخص ترکیبی و درجه کیفیت داده.
A17: شیت «پارامترها»: درآمد، وام، نرخ سود، متراژ و آستانه‌ها قابل تغییرند (سلول‌های زرد).
A18: شیت «مناطق»: جمع‌بندی ۲۲ منطقه و مقایسه گرادیان درآمد مدل با طرح هزینه و درآمد ۱۳۸۷.
A19: هشدار: درآمد محله‌ها برآوردی است و قیمت‌ها درخواستی؛ ارقام برای مقایسه و برنامه‌ریزی مناسب‌اند نه ارزش‌گذاری ملک خاص.

Sheet پارامترها
A1: پارامترها و فرض‌ها (سلول‌های زرد قابل تغییرند؛ همه محاسبات خودکار به‌روز می‌شوند)
A2: پارامتر | B2: مقدار | C2: منبع / توضیح
A3: متوسط درآمد سالانه خانوار شهری استان تهران ۱۴۰۴ (تومان) | B3: 721000000 | C3: مرکز آمار ایران، طرح هزینه و درآمد ۱۴۰۴ (به نقل از اکوایران، ۹ مهر ۱۴۰۵)
A4: ضریب به‌روزرسانی درآمد به مهر ۱۴۰۵ | B4: 1.35 | C4: فرض: رشد اسمی درآمد خانوار شهری در ۱۴۰۴ برابر ۴۱٫۲٪ بوده؛ برای فاصله میانه ۱۴۰۴ تا مهر ۱۴۰۵ حدود ۳۵٪ فرض شد
A5: درآمد سالانه مبنا خانوار متوسط تهران در مهر ۱۴۰۵ (تومان) | B5: =B3*B4 -> 9.7335e+08 | C5: محاسبه‌ای
A6: متراژ واحد استاندارد (متر مربع) | B6: 75 | C6: واحد مرجع برای مقایسه محلات
A7: نرخ پس‌انداز خانوار از درآمد | B7: 0.3 | C7: فرض متعارف در محاسبه سال‌های انتظار خرید
A8: آستانه بار هزینه مسکن (سهم درآمد) | B8: 0.3 | C8: معیار رایج بین‌المللی (۳۰٪ درآمد)
A9: سقف وام خرید مسکن زوجین تهران ۱۴۰۵ (تومان) | B9: 2000000000 | C9: وام از محل اوراق تسه بانک مسکن — جام‌جم آنلاین
A10: نرخ سود سالانه وام | B10: 0.225 | C10: ۲۲٫۵٪ — جام‌جم آنلاین
A11: مدت بازپرداخت (سال) | B11: 12 | C11: ۱۲ سال — جام‌جم آنلاین
A12: قسط ماهانه وام (تومان) | B12: =PMT(B10/12,B11*12,-B9) -> 40275240 | C12: محاسبه‌ای (منبع: حدود ۴۰٫۳ میلیون تومان)
A13: ضریب جینی خانوارهای شهری استان تهران ۱۴۰۴ | B13: 0.4021 | C13: مرکز آمار ایران (به نقل از تجارت‌نیوز/باشگاه خبرنگاران، مهر ۱۴۰۵)
A14: انحراف معیار لگاریتم درآمد (توزیع لگ‌نرمال) | B14: =2*NORMSINV((1+B13)/2) -> 1.0548456 | C14: از ضریب جینی: G = 2Φ(σ/√2) − 1
A15: میانگین لگاریتم درآمد μ | B15: =LN(B5)-B14^2/2 -> 20.139905 | C15: محاسبه‌ای
A16: نرخ تبدیل ودیعه به اجاره ماهانه (در داده‌ها اعمال شده) | B16: 0.03 | C16: عرف بازار ۲ تا ۳ درصد ماهانه (فرارو)؛ ۳٪ در پردازش آگهی‌ها اعمال شد
A17: کشش درآمد سرانه نسبت به قیمت مسکن (برآوردشده) | B17: 1.035 | C17: کالیبره‌شده با نسبت هزینه سرانه مناطق ۱، ۳ و ۱۶ به میانگین شهر (طرح هزینه و درآمد ۱۳۸۷)

Sheet محلات
A1: ردیف | B1: منطقه | C1: محله | D1: جمعیت (حدود ۱۳۹۵) | E1: تعداد خانوار (برآورد) | F1: ضریب درآمد نسبی خانوار (میانگین شهر = ۱) | G1: درآمد سالانه برآوردی خانوار ساکن (میلیون تومان) | H1: قیمت میانه هر متر (میلیون تومان) | I1: قیمت واحد استاندارد (میلیون تومان) | J1: متراژ میانه آگهی‌های فروش (متر) | K1: نسبت قیمت به درآمد (PIR) ساکنان | L1: PIR برای خانوار متوسط تهران | M1: سال‌های لازم پس‌انداز برای خرید (ساکنان) | N1: رهن کامل معادل هر متر (میلیون تومان) | O1: اجاره ماهانه معادل واحد استاندارد (میلیون تومان) | P1: سهم اجاره از درآمد ساکنان ٪ | Q1: سهم اجاره از درآمد خانوار متوسط تهران ٪ | R1: سطح استطاعت اجاره | S1: سهم خانوارهای تهران قادر به اجاره (≤۳۰٪ درآمد) ٪ | T1: سهم خانوارهای تهران با PIR ≤ ۵ ٪ | U1: پوشش وام از قیمت ٪ | V1: پیش‌پرداخت لازم پس از وام (میلیون تومان) | W1: سال‌های پس‌انداز برای پیش‌پرداخت (ساکنان) | X1: نسبت قسط وام به درآمد ماهانه ساکنان ٪ | Y1: شاخص ترکیبی استطاعت مسکن (۰ تا ۱۰۰؛ بیشتر = قابل‌استطاعت‌تر) | Z1: رتبه استطاعت در شهر | AA1: تعداد آگهی فروش | AB1: تعداد آگهی اجاره | AC1: منبع داده اجاره | AD1: نوع تطبیق | AE1: محله(های) دیوار | AF1: درجه کیفیت داده
A2: 1 | B2: 1 | C2: ولنجک | D2: 26587 | E2: =ROUND(D2/INDEX(مناطق!$D$2:$D$23,B2),0) -> 9112 | F2: 3.4199 | G2: =پارامترها!$B$5*F2/1000000 -> 3328.7597 | H2: 841.6 | I2: =H2*پارامترها!$B$6 -> 63120 | J2: 190 | K2: =I2/G2 -> 18.962018 | L2: =I2/(پارامترها!$B$5/1000000) -> 64.848205 | M2: =K2/پارامترها!$B$7 -> 63.206726 | N2: 68.3 | O2: =N2*پارامترها!$B$6*پارامترها!$B$16 -> 153.675 | P2: =O2*12/G2*100 -> 55.399013 | Q2: =O2*12/(پارامترها!$B$5/1000000)*100 -> 189.45908 | R2: =IF(P2<=30,"قابل استطاعت",IF(P2<=50,"زیر فشار","فشار شدید")) -> فشار شدید | S2: =(1-NORMSDIST((LN(O2*12*1000000/پارامترها!$B$8)-پارامترها!$B$15)/پارامترها!$B$14))*100 -> 1.1465723 | T2: =(1-NORMSDIST((LN(I2*1000000/5)-پارامترها!$B$15)/پارامترها!$B$14))*100 -> 0.155428 | U2: =MIN(100,پارامترها!$B$9/1000000/I2*100) -> 3.1685678 | V2: =MAX(0,I2-پارامترها!$B$9/1000000) -> 61120 | W2: =V2/(G2*پارامترها!$B$7) -> 61.203978 | X2: =پارامترها!$B$12/1000000/(G2/12)*100 -> 14.519008 | Y2: =ROUND(50*MIN(1,3/K2)+50*MIN(1,30/P2),1) -> 35 | Z2: =RANK(Y2,$Y$2:$Y$350,0) -> 12 | AA2: 88 | AB2: 83 | AC2: آگهی اجاره دیوار | AD2: دقیق | AE2: ولنجک | AF2: A
A3: 2 | B3: 1 | C3: زعفرانیه | D3: 30377 | E3: =ROUND(D3/INDEX(مناطق!$D$2:$D$23,B3),0) -> 10410 | F3: 3.3882 | G3: =پارامترها!$B$5*F3/1000000 -> 3297.9045 | H3: 834.1 | I3: =H3*پارامترها!$B$6 -> 62557.5 | J3: 200 | K3: =I3/G3 -> 18.968864 | L3: =I3/(پارامترها!$B$5/1000000) -> 64.270304 | M3: =K3/پارامترها!$B$7 -> 63.229545 | N3: 73.77 | O3: =N3*پارامترها!$B$6*پارامترها!$B$16 -> 165.9825 | P3: =O3*12/G3*100 -> 60.395624 | Q3: =O3*12/(پارامترها!$B$5/1000000)*100 -> 204.63245 | R3: =IF(P3<=30,"قابل استطاعت",IF(P3<=50,"زیر فشار","فشار شدید")) -> فشار شدید | S3: =(1-NORMSDIST((LN(O3*12*1000000/پارامترها!$B$8)-پارامترها!$B$15)/پارامترها!$B$14))*100 -> 0.94471087 | T3: =(1-NORMSDIST((LN(I3*1000000/5)-پارامترها!$B$15)/پارامترها!$B$14))*100 -> 0.15975947 | U3: =MIN(100,پارامترها!$B$9/1000000/I3*100) -> 3.1970587 | V3: =MAX(0,I3-پارامترها!$B$9/1000000) -> 60557.5 | W3: =V3/(G3*پارامترها!$B$7) -> 61.20806 | X3: =پارامترها!$B$12/1000000/(G3/12)*100 -> 14.654848 | Y3: =ROUND(50*MIN(1,3/K3)+50*MIN(1,30/P3),1) -> 32.7 | Z3: =RANK(Y3,$Y$2:$Y$350,0) -> 38 | AA3: 87 | AB3: 84 | AC3: آگهی اجاره دیوار | AD3: دقیق | AE3: زعفرانیه | AF3: A
A4: 3 | B4: 1 | C4: محمودیه | D4: 8763 | E4: =ROUND(D4/INDEX(مناطق!$D$2:$D$23,B4),0) -> 3003 | F4: 2.8535 | G4: =پارامترها!$B$5*F4/1000000 -> 2777.4542 | H4: 706.5 | I4: =H4*پارامترها!$B$6 -> 52987.5 | J4: 179 | K4: =I4/G4 -> 19.077722 | L4: =I4/(پارامترها!$B$5/1000000) -> 54.43828 | M4: =K4/پارامترها!$B$7 -> 63.592407 | N4: 71.04 | O4: =N4*پارامترها!$B$6*پارامترها!$B$16 -> 159.84 | P4: =O4*12/G4*100 -> 69.058924 | Q4: =O4*12/(پارامترها!$B$5/1000000)*100 -> 197.05964 | R4: =IF(P4<=30,"قابل استطاعت",IF(P4<=50,"زیر فشار","فشار شدید")) -> فشار شدید | S4: =(1-NORMSDIST((LN(O4*12*1000000/پارامترها!$B$8)-پارامترها!$B$15)/پارامترها!$B$14))*100 -> 1.0392615 | T4: =(1-NORMSDIST((LN(I4*1000000/5)-پارامترها!$B$15)/پارامترها!$B$14))*100 -> 0.26280035 | U4: =MIN(100,پارامترها!$B$9/1000000/I4*100) -> 3.7744751 | V4: =MAX(0,I4-پارامترها!$B$9/1000000) -> 50987.5 | W4: =V4/(G4*پارامترها!$B$7) -> 61.192128 | X4: =پارامترها!$B$12/1000000/(G4/12)*100 -> 17.400931 | Y4: =ROUND(50*MIN(1,3/K4)+50*MIN(1,30/P4),1) -> 29.6 | Z4: =RANK(Y4,$Y$2:$Y$350,0) -> 185 | AA4: 88 | AB4: 85 | AC4: آگهی اجاره دیوار | AD4: دقیق | AE4: محمودیه | AF4: A
A5: 4 | B5: 1 | C5: فرمانیه | D5: 22574 | E5: =ROUND(D5/INDEX(مناطق!$D$2:$D$23,B5),0) -> 7736 | F5: 2.8057 | G5: =پارامترها!$B$5*F5/1000000 -> 2730.9281 | H5: 695.1 | I5: =H5*پارامترها!$B$6 -> 52132.5 | J5: 212.5 | K5: =I5/G5 -> 19.089664 | L5: =I5/(پارامترها!$B$5/1000000) -> 53.559871 | M5: =K5/پارامترها!$B$7 -> 63.632214 | N5: 54.83 | O5: =N5*پارامترها!$B$6*پارامترها!$B$16 -> 123.3675 | P5: =O5*12/G5*100 -> 54.209044 | Q5: =O5*12/(پارامترها!$B$5/1000000)*100 -> 152.09431 | R5: =IF(P5<=30,"قابل استطاعت",IF(P5<=50,"زیر فشار","فشار شدید")) -> فشار شدید | S5: =(1-NORMSDIST((LN(O5*12*1000000/پارامترها!$B$8)-پارامترها!$B$15)/پارامترها!$B$14))*100 -> 1.9398938 | T5: =(1-NORMSDIST((LN(I5*1000000/5)-پارامترها!$B$15)/پارامترها!$B$14))*100 -> 0.27559431 | U5: =MIN(100,پارامترها!$B$9/1000000/I5*100) -> 3.8363785 | V5: =MAX(0,I5-پارامترها!$B$9/1000000) -> 50132.5 | W5: =V5/(G5*پارامترها!$B$7) -> 61.191041 | X5: =پارامترها!$B$12/1000000/(G5/12)*100 -> 17.697386 | Y5: =ROUND(50*MIN(1,3/K5)+50*MIN(1,30/P5),1) -> 35.5 | Z5: =RANK(Y5,$Y$2:$Y$350,0) -> 6 | AA5: 88 | AB5: 88 | AC5: آگهی اجاره دیوار | AD5: دقیق | AE5: فرمانیه | AF5: A
A6: 5 | B6: 1 | C6: باغ فردوس | D6: 17579 | E6: =ROUND(D6/INDEX(مناطق!$D$2:$D$23,B6),0) -> 6024 | F6: 2.7875 | G6: =پارامترها!$B$5*F6/1000000 -> 2713.2131 | H6: 690.8 | I6: =H6*پارامترها!$B$6 -> 51810 | J6: 189 | K6: =I6/G6 -> 19.095441 | L6: =I6/(پارامترها!$B$5/1000000) -> 53.228541 | M6: =K6/پارامترها!$B$7 -> 63.651469 | N6: 57.61 | O6: =N6*پارامترها!$B$6*پارامترها!$B$16 -> 129.6225 | P6: =O6*12/G6*100 -> 57.329444 | Q6: =O6*12/(پارامترها!$B$5/1000000)*100 -> 159.80583 | R6: =IF(P6<=30,"قابل استطاعت",IF(P6<=50,"زیر فشار","فشار شدید")) -> فشار شدید | S6: =(1-NORMSDIST((LN(O6*12*1000000/پارامترها!$B$8)-پارامترها!$B$15)/پارامترها!$B$14))*100 -> 1.7291342 | T6: =(1-NORMSDIST((LN(I6*1000000/5)-پارامترها!$B$15)/پارامترها!$B$14))*100 -> 0.28062097 | U6: =MIN(100,پارامترها!$B$9/1000000/I6*100) -> 3.8602586 | V6: =MAX(0,I6-پارامترها!$B$9/1000000) -> 49810 | W6: =V6/(G6*پارامترها!$B$7) -> 61.194357 | X6: =پارامترها!$B$12/1000000/(G6/12)*100 -> 17.812935 | Y6: =ROUND(50*MIN(1,3/K6)+50*MIN(1,30/P6),1) -> 34 | Z6: =RANK(Y6,$Y$2:$Y$350,0) -> 26 | AA6: 13 | AB6: 21 | AC6: آگهی اجاره دیوار | AD6: دقیق | AE6: باغ فردوس | AF6: B
A7: 6 | B7: 1 | C7: حصار بوعلی | D7: 13368 | E7: =ROUND(D7/INDEX(مناطق!$D$2:$D$23,B7),0) -> 4581 | F7: 2.6982 | G7: =پارامترها!$B$5*F7/1000000 -> 2626.293 | H7: 669.3 | I7: =H7*پارامترها!$B$6 -> 50197.5 | J7: 210 | K7: =I7/G7 -> 19.113443 | L7: =I7/(پارامترها!$B$5/1000000) -> 51.571891 | M7: =K7/پارامترها!$B$7 -> 63.711475 | N7: 54.82 | O7: =N7*پارامترها!$B$6*پارامترها!$B$16 -> 123.345 | P7: =O7*12/G7*100 -> 56.358526 | Q7: =O7*12/(پارامترها!$B$5/1000000)*100 -> 152.06657 | R7: =IF(P7<=30,"قابل استطاعت",IF(P7<=50,"زیر فشار","فشار شدید")) -> فشار شدید | S7: =(1-NORMSDIST((LN(O7*12*1000000/پارامترها!$B$8)-پارامترها!$B$15)/پارامترها!$B$14))*100 -> 1.9407098 | T7: =(1-NORMSDIST((LN(I7*1000000/5)-پارامترها!$B$15)/پارامترها!$B$14))*100 -> 0.30754036 | U7: =MIN(100,پارامترها!$B$9/1000000/I7*100) -> 3.9842622 | V7: =MAX(0,I7-پارامترها!$B$9/1000000) -> 48197.5 | W7: =V7/(G7*پارامترها!$B$7) -> 61.173043 | X7: =پارامترها!$B$12/1000000/(G7/12)*100 -> 18.402474 | Y7: =ROUND(50*MIN(1,3/K7)+50*MIN(1,30/P7),1) -> 34.5 | Z7: =RANK(Y7,$Y$2:$Y$350,0) -> 17 | AA7: 87 | AB7: 78 | AC7: آگهی اجاره دیوار | AD7: دقیق | AE7: حصار بوعلی | AF7: A
A8: 7 | B8: 1 | C8: نیاوران | D8: 9791 | E8: =ROUND(D8/INDEX(مناطق!$D$2:$D$23,B8),0) -> 3355 | F8: 2.6589 | G8: =پارامترها!$B$5*F8/1000000 -> 2588.0403 | H8: 659.9 | I8: =H8*پارامترها!$B$6 -> 49492.5 | J8: 191 | K8: =I8/G8 -> 19.123543 | L8: =I8/(پارامترها!$B$5/1000000) -> 50.847588 | M8: =K8/پارامترها!$B$7 -> 63.745143 | N8: 60.42 | O8: =N8*پارامترها!$B$6*پارامترها!$B$16 -> 135.945 | P8: =O8*12/G8*100 -> 63.033794 | Q8: =O8*12/(پارامترها!$B$5/1000000)*100 -> 167.60055 | R8: =IF(P8<=30,"قابل استطاعت",IF(P8<=50,"زیر فشار","فشار شدید")) -> فشار شدید | S8: =(1-NORMSDIST((LN(O8*12*1000000/پارامترها!$B$8)-پارامترها!$B$15)/پارامترها!$B$14))*100 -> 1.5449958 | T8: =(1-NORMSDIST((LN(I8*1000000/5)-پارامترها!$B$15)/پارامترها!$B$14))*100 -> 0.3203185 | U8: =MIN(100,پارامترها!$B$9/1000000/I8*100) -> 4.0410163 | V8: =MAX(0,I8-پارامترها!$B$9/1000000) -> 47492.5 | W8: =V8/(G8*پارامترها!$B$7) -> 61.169191 | X8: =پارامترها!$B$12/1000000/(G8/12)*100 -> 18.674473 | Y8: =ROUND(50*MIN(1,3/K8)+50*MIN(1,30/P8),1) -> 31.6 | Z8: =RANK(Y8,$Y$2:$Y$350,0) -> 81 | AA8: 90 | AB8: 88 | AC8: آگهی اجاره دیوار | AD8: دستی (نام مرکب/معادل) | AE8: نیاوران | AF8: A
A9: 8 | B9: 1 | C9: جماران | D9: 8373 | E9: =ROUND(D9/INDEX(مناطق!$D$2:$D$23,B9),0) -> 2869 | F9: 2.6502 | G9: =پارامترها!$B$5*F9/1000000 -> 2579.5722 | H9: 657.8 | I9: =H9*پارامترها!$B$6 -> 49335 | J9: 175 | K9: =I9/G9 -> 19.125264 | L9: =I9/(پارامترها!$B$5/1000000) -> 50.685776 | M9: =K9/پارامترها!$B$7 -> 63.750882 | N9: 58.13 | O9: =N9*پارامترها!$B$6*پارامترها!$B$16 -> 130.7925 | P9: =O9*12/G9*100 -> 60.84381 | Q9: =O9*12/(پارامترها!$B$5/1000000)*100 -> 161.24827 | R9: =IF(P9<=30,"قابل استطاعت",IF(P9<=50,"زیر فشار","فشار شدید")) -> فشار شدید | S9: =(1-NORMSDIST((LN(O9*12*1000000/پارامترها!$B$8)-پارامترها!$B$15)/پارامترها!$B$14))*100 -> 1.6930215 | T9: =(1-NORMSDIST((LN(I9*1000000/5)-پارامترها!$B$15)/پارامترها!$B$14))*100 -> 0.32326321 | U9: =MIN(100,پارامترها!$B$9/1000000/I9*100) -> 4.0539171 | V9: =MAX(0,I9-پارامترها!$B$9/1000000) -> 47335 | W9: =V9/(G9*پارامترها!$B$7) -> 61.166474 | X9: =پارامترها!$B$12/1000000/(G9/12)*100 -> 18.735777 | Y9: =ROUND(50*MIN(1,3/K9)+50*MIN(1,30/P9),1) -> 32.5 | Z9: =RANK(Y9,$Y$2:$Y$350,0) -> 42 | AA9: 91 | AB9: 89 | AC9: آگهی اجاره دیوار | AD9: دقیق | AE9: جماران (نیاوران) | AF9: A
A10: 9 | B10: 1 | C10: امامزاده قاسم | D10: 23845 | E10: =ROUND(D10/INDEX(مناطق!$D$2:$D$23,B10),0) -> 8172 | F10: 2.6283 | G10: =پارامترها!$B$5*F10/1000000 -> 2558.2558 | H10: 652.6 | I10: =H10*پارامترها!$B$6 -> 48945 | J10: 175 | K10: =I10/G10 -> 19.132176 | L10: =I10/(پارامترها!$B$5/1000000) -> 50.285098 | M10: =K10/پارامترها!$B$7 -> 63.77392 | N10: 60.1 | O10: =N10*پارامترها!$B$6*پارامترها!$B$16 -> 135.225 | P10: =O10*12/G10*100 -> 63.429935 | Q10: =O10*12/(پارامترها!$B$5/1000000)*100 -> 166.7129 | R10: =IF(P10<=30,"قابل استطاعت",IF(P10<=50,"زیر فشار","فشار شدید")) -> فشار شدید | S10: =(1-NORMSDIST((LN(O10*12*1000000/پارامترها!$B$8)-پارامترها!$B$15)/پارامترها!$B$14))*100 -> 1.5646574 | T10: =(1-NORMSDIST((LN(I10*1000000/5)-پارامترها!$B$15)/پارامترها!$B$14))*100 -> 0.33070161 | U10: =MIN(100,پارامترها!$B$9/1000000/I10*100) -> 4.0862192 | V10: =MAX(0,I10-پارامترها!$B$9/1000000) -> 46945 | W10: =V10/(G10*پارامترها!$B$7) -> 61.167977 | X10: =پارامترها!$B$12/1000000/(G10/12)*100 -> 18.89189 | Y10: =ROUND(50*MIN(1,3/K10)+50*MIN(1,30/P10),1) -> 31.5 | Z10: =RANK(Y10,$Y$2:$Y$350,0) -> 85 | AA10: 86 | AB10: 80 | AC10: آگهی اجاره دیوار | AD10: دقیق | AE10: امام زاده قاسم (نیاوران) | AF10: A
A11: 10 | B11: 1 | C11: دزاشیب | D11: 15178 | E11: =ROUND(D11/INDEX(مناطق!$D$2:$D$23,B11),0) -> 5202 | F11: 2.5357 | G11: =پارامترها!$B$5*F11/1000000 -> 2468.1236 | H11: 630.4 | I11: =H11*پارامترها!$B$6 -> 47280 | J11: 160 | K11: =I11/G11 -> 19.156253 | L11: =I11/(پارامترها!$B$5/1000000) -> 48.574511 | M11: =K11/پارامترها!$B$7 -> 63.854177 | N11: 49.99 | O11: =N11*پارامترها!$B$6*پارامترها!$B$16 -> 112.4775 | P11: =O11*12/G11*100 -> 54.686483 | Q11: =O11*12/(پارامترها!$B$5/1000000)*100 -> 138.66852 | R11: =IF(P11<=30,"قابل استطاعت",IF(P11<=50,"زیر فشار","فشار شدید")) -> فشار شدید | S11: =(1-NORMSDIST((LN(O11*12*1000000/پارامترها!$B$8)-پارامترها!$B$15)/پارامترها!$B$14))*100 -> 2.3924068 | T11: =(1-NORMSDIST((LN(I11*1000000/5)-پارامترها!$B$15)/پارامترها!$B$14))*100 -> 0.36496995 | U11: =MIN(100,پارامترها!$B$9/1000000/I11*100) -> 4.2301184 | V11: =MAX(0,I11-پارامترها!$B$9/1000000) -> 45280 | W11: =V11/(G11*پارامترها!$B$7) -> 61.153069 | X11: =پارامترها!$B$12/1000000/(G11/12)*100 -> 19.581794 | Y11: =ROUND(50*MIN(1,3/K11)+50*MIN(1,30/P11),1) -> 35.3 | Z11: =RANK(Y11,$Y$2:$Y$350,0) -> 8 | AA11: 88 | AB11: 88 | AC11: آگهی اجاره دیوار | AD11: دقیق | AE11: دزاشیب | AF11: A
A12: 11 | B12: 1 | C12: کاشانک | D12: 30216 | E12: =ROUND(D12/INDEX(مناطق!$D$2:$D$23,B12),0) -> 10355 | F12: 2.3249 | G12: =پارامترها!$B$5*F12/1000000 -> 2262.9414 | H12: 579.7 | I12: =H12*پارامترها!$B$6 -> 43477.5 | J12: 175 | K12: =I12/G12 -> 19.212826 | L12: =I12/(پارامترها!$B$5/1000000) -> 44.6679 | M12: =K12/پارامترها!$B$7 -> 64.042754 | N12: 47.76 | O12: =N12*پارامترها!$B$6*پارامترها!$B$16 -> 107.46 | P12: =O12*12/G12*100 -> 56.984241 | Q12: =O12*12/(پارامترها!$B$5/1000000)*100 -> 132.48266 | R12: =IF(P12<=30,"قابل استطاعت",IF(P12<=50,"زیر فشار","فشار شدید")) -> فشار شدید | S12: =(1-NORMSDIST((LN(O12*12*1000000/پارامترها!$B$8)-پارامترها!$B$15)/پارامترها!$B$14))*100 -> 2.646737 | T12: =(1-NORMSDIST((LN(I12*1000000/5)-پارامترها!$B$15)/پارامترها!$B$14))*100 -> 0.46154428 | U12: =MIN(100,پارامترها!$B$9/1000000/I12*100) -> 4.6000805 | V12: =MAX(0,I12-پارامترها!$B$9/1000000) -> 41477.5 | W12: =V12/(G12*پارامترها!$B$7) -> 61.096736 | X12: =پارامترها!$B$12/1000000/(G12/12)*100 -> 21.357287 | Y12: =ROUND(50*MIN(1,3/K12)+50*MIN(1,30/P12),1) -> 34.1 | Z12: =RANK(Y12,$Y$2:$Y$350,0) -> 23 | AA12: 90 | AB12: 88 | AC12: آگهی اجاره دیوار | AD12: دقیق | AE12: کاشانک | AF12: A
A13: 12 | B13: 1 | C13: قیطریه | D13: 24680 | E13: =ROUND(D13/INDEX(مناطق!$D$2:$D$23,B13),0) -> 8458 | F13: 2.2426 | G13: =پارامترها!$B$5*F13/1000000 -> 2182.8347 | H13: 559.8 | I13: =H13*پارامترها!$B$6 -> 41985 | J13: 150 | K13: =I13/G13 -> 19.234164 | L13: =I13/(پارامترها!$B$5/1000000) -> 43.134535 | M13: =K13/پارامترها!$B$7 -> 64.113879 | N13: 48.07 | O13: =N13*پارامترها!$B$6*پارامترها!$B$16 -> 108.1575 | P13: =O13*12/G13*100 -> 59.458923 | Q13: =O13*12/(پارامترها!$B$5/1000000)*100 -> 133.34258 | R13: =IF(P13<=30,"قابل استطاعت",IF(P13<=50,"زیر فشار","فشار شدید")) -> فشار شدید | S13: =(1-NORMSDIST((LN(O13*12*1000000/پارامترها!$B$8)-پارامترها!$B$15)/پارامترها!$B$14))*100 -> 2.6093599 | T13: =(1-NORMSDIST((LN(I13*1000000/5)-پارامترها!$B$15)/پارامترها!$B$14))*100 -> 0.50809973 | U13: =MIN(100,پارامترها!$B$9/1000000/I13*100) -> 4.763606 | V13: =MAX(0,I13-پارامترها!$B$9/1000000) -> 39985 | W13: =V13/(G13*پارامترها!$B$7) -> 61.059746 | X13: =پارامترها!$B$12/1000000/(G13/12)*100 -> 22.141067 | Y13: =ROUND(50*MIN(1,3/K13)+50*MIN(1,30/P13),1) -> 33 | Z13: =RANK(Y13,$Y$2:$Y$350,0) -> 32 | AA13: 89 | AB13: 89 | AC13: آگهی اجاره دیوار | AD13: دقیق | AE13: قیطریه | AF13: A
A14: 13 | B14: 1 | C14: تجریش | D14: 14564 | E14: =ROUND(D14/INDEX(مناطق!$D$2:$D$23,B14),0) -> 4991 | F14: 2.1572 | G14: =پارامترها!$B$5*F14/1000000 -> 2099.7106 | H14: 539.2 | I14: =H14*پارامترها!$B$6 -> 40440 | J14: 131 | K14: =I14/G14 -> 19.259797 | L14: =I14/(پارامترها!$B$5/1000000) -> 41.547234 | M14: =K14/پارامترها!$B$7 -> 64.199323 | N14: 43.72 | O14: =N14*پارامترها!$B$6*پارامترها!$B$16 -> 98.37 | P14: =O14*12/G14*100 -> 56.219176 | Q14: =O14*12/(پارامترها!$B$5/1000000)*100 -> 121.27601 | R14: =IF(P14<=30,"قابل استطاعت",IF(P14<=50,"زیر فشار","فشار شدید")) -> فشار شدید | S14: =(1-NORMSDIST((LN(O14*12*1000000/پارامترها!$B$8)-پارامترها!$B$15)/پارامترها!$B$14))*100 -> 3.2036936 | T14: =(1-NORMSDIST((LN(I14*1000000/5)-پارامترها!$B$15)/پارامترها!$B$14))*100 -> 0.56267956 | U14: =MIN(100,پارامترها!$B$9/1000000/I14*100) -> 4.9455984 | V14: =MAX(0,I14-پارامترها!$B$9/1000000) -> 38440 | W14: =V14/(G14*پارامترها!$B$7) -> 61.024282 | X14: =پارامترها!$B$12/1000000/(G14/12)*100 -> 23.017595 | Y14: =ROUND(50*MIN(1,3/K14)+50*MIN(1,30/P14),1) -> 34.5 | Z14: =RANK(Y14,$Y$2:$Y$350,0) -> 17 | AA14: 82 | AB14: 58 | AC14: آگهی اجاره دیوار | AD14: دقیق | AE14: تجریش | AF14: A
A15: 14 | B15: 1 | C15: اراج | D15: 16408 | E15: =ROUND(D15/INDEX(مناطق!$D$2:$D$23,B15),0) -> 5623 | F15: 2.1284 | G15: =پارامترها!$B$5*F15/1000000 -> 2071.6781 | H15: 532.3 | I15: =H15*پارامترها!$B$6 -> 39922.5 | K15: =I15/G15 -> 19.270609 | L15: =I15/(پارامترها!$B$5/1000000) -> 41.015565 | M15: =K15/پارامترها!$B$7 -> 64.235364 | N15: 52.39 | O15: =N15*پارامترها!$B$6*پارامترها!$B$16 -> 117.8775 | P15: =O15*12/G15*100 -> 68.279429 | Q15: =O15*12/(پارامترها!$B$5/1000000)*100 -> 145.32594 | R15: =IF(P15<=30,"قابل استطاعت",IF(P15<=50,"زیر فشار","فشار شدید")) -> فشار شدید | S15: =(1-NORMSDIST((LN(O15*12*1000000/پارامترها!$B$8)-پارامترها!$B$15)/پارامترها!$B$14))*100 -> 2.1527847 | T15: =(1-NORMSDIST((LN(I15*1000000/5)-پارامترها!$B$15)/پارامترها!$B$14))*100 -> 0.58259581 | U15: =MIN(100,پارامترها!$B$9/1000000/I15*100) -> 5.0097063 | V15: =MAX(0,I15-پارامترها!$B$9/1000000) -> 37922.5 | W15: =V15/(G15*پارامترها!$B$7) -> 61.017361 | X15: =پارامترها!$B$12/1000000/(G15/12)*100 -> 23.329053 | Y15: =ROUND(50*MIN(1,3/K15)+50*MIN(1,30/P15),1) -> 29.8 | Z15: =RANK(Y15,$Y$2:$Y$350,0) -> 172 | AA15: 0 | AB15: 0 | AC15: برآورد از قیمت فروش | AD15: بدون داده (میانگین منطقه) | AE15: — | AF15: D
A16: 15 | B16: 1 | C16: کوهسار | D16: 1088 | E16: =ROUND(D16/INDEX(مناطق!$D$2:$D$23,B16),0) -> 373 | F16: 2.1284 | G16: =پارامترها!$B$5*F16/1000000 -> 2071.6781 | H16: 532.3 | I16: =H16*پارامترها!$B$6 -> 39922.5 | K16: =I16/G16 -> 19.270609 | L16: =I16/(پارامترها!$B$5/1000000) -> 41.015565 | M16: =K16/پارامترها!$B$7 -> 64.235364 | N16: 52.39 | O16: =N16*پارامترها!$B$6*پارامترها!$B$16 -> 117.8775 | P16: =O16*12/G16*100 -> 68.279429 | Q16: =O16*12/(پارامترها!$B$5/1000000)*100 -> 145.32594 | R16: =IF(P16<=30,"قابل استطاعت",IF(P16<=50,"زیر فشار","فشار شدید")) -> فشار شدید | S16: =(1-NORMSDIST((LN(O16*12*1000000/پارامترها!$B$8)-پارامترها!$B$15)/پارامترها!$B$14))*100 -> 2.1527847 | T16: =(1-NORMSDIST((LN(I16*1000000/5)-پارامترها!$B$15)/پارامترها!$B$14))*100 -> 0.58259581 | U16: =MIN(100,پارامترها!$B$9/1000000/I16*100) -> 5.0097063 | V16: =MAX(0,I16-پارامترها!$B$9/1000000) -> 37922.5 | W16: =V16/(G16*پارامترها!$B$7) -> 61.017361 | X16: =پارامترها!$B$12/1000000/(G16/12)*100 -> 23.329053 | Y16: =ROUND(50*MIN(1,3/K16)+50*MIN(1,30/P16),1) -> 29.8 | Z16: =RANK(Y16,$Y$2:$Y$350,0) -> 172 | AA16: 0 | AB16: 0 | AC16: برآورد از قیمت فروش | AD16: بدون داده (میانگین منطقه) | AE16: — | AF16: D
A17: 16 | B17: 1 | C17: حکمت | D17: 40434 | E17: =ROUND(D17/INDEX(مناطق!$D$2:$D$23,B17),0) -> 13857 | F17: 2.0514 | G17: =پارامترها!$B$5*F17/1000000 -> 1996.7302 | H17: 513.6 | I17: =H17*پارامترها!$B$6 -> 38520 | J17: 130 | K17: =I17/G17 -> 19.29154 | L17: =I17/(پارامترها!$B$5/1000000) -> 39.574665 | M17: =K17/پارامترها!$B$7 -> 64.305133 | N17: 45.53 | O17: =N17*پارامترها!$B$6*پارامترها!$B$16 -> 102.4425 | P17: =O17*12/G17*100 -> 61.566155 | Q17: =O17*12/(پارامترها!$B$5/1000000)*100 -> 126.29681 | R17: =IF(P17<=30,"قابل استطاعت",IF(P17<=50,"زیر فشار","فشار شدید")) -> فشار شدید | S17: =(1-NORMSDIST((LN(O17*12*1000000/پارامترها!$B$8)-پارامترها!$B$15)/پارامترها!$B$14))*100 -> 2.9370816 | T17: =(1-NORMSDIST((LN(I17*1000000/5)-پارامترها!$B$15)/پارامترها!$B$14))*100 -> 0.64121526 | U17: =MIN(100,پارامترها!$B$9/1000000/I17*100) -> 5.192108 | V17: =MAX(0,I17-پارامترها!$B$9/1000000) -> 36520 | W17: =V17/(G17*پارامترها!$B$7) -> 60.966341 | X17: =پارامترها!$B$12/1000000/(G17/12)*100 -> 24.204717 | Y17: =ROUND(50*MIN(1,3/K17)+50*MIN(1,30/P17),1) -> 32.1 | Z17: =RANK(Y17,$Y$2:$Y$350,0) -> 58 | AA17: 91 | AB17: 91 | AC17: آگهی اجاره دیوار | AD17: دقیق | AE17: حکمت | AF17: A
A18: 17 | B18: 1 | C18: چیذر | D18: 18995 | E18: =ROUND(D18/INDEX(مناطق!$D$2:$D$23,B18),0) -> 6510 | F18: 1.8682 | G18: =پارامترها!$B$5*F18/1000000 -> 1818.4125 | H18: 469.2 | I18: =H18*پارامترها!$B$6 -> 35190 | J18: 135 | K18: =I18/G18 -> 19.352045 | L18: =I18/(پارامترها!$B$5/1000000) -> 36.153491 | M18: =K18/پارامترها!$B$7 -> 64.506817 | N18: 38.32 | O18: =N18*پارامترها!$B$6*پارامترها!$B$16 -> 86.22 | P18: =O18*12/G18*100 -> 56.897982 | Q18: =O18*12/(پارامترها!$B$5/1000000)*100 -> 106.29681 | R18: =IF(P18<=30,"قابل استطاعت",IF(P18<=50,"زیر فشار","فشار شدید")) -> فشار شدید | S18: =(1-NORMSDIST((LN(O18*12*1000000/پارامترها!$B$8)-پارامترها!$B$15)/پارامترها!$B$14))*100 -> 4.2112005 | T18: =(1-NORMSDIST((LN(I18*1000000/5)-پارامترها!$B$15)/پارامترها!$B$14))*100 -> 0.81328877 | U18: =MIN(100,پارامترها!$B$9/1000000/I18*100) -> 5.6834328 | V18: =MAX(0,I18-پارامترها!$B$9/1000000) -> 33190 | W18: =V18/(G18*پارامترها!$B$7) -> 60.840615 | X18: =پارامترها!$B$12/1000000/(G18/12)*100 -> 26.578287 | Y18: =ROUND(50*MIN(1,3/K18)+50*MIN(1,30/P18),1) -> 34.1 | Z18: =RANK(Y18,$Y$2:$Y$350,0) -> 23 | AA18: 78 | AB18: 61 | AC18: آگهی اجاره دیوار | AD18: دقیق | AE18: چیذر | AF18: A
A19: 18 | B19: 1 | C19: ازگل | D19: 25362 | E19: =ROUND(D19/INDEX(مناطق!$D$2:$D$23,B19),0) -> 8692 | F19: 1.7436 | G19: =پارامترها!$B$5*F19/1000000 -> 1697.1331 | H19: 439 | I19: =H19*پارامترها!$B$6 -> 32925 | J19: 130 | K19: =I19/G19 -> 19.400365 | L19: =I19/(پارامترها!$B$5/1000000) -> 33.826476 | M19: =K19/پارامترها!$B$7 -> 64.667882 | N19: 41.26 | O19: =N19*پارامترها!$B$6*پارامترها!$B$16 -> 92.835 | P19: =O19*12/G19*100 -> 65.641288 | Q19: =O19*12/(پارامترها!$B$5/1000000)*100 -> 114.45215 | R19: =IF(P19<=30,"قابل استطاعت",IF(P19<=50,"زیر فشار","فشار شدید")) -> فشار شدید | S19: =(1-NORMSDIST((LN(O19*12*1000000/پارامترها!$B$8)-پارامترها!$B$15)/پارامترها!$B$14))*100 -> 3.6186514 | T19: =(1-NORMSDIST((LN(I19*1000000/5)-پارامترها!$B$15)/پارامترها!$B$14))*100 -> 0.96463558 | U19: =MIN(100,پارامترها!$B$9/1000000/I19*100) -> 6.0744115 | V19: =MAX(0,I19-پارامترها!$B$9/1000000) -> 30925 | W19: =V19/(G19*پارامترها!$B$7) -> 60.739688 | X19: =پارامترها!$B$12/1000000/(G19/12)*100 -> 28.477607 | Y19: =ROUND(50*MIN(1,3/K19)+50*MIN(1,30/P19),1) -> 30.6 | Z19: =RANK(Y19,$Y$2:$Y$350,0) -> 123 | AA19: 86 | AB19: 91 | AC19: آگهی اجاره دیوار | AD19: دقیق | AE19: ازگل | AF19: A
A20: 19 | B20: 1 | C20: اوین | D20: 8226 | E20: =ROUND(D20/INDEX(مناطق!$D$2:$D$23,B20),0) -> 2819 | F20: 1.7227 | G20: =پارامترها!$B$5*F20/1000000 -> 1676.79 | H20: 433.9 | I20: =H20*پارامترها!$B$6 -> 32542.5 | J20: 115 | K20: =I20/G20 -> 19.407618 | L20: =I20/(پارامترها!$B$5/1000000) -> 33.433503 | M20: =K20/پارامترها!$B$7 -> 64.692059 | N20: 39.95 | O20: =N20*پارامترها!$B$6*پارامترها!$B$16 -> 89.8875 | P20: =O20*12/G20*100 -> 64.328268 | Q20: =O20*12/(پارامترها!$B$5/1000000)*100 -> 110.81831 | R20: =IF(P20<=30,"قابل استطاعت",IF(P20<=50,"زیر فشار","فشار شدید")) -> فشار شدید | S20: =(1-NORMSDIST((LN(O20*12*1000000/پارامترها!$B$8)-پارامترها!$B$15)/پارامترها!$B$14))*100 -> 3.8683066 | T20: =(1-NORMSDIST((LN(I20*1000000/5)-پارامترها!$B$15)/پارامترها!$B$14))*100 -> 0.99361959 | U20: =MIN(100,پارامترها!$B$9/1000000/I20*100) -> 6.1458093 | V20: =MAX(0,I20-پارامترها!$B$9/1000000) -> 30542.5 | W20: =V20/(G20*پارامترها!$B$7) -> 60.716208 | X20: =پارامترها!$B$12/1000000/(G20/12)*100 -> 28.823101 | Y20: =ROUND(50*MIN(1,3/K20)+50*MIN(1,30/P20),1) -> 31 | Z20: =RANK(Y20,$Y$2:$Y$350,0) -> 103 | AA20: 50 | AB20: 74 | AC20: آگهی اجاره دیوار | AD20: دقیق | AE20: اوین | AF20: A
A21: 20 | B21: 1 | C21: دربند | D21: 11282 | E21: =ROUND(D21/INDEX(مناطق!$D$2:$D$23,B21),0) -> 3866 | F21: 1.698 | G21: =پارامترها!$B$5*F21/1000000 -> 1652.7483 | H21: 427.9 | I21: =H21*پارامترها!$B$6 -> 32092.5 | J21: 119 | K21: =I21/G21 -> 19.417657 | L21: =I21/(پارامترها!$B$5/1000000) -> 32.971182 | M21: =K21/پارامترها!$B$7 -> 64.725524 | N21: 39.66 | O21: =N21*پارامترها!$B$6*پارامترها!$B$16 -> 89.235 | P21: =O21*12/G21*100 -> 64.790265 | Q21: =O21*12/(پارامترها!$B$5/1000000)*100 -> 110.01387 | R21: =IF(P21<=30,"قابل استطاعت",IF(P21<=50,"زیر فشار","فشار شدید")) -> فشار شدید | S21: =(1-NORMSDIST((LN(O21*12*1000000/پارامترها!$B$8)-پارامترها!$B$15)/پارامترها!$B$14))*100 -> 3.9265795 | T21: =(1-NORMSDIST((LN(I21*1000000/5)-پارامترها!$B$15)/پارامترها!$B$14))*100 -> 1.0291482 | U21: =MIN(100,پارامترها!$B$9/1000000/I21*100) -> 6.2319857 | V21: =MAX(0,I21-پارامترها!$B$9/1000000) -> 30092.5 | W21: =V21/(G21*پارامترها!$B$7) -> 60.691839 | X21: =پارامترها!$B$12/1000000/(G21/12)*100 -> 29.242377 | Y21: =ROUND(50*MIN(1,3/K21)+50*MIN(1,30/P21),1) -> 30.9 | Z21: =RANK(Y21,$Y$2:$Y$350,0) -> 109 | AA21: 46 | AB21: 63 | AC21: آگهی اجاره دیوار | AD21: دقیق | AE21: دربند | AF21: A
A22: 21 | B22: 1 | C22: دانشگاه - گلها | D22: 3048 | E22: =ROUND(D22/INDEX(مناطق!$D$2:$D$23,B22),0) -> 1045 | F22: 1.6889 | G22: =پارامترها!$B$5*F22/1000000 -> 1643.8908 | H22: 425.7 | I22: =H22*پارامترها!$B$6 -> 31927.5 | J22: 110 | K22: =I22/G22 -> 19.42191 | L22: =I22/(پارامترها!$B$5/1000000) -> 32.801664 | M22: =K22/پارامترها!$B$7 -> 64.739701 | N22: 32.4 | O22: =N22*پارامترها!$B$6*پارامترها!$B$16 -> 72.9 | P22: =O22*12/G22*100 -> 53.215213 | Q22: =O22*12/(پارامترها!$B$5/1000000)*100 -> 89.875173 | R22: =IF(P22<=30,"قابل استطاعت",IF(P22<=50,"زیر فشار","فشار شدید")) -> فشار شدید | S22: =(1-NORMSDIST((LN(O22*12*1000000/پارامترها!$B$8)-پارامترها!$B$15)/پارامترها!$B$14))*100 -> 5.8487477 | T22: =(1-NORMSDIST((LN(I22*1000000/5)-پارامترها!$B$15)/پارامترها!$B$14))*100 -> 1.0425785 | U22: =MIN(100,پارامترها!$B$9/1000000/I22*100) -> 6.2641923 | V22: =MAX(0,I22-پارامترها!$B$9/1000000) -> 29927.5 | W22: =V22/(G22*پارامترها!$B$7) -> 60.684282 | X22: =پارامترها!$B$12/1000000/(G22/12)*100 -> 29.399938 | Y22: =ROUND(50*MIN(1,3/K22)+50*MIN(1,30/P22),1) -> 35.9 | Z22: =RANK(Y22,$Y$2:$Y$350,0) -> 5 | AA22: 29 | AB22: 21 | AC22: آگهی اجاره دیوار | AD22: دستی (نام مرکب/معادل) | AE22: شهرک گلها | AF22: B
A23: 22 | B23: 1 | C23: درکه | D23: 6719 | E23: =ROUND(D23/INDEX(مناطق!$D$2:$D$23,B23),0) -> 2303 | F23: 1.6465 | G23: =پارامترها!$B$5*F23/1000000 -> 1602.6208 | H23: 415.3 | I23: =H23*پارامترها!$B$6 -> 31147.5 | J23: 130 | K23: =I23/G23 -> 19.435353 | L23: =I23/(پارامترها!$B$5/1000000) -> 32.000308 | M23: =K23/پارامترها!$B$7 -> 64.784509 | N23: 31.37 | O23: =N23*پارامترها!$B$6*پارامترها!$B$16 -> 70.5825 | P23: =O23*12/G23*100 -> 52.850307 | Q23: =O23*12/(پارامترها!$B$5/1000000)*100 -> 87.018031 | R23: =IF(P23<=30,"قابل استطاعت",IF(P23<=50,"زیر فشار","فشار شدید")) -> فشار شدید | S23: =(1-NORMSDIST((LN(O23*12*1000000/پارامترها!$B$8)-پارامترها!$B$15)/پارامترها!$B$14))*100 -> 6.2150151 | T23: =(1-NORMSDIST((LN(I23*1000000/5)-پارامترها!$B$15)/پارامترها!$B$14))*100 -> 1.109168 | U23: =MIN(100,پارامترها!$B$9/1000000/I23*100) -> 6.4210611 | V23: =MAX(0,I23-پارامترها!$B$9/1000000) -> 29147.5 | W23: =V23/(G23*پارامترها!$B$7) -> 60.624656 | X23: =پارامترها!$B$12/1000000/(G23/12)*100 -> 30.157034 | Y23: =ROUND(50*MIN(1,3/K23)+50*MIN(1,30/P23),1) -> 36.1 | Z23: =RANK(Y23,$Y$2:$Y$350,0) -> 4 | AA23: 50 | AB23: 55 | AC23: آگهی اجاره دیوار | AD23: دقیق | AE23: درکه | AF23: A
A24: 23 | B24: 1 | C24: شهرک نفت | D24: 24137 | E24: =ROUND(D24/INDEX(مناطق!$D$2:$D$23,B24),0) -> 8272 | F24: 1.5836 | G24: =پارامترها!$B$5*F24/1000000 -> 1541.3971 | H24: 400 | I24: =H24*پارامترها!$B$6 -> 30000 | J24: 120 | K24: =I24/G24 -> 19.462863 | L24: =I24/(پارامترها!$B$5/1000000) -> 30.82139 | M24: =K24/پارامترها!$B$7 -> 64.87621 | N24: 34.91 | O24: =N24*پارامترها!$B$6*پارامترها!$B$16 -> 78.5475 | P24: =O24*12/G24*100 -> 61.15037 | Q24: =O24*12/(پارامترها!$B$5/1000000)*100 -> 96.837725 | R24: =IF(P24<=30,"قابل استطاعت",IF(P24<=50,"زیر فشار","فشار شدید")) -> فشار شدید | S24: =(1-NORMSDIST((LN(O24*12*1000000/پارامترها!$B$8)-پارامترها!$B$15)/پارامترها!$B$14))*100 -> 5.0676074 | T24: =(1-NORMSDIST((LN(I24*1000000/5)-پارامترها!$B$15)/پارامترها!$B$14))*100 -> 1.2172874 | U24: =MIN(100,پارامترها!$B$9/1000000/I24*100) -> 6.6666667 | V24: =MAX(0,I24-پارامترها!$B$9/1000000) -> 28000 | W24: =V24/(G24*پارامترها!$B$7) -> 60.55113 | X24: =پارامترها!$B$12/1000000/(G24/12)*100 -> 31.35486 | Y24: =ROUND(50*MIN(1,3/K24)+50*MIN(1,30/P24),1) -> 32.2 | Z24: =RANK(Y24,$Y$2:$Y$350,0) -> 53 | AA24: 80 | AB24: 85 | AC24: آگهی اجاره دیوار | AD24: دستی (نام مرکب/معادل) | AE24: مینی‌سیتی (شهرک نفت) | AF24: A
A25: 24 | B25: 1 | C25: دارآباد | D25: 15236 | E25: =ROUND(D25/INDEX(مناطق!$D$2:$D$23,B25),0) -> 5221 | F25: 1.5833 | G25: =پارامترها!$B$5*F25/1000000 -> 1541.1051 | H25: 399.9 | I25: =H25*پارامترها!$B$6 -> 29992.5 | J25: 100 | K25: =I25/G25 -> 19.461684 | L25: =I25/(پارامترها!$B$5/1000000) -> 30.813685 | M25: =K25/پارامترها!$B$7 -> 64.872281 | N25: 37.99 | O25: =N25*پارامترها!$B$6*پارامترها!$B$16 -> 85.4775 | P25: =O25*12/G25*100 -> 66.558084 | Q25: =O25*12/(پارامترها!$B$5/1000000)*100 -> 105.38141 | R25: =IF(P25<=30,"قابل استطاعت",IF(P25<=50,"زیر فشار","فشار شدید")) -> فشار شدید | S25: =(1-NORMSDIST((LN(O25*12*1000000/پارامترها!$B$8)-پارامترها!$B$15)/پارامترها!$B$14))*100 -> 4.2853907 | T25: =(1-NORMSDIST((LN(I25*1000000/5)-پارامترها!$B$15)/پارامترها!$B$14))*100 -> 1.2180372 | U25: =MIN(100,پارامترها!$B$9/1000000/I25*100) -> 6.6683338 | V25: =MAX(0,I25-پارامترها!$B$9/1000000) -> 27992.5 | W25: =V25/(G25*پارامترها!$B$7) -> 60.546381 | X25: =پارامترها!$B$12/1000000/(G25/12)*100 -> 31.360801 | Y25: =ROUND(50*MIN(1,3/K25)+50*MIN(1,30/P25),1) -> 30.2 | Z25: =RANK(Y25,$Y$2:$Y$350,0) -> 156 | AA25: 81 | AB25: 91 | AC25: آگهی اجاره دیوار | AD25: دقیق | AE25: دارآباد | AF25: A
A26: 25 | B26: 1 | C26: سوهانک | D26: 22829 | E26: =ROUND(D26/INDEX(مناطق!$D$2:$D$23,B26),0) -> 7824 | F26: 1.5563 | G26: =پارامترها!$B$5*F26/1000000 -> 1514.8246 | H26: 393.3 | I26: =H26*پارامترها!$B$6 -> 29497.5 | J26: 125 | K26: =I26/G26 -> 19.472551 | L26: =I26/(پارامترها!$B$5/1000000) -> 30.305132 | M26: =K26/پارامترها!$B$7 -> 64.908505 | N26: 31.83 | O26: =N26*پارامترها!$B$6*پارامترها!$B$16 -> 71.6175 | P26: =O26*12/G26*100 -> 56.733301 | Q26: =O26*12/(پارامترها!$B$5/1000000)*100 -> 88.294036 | R26: =IF(P26<=30,"قابل استطاعت",IF(P26<=50,"زیر فشار","فشار شدید")) -> فشار شدید | S26: =(1-NORMSDIST((LN(O26*12*1000000/پارامترها!$B$8)-پارامترها!$B$15)/پارامترها!$B$14))*100 -> 6.0478194 | T26: =(1-NORMSDIST((LN(I26*1000000/5)-پارامترها!$B$15)/پارامترها!$B$14))*100 -> 1.2688498 | U26: =MIN(100,پارامترها!$B$9/1000000/I26*100) -> 6.7802356 | V26: =MAX(0,I26-پارامترها!$B$9/1000000) -> 27497.5 | W26: =V26/(G26*پارامترها!$B$7) -> 60.507555 | X26: =پارامترها!$B$12/1000000/(G26/12)*100 -> 31.904874 | Y26: =ROUND(50*MIN(1,3/K26)+50*MIN(1,30/P26),1) -> 34.1 | Z26: =RANK(Y26,$Y$2:$Y$350,0) -> 23 | AA26: 89 | AB26: 88 | AC26: آگهی اجاره دیوار | AD26: دقیق | AE26: سوهانک | AF26: A
A27: 26 | B27: 1 | C27: شهرک محلاتی | D27: 32186 | E27: =ROUND(D27/INDEX(مناطق!$D$2:$D$23,B27),0) -> 11030 | F27: 1.4089 | G27: =پارامترها!$B$5*F27/1000000 -> 1371.3528 | H27: 357.3 | I27: =H27*پارامترها!$B$6 -> 26797.5 | J27: 115 | K27: =I27/G27 -> 19.540923 | L27: =I27/(پارامترها!$B$5/1000000) -> 27.531207 | M27: =K27/پارامترها!$B$7 -> 65.136411 | N27: 28.23 | O27: =N27*پارامترها!$B$6*پارامترها!$B$16 -> 63.5175 | P27: =O27*12/G27*100 -> 55.580883 | Q27: =O27*12/(پارامترها!$B$5/1000000)*100 -> 78.307906 | R27: =IF(P27<=30,"قابل استطاعت",IF(P27<=50,"زیر فشار","فشار شدید")) -> فشار شدید | S27: =(1-NORMSDIST((LN(O27*12*1000000/پارامترها!$B$8)-پارامترها!$B$15)/پارامترها!$B$14))*100 -> 7.5360659 | T27: =(1-NORMSDIST((LN(I27*1000000/5)-پارامترها!$B$15)/پارامترها!$B$14))*100 -> 1.5992044 | U27: =MIN(100,پارامترها!$B$9/1000000/I27*100) -> 7.4633828 | V27: =MAX(0,I27-پارامترها!$B$9/1000000) -> 24797.5 | W27: =V27/(G27*پارامترها!$B$7) -> 60.275031 | X27: =پارامترها!$B$12/1000000/(G27/12)*100 -> 35.242782 | Y27: =ROUND(50*MIN(1,3/K27)+50*MIN(1,30/P27),1) -> 34.7 | Z27: =RANK(Y27,$Y$2:$Y$350,0) -> 14 | AA27: 56 | AB27: 45 | AC27: آگهی اجاره دیوار | AD27: دقیق | AE27: شهرک محلاتی | AF27: A
A28: 27 | B28: 1 | C28: گلابدره | D28: 14224 | E28: =ROUND(D28/INDEX(مناطق!$D$2:$D$23,B28),0) -> 4875 | F28: 1.142 | G28: =پارامترها!$B$5*F28/1000000 -> 1111.5657 | H28: 291.7 | I28: =H28*پارامترها!$B$6 -> 21877.5 | J28: 80 | K28: =I28/G28 -> 19.681698 | L28: =I28/(پارامترها!$B$5/1000000) -> 22.476499 | M28: =K28/پارامترها!$B$7 -> 65.605659 | N28: 26.31 | O28: =N28*پارامترها!$B$6*پارامترها!$B$16 -> 59.1975 | P28: =O28*12/G28*100 -> 63.907154 | Q28: =O28*12/(پارامترها!$B$5/1000000)*100 -> 72.981969 | R28: =IF(P28<=30,"قابل استطاعت",IF(P28<=50,"زیر فشار","فشار شدید")) -> فشار شدید | S28: =(1-NORMSDIST((LN(O28*12*1000000/پارامترها!$B$8)-پارامترها!$B$15)/پارامترها!$B$14))*100 -> 8.530999 | T28: =(1-NORMSDIST((LN(I28*1000000/5)-پارامترها!$B$15)/پارامترها!$B$14))*100 -> 2.5450912 | U28: =MIN(100,پارامترها!$B$9/1000000/I28*100) -> 9.1418124 | V28: =MAX(0,I28-پارامترها!$B$9/1000000) -> 19877.5 | W28: =V28/(G28*پارامترها!$B$7) -> 59.608113 | X28: =پارامترها!$B$12/1000000/(G28/12)*100 -> 43.479471 | Y28: =ROUND(50*MIN(1,3/K28)+50*MIN(1,30/P28),1) -> 31.1 | Z28: =RANK(Y28,$Y$2:$Y$350,0) -> 95 | AA28: 17 | AB28: 10 | AC28: آگهی اجاره دیوار | AD28: دقیق | AE28: گلاب دره | AF28: B
... A37: 36 | B37: 2 | C37: مرزداران شرقی | D37: 42043 | E37: =ROUND(D37/INDEX(مناطق!$D$2:$D$23,B37),0) -> 14387 | F37: 1.6297 | G37: =پارامترها!$B$5*F37/1000000 -> 1586.2685 | H37: 410.6 | I37: =H37*پارامترها!$B$6 -> 30795 | J37: 103 | K37: =I37/G37 -> 19.413485 | L37: =I37/(پارامترها!$B$5/1000000) -> 31.638157 | M37: =K37/پارامترها!$B$7 -> 64.711617 | N37: 33.09 | O37: =N37*پارامترها!$B$6*پارامترها!$B$16 -> 74.4525 | P37: =O37*12/G37*100 -> 56.322748 | Q37: =O37*12/(پارامترها!$B$5/1000000)*100 -> 91.789182 | R37: =IF(P37<=30,"قابل استطاعت",IF(P37<=50,"زیر فشار","فشار شدید")) -> فشار شدید | S37: =(1-NORMSDIST((LN(O37*12*1000000/پارامترها!$B$8)-پارامترها!$B$15)/پارامترها!$B$14))*100 -> 5.6191221 | T37: =(1-NORMSDIST((LN(I37*1000000/5)-پارامترها!$B$15)/پارامترها!$B$14))*100 -> 1.1410331 | U37: =MIN(100,پارامترها!$B$9/1000000/I37*100) -> 6.4945608 | V37: =MAX(0,I37-پارامترها!$B$9/1000000) -> 28795 | W37: =V37/(G37*پارامترها!$B$7) -> 60.508882 | X37: =پارامترها!$B$12/1000000/(G37/12)*100 -> 30.467912 | Y37: =ROUND(50*MIN(1,3/K37)+50*MIN(1,30/P37),1) -> 34.4 | Z37: =RANK(Y37,$Y$2:$Y$350,0) -> 20 | AA37: 89 | AB37: 93 | AC37: آگهی اجاره دیوار | AD37: دستی (نام مرکب/معادل) | AE37: مرزداران | AF37: A
A38: 37 | B38: 2 | C38: سپهر | D38: 33619 | E38: =ROUND(D38/INDEX(مناطق!$D$2:$D$23,B38),0) -> 11504 | F38: 1.6107 | G38: =پارامترها!$B$5*F38/1000000 -> 1567.7748 | H38: 406 | I38: =H38*پارامترها!$B$6 -> 30450 | K38: =I38/G38 -> 19.422432 | L38: =I38/(پارامترها!$B$5/1000000) -> 31.283711 | M38: =K38/پارامترها!$B$7 -> 64.741439 | N38: 39.96 | O38: =N38*پارامترها!$B$6*پارامترها!$B$16 -> 89.91 | P38: =O38*12/G38*100 -> 68.818555 | Q38: =O38*12/(پارامترها!$B$5/1000000)*100 -> 110.84605 | R38: =IF(P38<=30,"قابل استطاعت",IF(P38<=50,"زیر فشار","فشار شدید")) -> فشار شدید | S38: =(1-NORMSDIST((LN(O38*12*1000000/پارامترها!$B$8)-پارامترها!$B$15)/پارامترها!$B$14))*100 -> 3.8663173 | T38: =(1-NORMSDIST((LN(I38*1000000/5)-پارامترها!$B$15)/پارامترها!$B$14))*100 -> 1.1733557 | U38: =MIN(100,پارامترها!$B$9/1000000/I38*100) -> 6.5681445 | V38: =MAX(0,I38-پارامترها!$B$9/1000000) -> 28450 | W38: =V38/(G38*پارامترها!$B$7) -> 60.489128 | X38: =پارامترها!$B$12/1000000/(G38/12)*100 -> 30.827315 | Y38: =ROUND(50*MIN(1,3/K38)+50*MIN(1,30/P38),1) -> 29.5 | Z38: =RANK(Y38,$Y$2:$Y$350,0) -> 194 | AA38: 0 | AB38: 0 | AC38: برآورد از قیمت فروش | AD38: بدون داده (میانگین منطقه) | AE38: — | AF38: D
A39: 38 | B39: 2 | C39: شهرک قدس | D39: 29776 | E39: =ROUND(D39/INDEX(مناطق!$D$2:$D$23,B39),0) -> 10189 | F39: 1.6107 | G39: =پارامترها!$B$5*F39/1000000 -> 1567.7748 | H39: 406 | I39: =H39*پارامترها!$B$6 -> 30450 | K39: =I39/G39 -> 19.422432 | L39: =I39/(پارامترها!$B$5/1000000) -> 31.283711 | M39: =K39/پارامترها!$B$7 -> 64.741439 | N39: 39.96 | O39: =N39*پارامترها!$B$6*پارامترها!$B$16 -> 89.91 | P39: =O39*12/G39*100 -> 68.818555 | Q39: =O39*12/(پارامترها!$B$5/1000000)*100 -> 110.84605 | R39: =IF(P39<=30,"قابل استطاعت",IF(P39<=50,"زیر فشار","فشار شدید")) -> فشار شدید | S39: =(1-NORMSDIST((LN(O39*12*1000000/پارامترها!$B$8)-پارامترها!$B$15)/پارامترها!$B$14))*100 -> 3.8663173 | T39: =(1-NORMSDIST((LN(I39*1000000/5)-پارامترها!$B$15)/پارامترها!$B$14))*100 -> 1.1733557 | U39: =MIN(100,پارامترها!$B$9/1000000/I39*100) -> 6.5681445 | V39: =MAX(0,I39-پارامترها!$B$9/1000000) -> 28450 | W39: =V39/(G39*پارامترها!$B$7) -> 60.489128 | X39: =پارامترها!$B$12/1000000/(G39/12)*100 -> 30.827315 | Y39: =ROUND(50*MIN(1,3/K39)+50*MIN(1,30/P39),1) -> 29.5 | Z39: =RANK(Y39,$Y$2:$Y$350,0) -> 194 | AA39: 0 | AB39: 0 | AC39: برآورد از قیمت فروش | AD39: بدون داده (میانگین منطقه) | AE39: — | AF39: D
A40: 39 | B40: 2 | C40: تیموری | D40: 17555 | E40: =ROUND(D40/INDEX(مناطق!$D$2:$D$23,B40),0) -> 6007 | F40: 1.6107 | G40: =پارامترها!$B$5*F40/1000000 -> 1567.7748 | H40: 406 | I40: =H40*پارامترها!$B$6 -> 30450 | K40: =I40/G40 -> 19.422432 | L40: =I40/(پارامترها!$B$5/1000000) -> 31.283711 | M40: =K40/پارامترها!$B$7 -> 64.741439 | N40: 39.96 | O40: =N40*پارامترها!$B$6*پارامترها!$B$16 -> 89.91 | P40: =O40*12/G40*100 -> 68.818555 | Q40: =O40*12/(پارامترها!$B$5/1000000)*100 -> 110.84605 | R40: =IF(P40<=30,"قابل استطاعت",IF(P40<=50,"زیر فشار","فشار شدید")) -> فشار شدید | S40: =(1-NORMSDIST((LN(O40*12*1000000/پارامترها!$B$8)-پارامترها!$B$15)/پارامترها!$B$14))*100 -> 3.8663173 | T40: =(1-NORMSDIST((LN(I40*1000000/5)-پارامترها!$B$15)/پارامترها!$B$14))*100 -> 1.1733557 | U40: =MIN(100,پارامترها!$B$9/1000000/I40*100) -> 6.5681445 | V40: =MAX(0,I40-پارامترها!$B$9/1000000) -> 28450 | W40: =V40/(G40*پارامترها!$B$7) -> 60.489128 | X40: =پارامترها!$B$12/1000000/(G40/12)*100 -> 30.827315 | Y40: =ROUND(50*MIN(1,3/K40)+50*MIN(1,30/P40),1) -> 29.5 | Z40: =RANK(Y40,$Y$2:$Y$350,0) -> 194 | AA40: 0 | AB40: 0 | AC40: برآورد از قیمت فروش | AD40: بدون داده (میانگین منطقه) | AE40: — | AF40: D
A41: 40 | B41: 2 | C41: پونک | D41: 25981 | E41: =ROUND(D41/INDEX(مناطق!$D$2:$D$23,B41),0) -> 8890 | F41: 1.51 | G41: =پارامترها!$B$5*F41/1000000 -> 1469.7585 | H41: 381.5 | I41: =H41*پارامترها!$B$6 -> 28612.5 | J41: 87.5 | K41: =I41/G41 -> 19.467484 | L41: =I41/(پارامترها!$B$5/1000000) -> 29.395901 | M41: =K41/پارامترها!$B$7 -> 64.891613 | N41: 33.08 | O41: =N41*پارامترها!$B$6*پارامترها!$B$16 -> 74.43 | P41: =O41*12/G41*100 -> 60.769167 | Q41: =O41*12/(پارامترها!$B$5/1000000)*100 -> 91.761442 | R41: =IF(P41<=30,"قابل استطاعت",IF(P41<=50,"زیر فشار","فشار شدید")) -> فشار شدید | S41: =(1-NORMSDIST((LN(O41*12*1000000/پارامترها!$B$8)-پارامترها!$B$15)/پارامترها!$B$14))*100 -> 5.6223647 | T41: =(1-NORMSDIST((LN(I41*1000000/5)-پارامترها!$B$15)/پارامترها!$B$14))*100 -> 1.3666217 | U41: =MIN(100,پارامترها!$B$9/1000000/I41*100) -> 6.9899519 | V41: =MAX(0,I41-پارامترها!$B$9/1000000) -> 26612.5 | W41: =V41/(G41*پارامترها!$B$7) -> 60.355721 | X41: =پارامترها!$B$12/1000000/(G41/12)*100 -> 32.88315 | Y41: =ROUND(50*MIN(1,3/K41)+50*MIN(1,30/P41),1) -> 32.4 | Z41: =RANK(Y41,$Y$2:$Y$350,0) -> 47 | AA41: 90 | AB41: 89 | AC41: آگهی اجاره دیوار | AD41: دقیق | AE41: پونک | AF41: A
A42: 41 | B42: 2 | C42: پرواز | D42: 13348 | E42: =ROUND(D42/INDEX(مناطق!$D$2:$D$23,B42),0) -> 4568 | F42: 1.3728 | G42: =پارامترها!$B$5*F42/1000000 -> 1336.2149 | H42: 347.9 | I42: =H42*پارامترها!$B$6 -> 26092.5 | J42: 102 | K42: =I42/G42 -> 19.527174 | L42: =I42/(پارامترها!$B$5/1000000) -> 26.806904 | M42: =K42/پارامترها!$B$7 -> 65.090579 | N42: 41.16 | O42: =N42*پارامترها!$B$6*پارامترها!$B$16 -> 92.61 | P42: =O42*12/G42*100 -> 83.169258 | Q42: =O42*12/(پارامترها!$B$5/1000000)*100 -> 114.17476 | R42: =IF(P42<=30,"قابل استطاعت",IF(P42<=50,"زیر فشار","فشار شدید")) -> فشار شدید | S42: =(1-NORMSDIST((LN(O42*12*1000000/پارامترها!$B$8)-پارامترها!$B$15)/پارامترها!$B$14))*100 -> 3.6369571 | T42: =(1-NORMSDIST((LN(I42*1000000/5)-پارامترها!$B$15)/پارامترها!$B$14))*100 -> 1.7031086 | U42: =MIN(100,پارامترها!$B$9/1000000/I42*100) -> 7.6650378 | V42: =MAX(0,I42-پارامترها!$B$9/1000000) -> 24092.5 | W42: =V42/(G42*پارامترها!$B$7) -> 60.101361 | X42: =پارامترها!$B$12/1000000/(G42/12)*100 -> 36.169548 | Y42: =ROUND(50*MIN(1,3/K42)+50*MIN(1,30/P42),1) -> 25.7 | Z42: =RANK(Y42,$Y$2:$Y$350,0) -> 313 | AA42: 25 | AB42: 30 | AC42: آگهی اجاره دیوار | AD42: دستی (نام مرکب/معادل) | AE42: پرواز | AF42: B
A43: 42 | B43: 2 | C43: شهر آرا | D43: 36305 | E43: =ROUND(D43/INDEX(مناطق!$D$2:$D$23,B43),0) -> 12423 | F43: 1.3527 | G43: =پارامترها!$B$5*F43/1000000 -> 1316.6505 | H43: 343 | I43: =H43*پارامترها!$B$6 -> 25725 | J43: 108 | K43: =I43/G43 -> 19.538214 | L43: =I43/(پارامترها!$B$5/1000000) -> 26.429342 | M43: =K43/پارامترها!$B$7 -> 65.12738 | N43: 27.03 | O43: =N43*پارامترها!$B$6*پارامترها!$B$16 -> 60.8175 | P43: =O43*12/G43*100 -> 55.429286 | Q43: =O43*12/(پارامترها!$B$5/1000000)*100 -> 74.979196 | R43: =IF(P43<=30,"قابل استطاعت",IF(P43<=50,"زیر فشار","فشار شدید")) -> فشار شدید | S43: =(1-NORMSDIST((LN(O43*12*1000000/پارامترها!$B$8)-پارامترها!$B$15)/پارامترها!$B$14))*100 -> 8.138602 | T43: =(1-NORMSDIST((LN(I43*1000000/5)-پارامترها!$B$15)/پارامترها!$B$14))*100 -> 1.7607049 | U43: =MIN(100,پارامترها!$B$9/1000000/I43*100) -> 7.7745384 | V43: =MAX(0,I43-پارامترها!$B$9/1000000) -> 23725 | W43: =V43/(G43*پارامترها!$B$7) -> 60.064027 | X43: =پارامترها!$B$12/1000000/(G43/12)*100 -> 36.706998 | Y43: =ROUND(50*MIN(1,3/K43)+50*MIN(1,30/P43),1) -> 34.7 | Z43: =RANK(Y43,$Y$2:$Y$350,0) -> 14 | AA43: 93 | AB43: 88 | AC43: آگهی اجاره دیوار | AD43: دقیق | AE43: شهرآرا | AF43: A
A44: 43 | B44: 2 | C44: تهران ویلا | D44: 17173 | E44: =ROUND(D44/INDEX(مناطق!$D$2:$D$23,B44),0) -> 5876 | F44: 1.2672 | G44: =پارامترها!$B$5*F44/1000000 -> 1233.4291 | H44: 322 | I44: =H44*پارامترها!$B$6 -> 24150 | J44: 100 | K44: =I44/G44 -> 19.57956 | L44: =I44/(پارامترها!$B$5/1000000) -> 24.811219 | M44: =K44/پارامترها!$B$7 -> 65.265201 | N44: 27.91 | O44: =N44*پارامترها!$B$6*پارامترها!$B$16 -> 62.7975 | P44: =O44*12/G44*100 -> 61.095525 | Q44: =O44*12/(پارامترها!$B$5/1000000)*100 -> 77.42025 | R44: =IF(P44<=30,"قابل استطاعت",IF(P44<=50,"زیر فشار","فشار شدید")) -> فشار شدید | S44: =(1-NORMSDIST((LN(O44*12*1000000/پارامترها!$B$8)-پارامترها!$B$15)/پارامترها!$B$14))*100 -> 7.6908073 | T44: =(1-NORMSDIST((LN(I44*1000000/5)-پارامترها!$B$15)/پارامترها!$B$14))*100 -> 2.0378488 | U44: =MIN(100,پارامترها!$B$9/1000000/I44*100) -> 8.2815735 | V44: =MAX(0,I44-پارامترها!$B$9/1000000) -> 22150 | W44: =V44/(G44*پارامترها!$B$7) -> 59.860216 | X44: =پارامترها!$B$12/1000000/(G44/12)*100 -> 39.183677 | Y44: =ROUND(50*MIN(1,3/K44)+50*MIN(1,30/P44),1) -> 32.2 | Z44: =RANK(Y44,$Y$2:$Y$350,0) -> 53 | AA44: 93 | AB44: 80 | AC44: آگهی اجاره دیوار | AD44: دقیق | AE44: تهران‌ویلا | AF44: A
A45: 44 | B45: 2 | C45: برق آلستوم(ستارخان) | D45: 26267 | E45: =ROUND(D45/INDEX(مناطق!$D$2:$D$23,B45),0) -> 8988 | F45: 1.1891 | G45: =پارامترها!$B$5*F45/1000000 -> 1157.4105 | H45: 302.8 | I45: =H45*پارامترها!$B$6 -> 22710 | J45: 102 | K45: =I45/G45 -> 19.621388 | L45: =I45/(پارامترها!$B$5/1000000) -> 23.331792 | M45: =K45/پارامترها!$B$7 -> 65.404626 | N45: 26.26 | O45: =N45*پارامترها!$B$6*پارامترها!$B$16 -> 59.085 | P45: =O45*12/G45*100 -> 61.259165 | Q45: =O45*12/(پارامترها!$B$5/1000000)*100 -> 72.843273 | R45: =IF(P45<=30,"قابل استطاعت",IF(P45<=50,"زیر فشار","فشار شدید")) -> فشار شدید | S45: =(1-NORMSDIST((LN(O45*12*1000000/پارامترها!$B$8)-پارامترها!$B$15)/پارامترها!$B$14))*100 -> 8.5591717 | T45: =(1-NORMSDIST((LN(I45*1000000/5)-پارامترها!$B$15)/پارامترها!$B$14))*100 -> 2.3421811 | U45: =MIN(100,پارامترها!$B$9/1000000/I45*100) -> 8.8066931 | V45: =MAX(0,I45-پارامترها!$B$9/1000000) -> 20710 | W45: =V45/(G45*پارامترها!$B$7) -> 59.644641 | X45: =پارامترها!$B$12/1000000/(G45/12)*100 -> 41.757258 | Y45: =ROUND(50*MIN(1,3/K45)+50*MIN(1,30/P45),1) -> 32.1 | Z45: =RANK(Y45,$Y$2:$Y$350,0) -> 58 | AA45: 95 | AB45: 86 | AC45: آگهی اجاره دیوار | AD45: جایگزین (محله مجاور) | AE45: ستارخان | AF45: B
A46: 45 | B46: 2 | C46: صادقیه | D46: 42945 | E46: =ROUND(D46/INDEX(مناطق!$D$2:$D$23,B46),0) -> 14695 | F46: 1.1211 | G46: =پارامترها!$B$5*F46/1000000 -> 1091.2227 | H46: 286.1 | I46: =H46*پارامترها!$B$6 -> 21457.5 | J46: 98 | K46: =I46/G46 -> 19.663722 | L46: =I46/(پارامترها!$B$5/1000000) -> 22.044999 | M46: =K46/پارامترها!$B$7 -> 65.545741 | N46: 27.47 | O46: =N46*پارامترها!$B$6*پارامترها!$B$16 -> 61.8075 | P46: =O46*12/G46*100 -> 67.968712 | Q46: =O46*12/(پارامترها!$B$5/1000000)*100 -> 76.199723 | R46: =IF(P46<=30,"قابل استطاعت",IF(P46<=50,"زیر فشار","فشار شدید")) -> فشار شدید | S46: =(1-NORMSDIST((LN(O46*12*1000000/پارامترها!$B$8)-پارامترها!$B$15)/پارامترها!$B$14))*100 -> 7.9105131 | T46: =(1-NORMSDIST((LN(I46*1000000/5)-پارامترها!$B$15)/پارامترها!$B$14))*100 -> 2.6560873 | U46: =MIN(100,پارامترها!$B$9/1000000/I46*100) -> 9.3207503 | V46: =MAX(0,I46-پارامترها!$B$9/1000000) -> 19457.5 | W46: =V46/(G46*پارامترها!$B$7) -> 59.436387 | X46: =پارامترها!$B$12/1000000/(G46/12)*100 -> 44.290033 | Y46: =ROUND(50*MIN(1,3/K46)+50*MIN(1,30/P46),1) -> 29.7 | Z46: =RANK(Y46,$Y$2:$Y$350,0) -> 179 | AA46: 92 | AB46: 83 | AC46: آگهی اجاره دیوار | AD46: دستی (نام مرکب/معادل) | AE46: صادقیه | AF46: A
A47: 46 | B47: 2 | C47: توحید | D47: 34358 | E47: =ROUND(D47/INDEX(مناطق!$D$2:$D$23,B47),0) -> 11757 | F47: 1.0249 | G47: =پارامترها!$B$5*F47/1000000 -> 997.58641 | H47: 262.3 | I47: =H47*پارامترها!$B$6 -> 19672.5 | J47: 93 | K47: =I47/G47 -> 19.720096 | L47: =I47/(پارامترها!$B$5/1000000) -> 20.211127 | M47: =K47/پارامترها!$B$7 -> 65.733654 | N47: 23.81 | O47: =N47*پارامترها!$B$6*پارامترها!$B$16 -> 53.5725 | P47: =O47*12/G47*100 -> 64.442538 | Q47: =O47*12/(پارامترها!$B$5/1000000)*100 -> 66.047157 | R47: =IF(P47<=30,"قابل استطاعت",IF(P47<=50,"زیر فشار","فشار شدید")) -> فشار شدید | S47: =(1-NORMSDIST((LN(O47*12*1000000/پارامترها!$B$8)-پارامترها!$B$15)/پارامترها!$B$14))*100 -> 10.105516 | T47: =(1-NORMSDIST((LN(I47*1000000/5)-پارامترها!$B$15)/پارامترها!$B$14))*100 -> 3.204213 | U47: =MIN(100,پارامترها!$B$9/1000000/I47*100) -> 10.166476 | V47: =MAX(0,I47-پارامترها!$B$9/1000000) -> 17672.5 | W47: =V47/(G47*پارامترها!$B$7) -> 59.050858 | X47: =پارامترها!$B$12/1000000/(G47/12)*100 -> 48.44722 | Y47: =ROUND(50*MIN(1,3/K47)+50*MIN(1,30/P47),1) -> 30.9 | Z47: =RANK(Y47,$Y$2:$Y$350,0) -> 109 | AA47: 88 | AB47: 83 | AC47: آگهی اجاره دیوار | AD47: دقیق | AE47: توحید | AF47: A
A48: 47 | B48: 2 | C48: طرشت | D48: 25110 | E48: =ROUND(D48/INDEX(مناطق!$D$2:$D$23,B48),0) -> 8592 | F48: 0.975 | G48: =پارامترها!$B$5*F48/1000000 -> 949.01625 | H48: 250 | I48: =H48*پارامترها!$B$6 -> 18750 | J48: 85 | K48: =I48/G48 -> 19.757301 | L48: =I48/(پارامترها!$B$5/1000000) -> 19.263369 | M48: =K48/پارامترها!$B$7 -> 65.857671 | N48: 23.77 | O48: =N48*پارامترها!$B$6*پارامترها!$B$16 -> 53.4825 | P48: =O48*12/G48*100 -> 67.626872 | Q48: =O48*12/(پارامترها!$B$5/1000000)*100 -> 65.9362 | R48: =IF(P48<=30,"قابل استطاعت",IF(P48<=50,"زیر فشار","فشار شدید")) -> فشار شدید | S48: =(1-NORMSDIST((LN(O48*12*1000000/پارامترها!$B$8)-پارامترها!$B$15)/پارامترها!$B$14))*100 -> 10.133733 | T48: =(1-NORMSDIST((LN(I48*1000000/5)-پارامترها!$B$15)/پارامترها!$B$14))*100 -> 3.5454296 | U48: =MIN(100,پارامترها!$B$9/1000000/I48*100) -> 10.666667 | V48: =MAX(0,I48-پارامترها!$B$9/1000000) -> 16750 | W48: =V48/(G48*پارامترها!$B$7) -> 58.832853 | X48: =پارامترها!$B$12/1000000/(G48/12)*100 -> 50.926724 | Y48: =ROUND(50*MIN(1,3/K48)+50*MIN(1,30/P48),1) -> 29.8 | Z48: =RANK(Y48,$Y$2:$Y$350,0) -> 172 | AA48: 87 | AB48: 86 | AC48: آگهی اجاره دیوار | AD48: دقیق | AE48: طرشت | AF48: A
...

Sheet مناطق
A1: منطقه | B1: جمعیت ۱۳۹۵ (سرشماری) | C1: خانوار ۱۳۹۵ (سرشماری) | D1: بُعد خانوار | E1: نسبت درآمد سرانه منطقه به شهر (مدل) | F1: نسبت هزینه سرانه به شهر در ۱۳۸۷ (طرح هزینه و درآمد) | G1: خانوارهای برآوردی محلات | H1: میانگین وزنی قیمت هر متر (میلیون تومان) | I1: میانگین وزنی درآمد خانوار (میلیون تومان) | J1: میانگین وزنی PIR ساکنان | K1: میانگین وزنی سهم اجاره از درآمد ساکنان ٪ | L1: میانگین وزنی PIR خانوار متوسط تهران | M1: کمترین قیمت هر متر محله | N1: بیشترین قیمت هر متر محله | O1: پوشش داده قیمت (محلات دارای آگهی/کل)
A2: 1 | B2: 493889 | C2: 169259 | D2: =B2/C2 -> 2.9179482 | E2: 2.279 | F2: ≈ ۲ (دو برابر) | G2: =SUMIF(محلات!$B$2:$B$350,A2,محلات!$E$2:$E$350) -> 166578 | H2: =SUMPRODUCT((محلات!$B$2:$B$350=A2)*محلات!$E$2:$E$350*محلات!$H$2:$H$350)/G2 -> 555.38452 | I2: =SUMPRODUCT((محلات!$B$2:$B$350=A2)*محلات!$E$2:$E$350*محلات!$G$2:$G$350)/G2 -> 2167.7985 | J2: =SUMPRODUCT((محلات!$B$2:$B$350=A2)*محلات!$E$2:$E$350*محلات!$K$2:$K$350)/G2 -> 19.266343 | K2: =SUMPRODUCT((محلات!$B$2:$B$350=A2)*محلات!$E$2:$E$350*محلات!$P$2:$P$350)/G2 -> 59.795863 | L2: =SUMPRODUCT((محلات!$B$2:$B$350=A2)*محلات!$E$2:$E$350*محلات!$L$2:$L$350)/G2 -> 42.794308 | M2: =_xlfn.MINIFS(محلات!$H$2:$H$350,محلات!$B$2:$B$350,A2) -> 291.7 | N2: =_xlfn.MAXIFS(محلات!$H$2:$H$350,محلات!$B$2:$B$350,A2) -> 841.6 | O2: =COUNTIFS(محلات!$B$2:$B$350,A2,محلات!$AA$2:$AA$350,">0")/COUNTIF(محلات!$B$2:$B$350,A2)*100 -> 92.592593
A3: 2 | B3: 692579 | C3: 236992 | D3: =B3/C3 -> 2.9223729 | E3: 1.709 | F3: — | G3: =SUMIF(محلات!$B$2:$B$350,A3,محلات!$E$2:$E$350) -> 236723 | H3: =SUMPRODUCT((محلات!$B$2:$B$350=A3)*محلات!$E$2:$E$350*محلات!$H$2:$H$350)/G3 -> 420.62842 | I3: =SUMPRODUCT((محلات!$B$2:$B$350=A3)*محلات!$E$2:$E$350*محلات!$G$2:$G$350)/G3 -> 1628.2299 | J3: =SUMPRODUCT((محلات!$B$2:$B$350=A3)*محلات!$E$2:$E$350*محلات!$K$2:$K$350)/G3 -> 19.422878 | K3: =SUMPRODUCT((محلات!$B$2:$B$350=A3)*محلات!$E$2:$E$350*محلات!$P$2:$P$350)/G3 -> 60.712903 | L3: =SUMPRODUCT((محلات!$B$2:$B$350=A3)*محلات!$E$2:$E$350*محلات!$L$2:$L$350)/G3 -> 32.410882 | M3: =_xlfn.MINIFS(محلات!$H$2:$H$350,محلات!$B$2:$B$350,A3) -> 246.8 | N3: =_xlfn.MAXIFS(محلات!$H$2:$H$350,محلات!$B$2:$B$350,A3) -> 647.7 | O3: =COUNTIFS(محلات!$B$2:$B$350,A3,محلات!$AA$2:$AA$350,">0")/COUNTIF(محلات!$B$2:$B$350,A3)*100 -> 85.714286
A4: 3 | B4: 330004 | C4: 118801 | D4: =B4/C4 -> 2.7777881 | E4: 1.892 | F4: ≈ ۲ (دو برابر) | G4: =SUMIF(محلات!$B$2:$B$350,A4,محلات!$E$2:$E$350) -> 118801 | H4: =SUMPRODUCT((محلات!$B$2:$B$350=A4)*محلات!$E$2:$E$350*محلات!$H$2:$H$350)/G4 -> 464.58156 | I4: =SUMPRODUCT((محلات!$B$2:$B$350=A4)*محلات!$E$2:$E$350*محلات!$G$2:$G$350)/G4 -> 1714.0322 | J4: =SUMPRODUCT((محلات!$B$2:$B$350=A4)*محلات!$E$2:$E$350*محلات!$K$2:$K$350)/G4 -> 20.345809 | K4: =SUMPRODUCT((محلات!$B$2:$B$350=A4)*محلات!$E$2:$E$350*محلات!$P$2:$P$350)/G4 -> 64.472281 | L4: =SUMPRODUCT((محلات!$B$2:$B$350=A4)*محلات!$E$2:$E$350*محلات!$L$2:$L$350)/G4 -> 35.797624 | M4: =_xlfn.MINIFS(محلات!$H$2:$H$350,محلات!$B$2:$B$350,A4) -> 360.9 | N4: =_xlfn.MAXIFS(محلات!$H$2:$H$350,محلات!$B$2:$B$350,A4) -> 665.6 | O4: =COUNTIFS(محلات!$B$2:$B$350,A4,محلات!$AA$2:$AA$350,">0")/COUNTIF(محلات!$B$2:$B$350,A4)*100 -> 83.333333
A5: 4 | B5: 917261 | C5: 303730 | D5: =B5/C5 -> 3.0199881 | E5: 1.029 | F5: — | G5: =SUMIF(محلات!$B$2:$B$350,A5,محلات!$E$2:$E$350) -> 300198 | H5: =SUMPRODUCT((محلات!$B$2:$B$350=A5)*محلات!$E$2:$E$350*محلات!$H$2:$H$350)/G5 -> 257.55534 | I5: =SUMPRODUCT((محلات!$B$2:$B$350=A5)*محلات!$E$2:$E$350*محلات!$G$2:$G$350)/G5 -> 1013.0324 | J5: =SUMPRODUCT((محلات!$B$2:$B$350=A5)*محلات!$E$2:$E$350*محلات!$K$2:$K$350)/G5 -> 19.126442 | K5: =SUMPRODUCT((محلات!$B$2:$B$350=A5)*محلات!$E$2:$E$350*محلات!$P$2:$P$350)/G5 -> 65.062628 | L5: =SUMPRODUCT((محلات!$B$2:$B$350=A5)*محلات!$E$2:$E$350*محلات!$L$2:$L$350)/G5 -> 19.845534 | M5: =_xlfn.MINIFS(محلات!$H$2:$H$350,محلات!$B$2:$B$350,A5) -> 98.6 | N5: =_xlfn.MAXIFS(محلات!$H$2:$H$350,محلات!$B$2:$B$350,A5) -> 538.1 | O5: =COUNTIFS(محلات!$B$2:$B$350,A5,محلات!$AA$2:$AA$350,">0")/COUNTIF(محلات!$B$2:$B$350,A5)*100 -> 80
A6: 5 | B6: 856565 | C6: 291665 | D6: =B6/C6 -> 2.9368111 | E6: 1.265 | F6: — | G6: =SUMIF(محلات!$B$2:$B$350,A6,محلات!$E$2:$E$350) -> 290524 | H6: =SUMPRODUCT((محلات!$B$2:$B$350=A6)*محلات!$E$2:$E$350*محلات!$H$2:$H$350)/G6 -> 314.7958 | I6: =SUMPRODUCT((محلات!$B$2:$B$350=A6)*محلات!$E$2:$E$350*محلات!$G$2:$G$350)/G6 -> 1211.1282 | J6: =SUMPRODUCT((محلات!$B$2:$B$350=A6)*محلات!$E$2:$E$350*محلات!$K$2:$K$350)/G6 -> 19.505805 | K6: =SUMPRODUCT((محلات!$B$2:$B$350=A6)*محلات!$E$2:$E$350*محلات!$P$2:$P$350)/G6 -> 65.236618 | L6: =SUMPRODUCT((محلات!$B$2:$B$350=A6)*محلات!$E$2:$E$350*محلات!$L$2:$L$350)/G6 -> 24.25611 | M6: =_xlfn.MINIFS(محلات!$H$2:$H$350,محلات!$B$2:$B$350,A6) -> 188 | N6: =_xlfn.MAXIFS(محلات!$H$2:$H$350,محلات!$B$2:$B$350,A6) -> 380.3 | O6: =COUNTIFS(محلات!$B$2:$B$350,A6,محلات!$AA$2:$AA$350,">0")/COUNTIF(محلات!$B$2:$B$350,A6)*100 -> 100
A7: 6 | B7: 250753 | C7: 84896 | D7: =B7/C7 -> 2.9536492 | E7: 1.435 | F7: — | G7: =SUMIF(محلات!$B$2:$B$350,A7,محلات!$E$2:$E$350) -> 84897 | H7: =SUMPRODUCT((محلات!$B$2:$B$350=A7)*محلات!$E$2:$E$350*محلات!$H$2:$H$350)/G7 -> 355.40255 | I7: =SUMPRODUCT((محلات!$B$2:$B$350=A7)*محلات!$E$2:$E$350*محلات!$G$2:$G$350)/G7 -> 1381.9404 | J7: =SUMPRODUCT((محلات!$B$2:$B$350=A7)*محلات!$E$2:$E$350*محلات!$K$2:$K$350)/G7 -> 19.327384 | K7: =SUMPRODUCT((محلات!$B$2:$B$350=A7)*محلات!$E$2:$E$350*محلات!$P$2:$P$350)/G7 -> 61.493448 | L7: =SUMPRODUCT((محلات!$B$2:$B$350=A7)*محلات!$E$2:$E$350*محلات!$L$2:$L$350)/G7 -> 27.385002 | M7: =_xlfn.MINIFS(محلات!$H$2:$H$350,محلات!$B$2:$B$350,A7) -> 203.4 | N7: =_xlfn.MAXIFS(محلات!$H$2:$H$350,محلات!$B$2:$B$350,A7) -> 449.7 | O7: =COUNTIFS(محلات!$B$2:$B$350,A7,محلات!$AA$2:$AA$350,">0")/COUNTIF(محلات!$B$2:$B$350,A7)*100 -> 85.714286
A8: 7 | B8: 312002 | C8: 115880 | D8: =B8/C8 -> 2.6924577 | E8: 1.001 | F8: — | G8: =SUMIF(محلات!$B$2:$B$350,A8,محلات!$E$2:$E$350) -> 115879 | H8: =SUMPRODUCT((محلات!$B$2:$B$350=A8)*محلات!$E$2:$E$350*محلات!$H$2:$H$350)/G8 -> 250.75538 | I8: =SUMPRODUCT((محلات!$B$2:$B$350=A8)*محلات!$E$2:$E$350*محلات!$G$2:$G$350)/G8 -> 878.34561 | J8: =SUMPRODUCT((محلات!$B$2:$B$350=A8)*محلات!$E$2:$E$350*محلات!$K$2:$K$350)/G8 -> 21.467823 | K8: =SUMPRODUCT((محلات!$B$2:$B$350=A8)*محلات!$E$2:$E$350*محلات!$P$2:$P$350)/G8 -> 78.159503 | L8: =SUMPRODUCT((محلات!$B$2:$B$350=A8)*محلات!$E$2:$E$350*محلات!$L$2:$L$350)/G8 -> 19.321574 | M8: =_xlfn.MINIFS(محلات!$H$2:$H$350,محلات!$B$2:$B$350,A8) -> 179 | N8: =_xlfn.MAXIFS(محلات!$H$2:$H$350,محلات!$B$2:$B$350,A8) -> 417.2 | O8: =COUNTIFS(محلات!$B$2:$B$350,A8,محلات!$AA$2:$AA$350,">0")/COUNTIF(محلات!$B$2:$B$350,A8)*100 -> 92.857143
A9: 8 | B9: 425044 | C9: 148535 | D9: =B9/C9 -> 2.8615747 | E9: 0.943 | F9: — | G9: =SUMIF(محلات!$B$2:$B$350,A9,محلات!$E$2:$E$350) -> 148535 | H9: =SUMPRODUCT((محلات!$B$2:$B$350=A9)*محلات!$E$2:$E$350*محلات!$H$2:$H$350)/G9 -> 237.06819 | I9: =SUMPRODUCT((محلات!$B$2:$B$350=A9)*محلات!$E$2:$E$350*محلات!$G$2:$G$350)/G9 -> 880.0068 | J9: =SUMPRODUCT((محلات!$B$2:$B$350=A9)*محلات!$E$2:$E$350*محلات!$K$2:$K$350)/G9 -> 20.224375 | K9: =SUMPRODUCT((محلات!$B$2:$B$350=A9)*محلات!$E$2:$E$350*محلات!$P$2:$P$350)/G9 -> 68.850348 | L9: =SUMPRODUCT((محلات!$B$2:$B$350=A9)*محلات!$E$2:$E$350*محلات!$L$2:$L$350)/G9 -> 18.266928 | M9: =_xlfn.MINIFS(محلات!$H$2:$H$350,محلات!$B$2:$B$350,A9) -> 176.4 | N9: =_xlfn.MAXIFS(محلات!$H$2:$H$350,محلات!$B$2:$B$350,A9) -> 301.6 | O9: =COUNTIFS(محلات!$B$2:$B$350,A9,محلات!$AA$2:$AA$350,">0")/COUNTIF(محلات!$B$2:$B$350,A9)*100 -> 100
A10: 9 | B10: 174115 | C10: 57648 | D10: =B10/C10 -> 3.0203129 | E10: 0.646 | F10: — | G10: =SUMIF(محلات!$B$2:$B$350,A10,محلات!$E$2:$E$350) -> 57649 | H10: =SUMPRODUCT((محلات!$B$2:$B$350=A10)*محلات!$E$2:$E$350*محلات!$H$2:$H$350)/G10 -> 164.56045 | I10: =SUMPRODUCT((محلات!$B$2:$B$350=A10)*محلات!$E$2:$E$350*محلات!$G$2:$G$350)/G10 -> 636.36472 | J10: =SUMPRODUCT((محلات!$B$2:$B$350=A10)*محلات!$E$2:$E$350*محلات!$K$2:$K$350)/G10 -> 19.400448 | K10: =SUMPRODUCT((محلات!$B$2:$B$350=A10)*محلات!$E$2:$E$350*محلات!$P$2:$P$350)/G10 -> 75.726558 | L10: =SUMPRODUCT((محلات!$B$2:$B$350=A10)*محلات!$E$2:$E$350*محلات!$L$2:$L$350)/G10 -> 12.679954 | M10: =_xlfn.MINIFS(محلات!$H$2:$H$350,محلات!$B$2:$B$350,A10) -> 145.4 | N10: =_xlfn.MAXIFS(محلات!$H$2:$H$350,محلات!$B$2:$B$350,A10) -> 188.7 | O10: =COUNTIFS(محلات!$B$2:$B$350,A10,محلات!$AA$2:$AA$350,">0")/COUNTIF(محلات!$B$2:$B$350,A10)*100 -> 66.666667
A11: 10 | B11: 326885 | C11: 117325 | D11: =B11/C11 -> 2.7861496 | E11: 0.602 | F11: — | G11: =SUMIF(محلات!$B$2:$B$350,A11,محلات!$E$2:$E$350) -> 117324 | H11: =SUMPRODUCT((محلات!$B$2:$B$350=A11)*محلات!$E$2:$E$350*محلات!$H$2:$H$350)/G11 -> 153.75306 | I11: =SUMPRODUCT((محلات!$B$2:$B$350=A11)*محلات!$E$2:$E$350*محلات!$G$2:$G$350)/G11 -> 547.20009 | J11: =SUMPRODUCT((محلات!$B$2:$B$350=A11)*محلات!$E$2:$E$350*محلات!$K$2:$K$350)/G11 -> 21.076915 | K11: =SUMPRODUCT((محلات!$B$2:$B$350=A11)*محلات!$E$2:$E$350*محلات!$P$2:$P$350)/G11 -> 81.601486 | L11: =SUMPRODUCT((محلات!$B$2:$B$350=A11)*محلات!$E$2:$E$350*محلات!$L$2:$L$350)/G11 -> 11.847208 | M11: =_xlfn.MINIFS(محلات!$H$2:$H$350,محلات!$B$2:$B$350,A11) -> 135.7 | N11: =_xlfn.MAXIFS(محلات!$H$2:$H$350,محلات!$B$2:$B$350,A11) -> 170.3 | O11: =COUNTIFS(محلات!$B$2:$B$350,A11,محلات!$AA$2:$AA$350,">0")/COUNTIF(محلات!$B$2:$B$350,A11)*100 -> 80
